Workbook

Sheet Cambios
A1: Mallplaza (Plaza S.A.) — Valorización consolidada v2
A2: Resumen y cambios respecto de 'Mallplaza Valoracion Consolidada VF.xlsx'. Todas las cifras de esta hoja son vínculos vivos.
A4: Resultado
A5: Valor por acción DCF (CLP) | B5: =DCF!C49 -> 1856.812
A6: Valor por acción por múltiplos — EV/EBITDA LTM (CLP) | B6: =Precio_Objetivo!D5 -> 2951.3855
A7: Precio objetivo 80% DCF / 20% múltiplos (CLP) | B7: =Precio_Objetivo!B15 -> 2075.7267
A8: Precio 30-09-2026 (CLP) | B8: =Supuestos!$B$8 -> 3555
A9: Upside / (downside) del precio objetivo | B9: =Precio_Objetivo!B17 -> -0.41611064
A10: Valor por acción APV — chequeo (CLP) | B10: =DCF!C63 -> 1893.6531
A11: WACC nominal: 2S26E → terminal | B11: =WACC!C43 -> 0.10536861 | C11: =WACC!I43 -> 0.10413887
A12: DFN/EBITDA: hoy → 2031 | B12: =Supuestos!$B$41 -> 2.3594374 | C12: =Deuda!H22 -> 3.5
A14: Comparación con el VF
A15: Valor por acción DCF VF (CLP) | B15: =Supuestos!$B$108 -> 1880.3684
A16: Diferencia DCF v2 − VF (CLP) | B16: =DCF!C62 -> -23.556361
A17: Precio objetivo VF (CLP) | B17: =Supuestos!$B$110 -> 2094.5718
A20: Qué cambió en v2
A21: 1. Estructura de capital: parte en la DFN/EBITDA real de jun-26 (2,36x) y converge linealmente a 3,5x al cierre de 2031 (Supuestos C, editable). El valor terminal usa 3,5x.
A22: 2. Deuda: la caja sobrante se registra como distribución adicional a accionistas (recompra o dividendo extra), de modo que la DFN sigue la trayectoria objetivo. En el VF la DFN bajaba a ~1,0x mientras la WACC suponía 3,5x.
A23: 3. WACC por período: el D/E parte en la estructura actual del modelo original (19,98%) y converge a la objetivo (28,52%) en 2031; beta, Ke, Kd y WACC se recalculan cada año y el DCF descuenta con factores acumulados.
A24: 4. Costo de la deuda: +25 pb de Kd real por cada vuelta de DFN/EBITDA sobre 2,36x (supuesto del equipo). Afecta la WACC y el costo financiero.
A25: 5. Reajuste UF tratado como gasto deducible en la hoja Deuda (no cambia el EV).
A26: 6. Nuevas hojas: APV (chequeo de consistencia) y Sensibilidad (WACC vs g con fórmulas vivas; objetivo de deuda vs spread).
A27: 7. Todo el libro queda vinculado: betas y CRP → WACC; Capital_Trabajo → Supuestos; Expansion → DCF; Datos_BBG → Comparables → Precio_Objetivo.
A28: 8. Sin cambios de supuestos: forecast operativo, expansión, capital de trabajo, g terminal, múltiplos y puente a patrimonio.
A29: Control: Supuestos C, switch = 0 → reproduce exactamente el VF (WACC 10,37% constante; CLP 1.880; precio objetivo CLP 2.095).
A31: NUEVO · v3: hojas TIR_Implicita (TIR de la firma, tasa única, Buscar objetivo) y TIR_Accionista (TIR de la firma, del accionista y por escenario, nominal y real, fórmulas vivas).
A32: NUEVO · v3: sin cambios en las demás hojas (valores idénticos a v2). El 7,57% de TIR_Implicita es una tasa única; el 7,56% de la Figura 34/V6 desplaza en paralelo la WACC de cada período.

Sheet Supuestos
A1: Supuestos — modelo consolidado de valoración Mallplaza (Plaza S.A.) · v2
A2: Única hoja de inputs. Azul = dato ingresado · negro = fórmula · verde = vínculo a otra hoja · fondo amarillo = supuesto clave del equipo. MM CLP salvo indicación. Tags: [R] reportado · [P] consenso/forecast · [C] cálculo · [S] supuesto del equipo.
A4: Concepto | B4: Valor | C4: Unidad | D4: Tag | E4: Fuente / comentario
A6: A. General y puente a patrimonio
A7: Fecha de valorización | B7: 30-06-2026 | C7: fecha | D7: S | E7: Coincide con la última DFN y minoritarios reportados (Release 2Q26).
A8: Precio de referencia | B8: 3555 | C8: CLP | D8: R | E8: Bloomberg PX_LAST al 30-09-2026 (Datos_BBG).
A9: Acciones en circulación | B9: 2190 | C9: MM | D9: R | E9: Bloomberg: market cap / precio (Datos_BBG).
A10: Deuda financiera neta 30-06-2026 (definición compañía) | B10: 1285740 | C10: MM CLP | D10: R | E10: Release 2Q26 / Análisis Razonado 1S26.
A11: Participaciones no controladoras (libro) 30-06-2026 | B11: 50841 | C11: MM CLP | D11: R | E11: Release 2Q26. Libro como proxy del valor de mercado [S].
A12: Caja y equivalentes 30-06-2026 | B12: 347621 | C12: MM CLP | D12: R | E12: Release 2Q26. Se mantiene constante para pasar de DFN a deuda bruta.
A13: EBITDA LTM 2T26 (definición compañía) | B13: 544935 | C13: MM CLP | D13: R | E13: Release 2Q26, p. 29.
A14: Deuda neta Mallplaza para múltiplos (BBG NET_DEBT) | B14: 1311568.6 | C14: MM CLP | D14: R | E14: Misma definición que los pares (Bloomberg), solo para el método de múltiplos.
A16: B. WACC (fórmulas en hoja WACC)
A17: Rf — bono del Tesoro de EE.UU. | B17: 0.049778 | C17: % | D17: R | E17: Tasa_WACC.xlsm, FFCF!C11.
A18: Rf — tasa "Chile" del archivo original | B18: 0.0543 | C18: % | D18: R | E18: Tasa_WACC.xlsm, FFCF!E11. Si ya incluye riesgo Chile, el CRP se contaría dos veces.
A19: Rf usada en el Ke (1 = "Chile" · 2 = EE.UU.) | B19: 2 | C19: switch | D19: S | E19: Rf = bono de EE.UU.; el CRP se suma aparte (sin doble conteo).
A20: Inflación de largo plazo EE.UU. (breakeven 10Y, jun-26) | B20: 0.022431 | C20: % | D20: R | E20: Bloomberg USGG10YR − USGGT10Y al 30-06-2026.
A21: Convertir el Ke en USD a CLP con el diferencial de inflación (1 = sí) | B21: 1 | C21: switch | D21: S | E21: Ke CLP = (1 + Ke USD) × (1 + inflación Chile) / (1 + inflación EE.UU.) − 1.
A22: Prima por riesgo de mercado (ERP) | B22: 0.0414 | C22: % | D22: R | E22: Damodaran (Tasa_WACC.xlsm, FFCF!B73).
A23: CRP Chile | B23: 0.0104 | C23: % | D23: R | E23: Tasa_WACC.xlsm, FFCF!C79.
A24: CRP Perú | B24: 0.0155 | C24: % | D24: R | E24: Tasa_WACC.xlsm, FFCF!C80.
A25: CRP Colombia | B25: 0.037 | C25: % | D25: R | E25: Tasa_WACC.xlsm, FFCF!C81.
A26: Ingresos LTM consolidados (ponderador CRP) | B26: 677333 | C26: MM CLP | D26: R | E26: Tasa_WACC.xlsm, FFCF!C83.
A27: Ingresos LTM Chile | B27: 486084 | C27: MM CLP | D27: R | E27: Tasa_WACC.xlsm, FFCF!C86.
A28: Ingresos LTM Perú | B28: 463174 | C28: miles PEN | D28: R | E28: Tasa_WACC.xlsm, FFCF!C90.
... A37: Market cap Mallplaza (estructura de la WACC) | B37: 7905900 | C37: MM CLP | D37: R | E37: Tasa_WACC.xlsm, FFCF!G26.
A39: C. Política de deuda (v2: estructura actual → objetivo de largo plazo)
A40: Política de deuda (1 = convergencia al objetivo · 0 = WACC constante del VF) | B40: 1 | C40: switch | D40: S | E40: Con 0 se reproduce el DCF VF: 3,5x desde hoy, WACC 10,37% constante, CLP 1.880.
A41: DFN / EBITDA inicial (30-06-2026) | B41: =$B$10/$B$13 -> 2.3594374 | C41: x | D41: C | E41: DFN / EBITDA LTM.
A42: DFN / EBITDA objetivo de largo plazo | B42: 3.5 | C42: x | D42: S | E42: La compañía usa su capacidad de deuda para crecer. Referencias: 3,78x dic-24 (post Open Plaza Perú); Parque Arauco 5,7x; Cencosud Shopping 2,1x.
A43: Año en que se alcanza el objetivo (al 31-dic) | B43: 2031 | C43: año | D43: S | E43: Convergencia lineal desde el nivel inicial; el valor terminal usa el objetivo.
A44: Horizonte de convergencia | B44: =$B$43-2026+0.5 -> 5.5 | C44: años | D44: C | E44: Años entre el 30-06-2026 y el 31-dic del año objetivo.
A45: Aumento del Kd real por cada 1,0x de DFN/EBITDA sobre el nivel inicial | B45: 0.0025 | C45: % | D45: S | E45: Más deuda → menor clasificación y mayor spread. Calibrar con spreads de bonos corporativos UF por clasificación. Afecta la WACC y el costo financiero de la hoja Deuda.
A46: Costo financiero neto / DFN de apertura (sin reajuste UF), nivel inicial | B46: 0.0308 | C46: % | D46: C | E46: Exhibits v6: 1S26 anualizado.
A47: Deuda en UF / deuda total | B47: 0.79 | C47: % | D47: R | E47: Release 2Q26.
A48: Payout sobre utilidad distribuible | B48: 0.4 | C48: % | D48: R | E48: Política de dividendos (EEFF dic-25, Nota 20e).
A49: Dividendos 2026E totales | B49: 147724.8 | C49: MM CLP | D49: P | E49: Exhibits v6 (40% × distribuible 2025).
A50: Dividendos pagados 1S26 | B50: 87617 | C50: MM CLP | D50: R | E50: EEFF jun-26, flujos.
A51: Utilidad distribuible 2026E (año completo) | B51: 380038.82 | C51: MM CLP | D51: P | E51: Exhibits v6.
A53: D. Forecast base (motor operativo, Exhibits v6)
...

Sheet WACC
A1: WACC nominal en CLP por período — misma lógica que Tasa_WACC.xlsm (FFCF) con correcciones
A2: Correcciones del VF: (1) Kd real UF pasado a nominal; (2) escudo fiscal (1 − t); (3) set de pares = coincidencia betas–comparables. v2: la estructura de capital, la beta y el Kd cambian cada período según la hoja Deuda.
A4: A. Betas de los pares
A5: Empresa | B5: Ticker BBG | C5: País | D5: Beta apalancada | E5: Deuda | F5: Market cap | G5: Impuesto | H5: Beta desapalancada | I5: En set común (1/0) | J5: Beta incluida
A6: Parque Arauco | B6: PARAUCO CI | C6: Chile | D6: 1.25 | E6: 1700506.9 | F6: 3828031 | G6: 0.27 | H6: =D6/(1+(1-G6)*E6/F6) -> 0.94390614 | I6: =IF(COUNTIFS(Comparables!$B$5:$B$12,B6,Comparables!$D$5:$D$12,1)>0,1,0) -> 1 | J6: =IF(I6=1,H6,"") -> 0.94390614
A7: Cencosud Shopping | B7: CENCOMAL CI | C7: Chile | D7: 1.075 | E7: 762153.7 | F7: 3942858 | G7: 0.27 | H7: =D7/(1+(1-G7)*E7/F7) -> 0.94206612 | I7: =IF(COUNTIFS(Comparables!$B$5:$B$12,B7,Comparables!$D$5:$D$12,1)>0,1,0) -> 1 | J7: =IF(I7=1,H7,"") -> 0.94206612
A8: Allos | B8: ALOS3 BZ | C8: Brasil | D8: 1.164 | E8: 960191 | F8: 2712166.2 | G8: 0.34 | H8: =D8/(1+(1-G8)*E8/F8) -> 0.94353351 | I8: =IF(COUNTIFS(Comparables!$B$5:$B$12,B8,Comparables!$D$5:$D$12,1)>0,1,0) -> 1 | J8: =IF(I8=1,H8,"") -> 0.94353351
A9: Iguatemi | B9: IGTI11 BZ | C9: Brasil | D9: 0.908 | E9: 647396.6 | F9: 1421560.1 | G9: 0.34 | H9: =D9/(1+(1-G9)*E9/F9) -> 0.69815413 | I9: =IF(COUNTIFS(Comparables!$B$5:$B$12,B9,Comparables!$D$5:$D$12,1)>0,1,0) -> 1 | J9: =IF(I9=1,H9,"") -> 0.69815413
A10: Costa Verde | B10: n/d (no está en comparables) | C10: México | D10: 0.025 | E10: 203967.5 | F10: 489349.7 | G10: 0.3 | H10: =D10/(1+(1-G10)*E10/F10) -> 0.0193533 | I10: =IF(COUNTIFS(Comparables!$B$5:$B$12,B10,Comparables!$D$5:$D$12,1)>0,1,0) -> 0 | J10: =IF(I10=1,H10,"")
A11: IRSA | B11: IRSA AR | C11: Argentina | D11: 0.427 | E11: 625046.5 | F11: 1218777.1 | G11: 0.35 | H11: =D11/(1+(1-G11)*E11/F11) -> 0.32024582 | I11: =IF(COUNTIFS(Comparables!$B$5:$B$12,B11,Comparables!$D$5:$D$12,1)>0,1,0) -> 1 | J11: =IF(I11=1,H11,"") -> 0.32024582
A12: Multiplan | B12: MULT3 BZ | C12: Brasil | D12: 1.219 | E12: 191478.3 | F12: 2959844.9 | G12: 0.34 | H12: =D12/(1+(1-G12)*E12/F12) -> 1.1690839 | I12: =IF(COUNTIFS(Comparables!$B$5:$B$12,B12,Comparables!$D$5:$D$12,1)>0,1,0) -> 1 | J12: =IF(I12=1,H12,"") -> 1.1690839
A13: Beta desapalancada: mediana del set común | H13: =MEDIAN(J6:J12) -> 0.94279981 | I13: =COUNT(J6:J12) -> 6
A15: B. Riesgo país ponderado por ingresos
A16: Ponderación Chile (ingresos) | C16: =Supuestos!$B$27/Supuestos!$B$26 -> 0.71764405
A17: Ingresos Perú en MM CLP | C17: =Supuestos!$B$28/Supuestos!$B$31*Supuestos!$B$30/1000 -> 125262.08
A18: Ingresos Colombia en MM CLP | C18: =Supuestos!$B$29/Supuestos!$B$32*Supuestos!$B$30 -> 74355.805
A19: Ponderación Perú | C19: =(1-$C$16)*$C$17/($C$17+$C$18) -> 0.17718098
A20: Ponderación Colombia | C20: =(1-$C$16)*$C$18/($C$17+$C$18) -> 0.10517496
A21: CRP ponderado Mallplaza | C21: =$C$16*Supuestos!$B$23+$C$19*Supuestos!$B$24+$C$20*Supuestos!$B$25 -> 0.014101277
A22: Rf usada | C22: =IF(Supuestos!$B$19=1,Supuestos!$B$18,Supuestos!$B$17) -> 0.049778
A24: C. Estructura de capital original del modelo (extremos de la convergencia)
A25: Deuda bruta actual / market cap = D/E actual (punto de partida) | C25: =Supuestos!$B$36/Supuestos!$B$37 -> 0.19976413 | D25: Estructura actual calculada en el modelo original (Tasa_WACC.xlsm, FFCF!G23:G26): 1.579.315 / 7.905.900.
A26: Deuda objetivo = DFN/EBITDA objetivo × EBITDA LTM + caja | C26: =Supuestos!$B$42*Supuestos!$B$13+Supuestos!$B$12 -> 2254893.5
A27: D/E objetivo (punto de llegada, valor terminal) | C27: =C26/Supuestos!$B$37 -> 0.28521655 | D27: Estructura objetivo calculada en el modelo original (3,5x): 28,52%.
A28: Control: Ke del archivo original (Rf "Chile", estructura actual, sin conversión) | C28: =Supuestos!$B$18+$H$13*(1+(1-Supuestos!$B$35)*Supuestos!$B$36/Supuestos!$B$37)*Supuestos!$B$22+$C$21 -> 0.11312513 | D28: Debe dar 11,31% (Tasa_WACC.xlsm, FFCF!B112).
A30: D. WACC por período (D/E converge linealmente de la estructura actual a la objetivo)
A31: Concepto | C31: 2S26E | D31: 2027E | E31: 2028E | F31: 2029E | G31: 2030E | H31: 2031E | I31: Terminal
A32: DFN / EBITDA (cierre del período) | C32: =Deuda!C22 -> 2.4631249 | D32: =Deuda!D22 -> 2.6704999 | E32: =Deuda!E22 -> 2.8778749 | F32: =Deuda!F22 -> 3.08525 | G32: =Deuda!G22 -> 3.292625 | H32: =Deuda!H22 -> 3.5 | I32: =IF(Supuestos!$B$40=1,Supuestos!$B$42,Deuda!H22) -> 3.5
A33: Años desde 30-06-2026 al cierre del período | C33: =Deuda!C5 -> 0.5 | D33: =Deuda!D5 -> 1.5 | E33: =Deuda!E5 -> 2.5 | F33: =Deuda!F5 -> 3.5 | G33: =Deuda!G5 -> 4.5 | H33: =Deuda!H5 -> 5.5
A34: D/E usado | C34: =IF(Supuestos!$B$40=1,WACC!$C$25+(WACC!$C$27-WACC!$C$25)*MIN(1,C33/Supuestos!$B$44),WACC!$C$27) -> 0.20753253 | D34: =IF(Supuestos!$B$40=1,WACC!$C$25+(WACC!$C$27-WACC!$C$25)*MIN(1,D33/Supuestos!$B$44),WACC!$C$27) -> 0.22306933 | E34: =IF(Supuestos!$B$40=1,WACC!$C$25+(WACC!$C$27-WACC!$C$25)*MIN(1,E33/Supuestos!$B$44),WACC!$C$27) -> 0.23860614 | F34: =IF(Supuestos!$B$40=1,WACC!$C$25+(WACC!$C$27-WACC!$C$25)*MIN(1,F33/Supuestos!$B$44),WACC!$C$27) -> 0.25414294 | G34: =IF(Supuestos!$B$40=1,WACC!$C$25+(WACC!$C$27-WACC!$C$25)*MIN(1,G33/Supuestos!$B$44),WACC!$C$27) -> 0.26967974 | H34: =IF(Supuestos!$B$40=1,WACC!$C$25+(WACC!$C$27-WACC!$C$25)*MIN(1,H33/Supuestos!$B$44),WACC!$C$27) -> 0.28521655 | I34: =WACC!$C$27 -> 0.28521655 | J34: Convergencia lineal desde el D/E actual (19,98%) hasta el objetivo (28,52%) en el año objetivo de Supuestos C; el terminal usa el objetivo. Switch 0: objetivo desde hoy (VF).
A35: D/V | C35: =C34/(1+C34) -> 0.17186496 | D35: =D34/(1+D34) -> 0.18238486 | E35: =E34/(1+E34) -> 0.19264085 | F35: =F34/(1+F34) -> 0.20264272 | G35: =G34/(1+G34) -> 0.21239982 | H35: =H34/(1+H34) -> 0.221921 | I35: =I34/(1+I34) -> 0.221921
A36: E/V | C36: =1-C35 -> 0.82813504 | D36: =1-D35 -> 0.81761514 | E36: =1-E35 -> 0.80735915 | F36: =1-F35 -> 0.79735728 | G36: =1-G35 -> 0.78760018 | H36: =1-H35 -> 0.778079 | I36: =1-I35 -> 0.778079
A37: Beta re-apalancada | C37: =WACC!$H$13*(1+(1-Supuestos!$B$35)*C34) -> 1.0856328 | D37: =WACC!$H$13*(1+(1-Supuestos!$B$35)*D34) -> 1.0963259 | E37: =WACC!$H$13*(1+(1-Supuestos!$B$35)*E34) -> 1.107019 | F37: =WACC!$H$13*(1+(1-Supuestos!$B$35)*F34) -> 1.1177121 | G37: =WACC!$H$13*(1+(1-Supuestos!$B$35)*G34) -> 1.1284052 | H37: =WACC!$H$13*(1+(1-Supuestos!$B$35)*H34) -> 1.1390984 | I37: =WACC!$H$13*(1+(1-Supuestos!$B$35)*I34) -> 1.1390984
A38: Ke antes de conversión = Rf + β × ERP + CRP | C38: =WACC!$C$22+C37*Supuestos!$B$22+WACC!$C$21 -> 0.10882448 | D38: =WACC!$C$22+D37*Supuestos!$B$22+WACC!$C$21 -> 0.10926717 | E38: =WACC!$C$22+E37*Supuestos!$B$22+WACC!$C$21 -> 0.10970986 | F38: =WACC!$C$22+F37*Supuestos!$B$22+WACC!$C$21 -> 0.11015256 | G38: =WACC!$C$22+G37*Supuestos!$B$22+WACC!$C$21 -> 0.11059525 | H38: =WACC!$C$22+H37*Supuestos!$B$22+WACC!$C$21 -> 0.11103795 | I38: =WACC!$C$22+I37*Supuestos!$B$22+WACC!$C$21 -> 0.11103795
A39: Ke nominal CLP | C39: =IF(AND(Supuestos!$B$21=1,Supuestos!$B$19=2),(1+C38)*(1+Supuestos!$B$34)/(1+Supuestos!$B$20)-1,C38) -> 0.11703304 | D39: =IF(AND(Supuestos!$B$21=1,Supuestos!$B$19=2),(1+D38)*(1+Supuestos!$B$34)/(1+Supuestos!$B$20)-1,D38) -> 0.11747901 | E39: =IF(AND(Supuestos!$B$21=1,Supuestos!$B$19=2),(1+E38)*(1+Supuestos!$B$34)/(1+Supuestos!$B$20)-1,E38) -> 0.11792499 | F39: =IF(AND(Supuestos!$B$21=1,Supuestos!$B$19=2),(1+F38)*(1+Supuestos!$B$34)/(1+Supuestos!$B$20)-1,F38) -> 0.11837096 | G39: =IF(AND(Supuestos!$B$21=1,Supuestos!$B$19=2),(1+G38)*(1+Supuestos!$B$34)/(1+Supuestos!$B$20)-1,G38) -> 0.11881693 | H39: =IF(AND(Supuestos!$B$21=1,Supuestos!$B$19=2),(1+H38)*(1+Supuestos!$B$34)/(1+Supuestos!$B$20)-1,H38) -> 0.1192629 | I39: =IF(AND(Supuestos!$B$21=1,Supuestos!$B$19=2),(1+I38)*(1+Supuestos!$B$34)/(1+Supuestos!$B$20)-1,I38) -> 0.1192629 | J39: Con Rf de EE.UU. el Ke queda en USD y se pasa a CLP por diferencial de inflación.
A40: Kd real (UF) con spread por apalancamiento | C40: =Supuestos!$B$33+Supuestos!$B$40*Supuestos!$B$45*MAX(0,C32-Supuestos!$B$41) -> 0.036259219 | D40: =Supuestos!$B$33+Supuestos!$B$40*Supuestos!$B$45*MAX(0,D32-Supuestos!$B$41) -> 0.036777656 | E40: =Supuestos!$B$33+Supuestos!$B$40*Supuestos!$B$45*MAX(0,E32-Supuestos!$B$41) -> 0.037296094 | F40: =Supuestos!$B$33+Supuestos!$B$40*Supuestos!$B$45*MAX(0,F32-Supuestos!$B$41) -> 0.037814531 | G40: =Supuestos!$B$33+Supuestos!$B$40*Supuestos!$B$45*MAX(0,G32-Supuestos!$B$41) -> 0.038332969 | H40: =Supuestos!$B$33+Supuestos!$B$40*Supuestos!$B$45*MAX(0,H32-Supuestos!$B$41) -> 0.038851407 | I40: =Supuestos!$B$33+Supuestos!$B$40*Supuestos!$B$45*MAX(0,I32-Supuestos!$B$41) -> 0.038851407
A41: Kd nominal CLP = (1 + Kd real)(1 + inflación) − 1 | C41: =(1+C40)*(1+Supuestos!$B$34)-1 -> 0.067346995 | D41: =(1+D40)*(1+Supuestos!$B$34)-1 -> 0.067880986 | E41: =(1+E40)*(1+Supuestos!$B$34)-1 -> 0.068414977 | F41: =(1+F40)*(1+Supuestos!$B$34)-1 -> 0.068948967 | G41: =(1+G40)*(1+Supuestos!$B$34)-1 -> 0.069482958 | H41: =(1+H40)*(1+Supuestos!$B$34)-1 -> 0.070016949 | I41: =(1+I40)*(1+Supuestos!$B$34)-1 -> 0.070016949
A42: Kd nominal después de impuestos | C42: =C41*(1-Supuestos!$B$35) -> 0.049163307 | D42: =D41*(1-Supuestos!$B$35) -> 0.04955312 | E42: =E41*(1-Supuestos!$B$35) -> 0.049942933 | F42: =F41*(1-Supuestos!$B$35) -> 0.050332746 | G42: =G41*(1-Supuestos!$B$35) -> 0.050722559 | H42: =H41*(1-Supuestos!$B$35) -> 0.051112373 | I42: =I41*(1-Supuestos!$B$35) -> 0.051112373
A43: WACC nominal CLP | C43: =C36*C39+C35*C42 -> 0.10536861 | D43: =D36*D39+D35*D42 -> 0.10509036 | E43: =E36*E39+E35*E42 -> 0.10482887 | F43: =F36*F39+F35*F42 -> 0.10458351 | G43: =G36*G39+G35*G42 -> 0.1043537 | H43: =H36*H39+H35*H42 -> 0.10413887 | I43: =I36*I39+I35*I42 -> 0.10413887
A44: WACC real implícita | C44: =(1+C43)/(1+Supuestos!$B$34)-1 -> 0.07317341 | D44: =(1+D43)/(1+Supuestos!$B$34)-1 -> 0.072903261 | E44: =(1+E43)/(1+Supuestos!$B$34)-1 -> 0.072649384 | F44: =(1+F43)/(1+Supuestos!$B$34)-1 -> 0.072411174 | G44: =(1+G43)/(1+Supuestos!$B$34)-1 -> 0.072188056 | H44: =(1+H43)/(1+Supuestos!$B$34)-1 -> 0.071979483 | I44: =(1+I43)/(1+Supuestos!$B$34)-1 -> 0.071979483
...

Sheet Forecast_Base
A1: Forecast base — motor operativo (Mallplaza_FA_Exhibits_v6.xlsx), 2S26E–2031E
A2: Cifras del forecast del equipo en azul, basadas en el pipeline anunciado hasta 2028. Sin la expansión post-2028 (hoja Expansion).
A4: MM CLP | C4: 2S26E | D4: 2027E | E4: 2028E | F4: 2029E | G4: 2030E | H4: 2031E | I4: Fuente / supuesto
A5: Ingresos año calendario (2026E = año completo) | C5: 703998.94 | D5: 767179.42 | E5: 820506.7 | F5: 866951.61 | G5: 904202.83 | H5: 939524.47 | I5: Exhibits v6, Forecast fila "Ingresos ordinarios consolidados".
A6: Ingresos del período (2S26E = 2026E − 1S26 real) | C6: =C5-Supuestos!$B$54 -> 364468.94 | D6: =D5 -> 767179.42 | E6: =E5 -> 820506.7 | F6: =F5 -> 866951.61 | G6: =G5 -> 904202.83 | H6: =H5 -> 939524.47
A7: EBITDA año calendario | C7: 561315.41 | D7: 611360.36 | E7: 654236.23 | F7: 691459.84 | G7: 721124.37 | H7: 749208.58 | I7: Exhibits v6, Forecast bloque E.
A8: EBITDA del período | C8: =C7-Supuestos!$B$55 -> 290741.41 | D8: =D7 -> 611360.36 | E8: =E7 -> 654236.23 | F8: =F7 -> 691459.84 | G8: =G7 -> 721124.37 | H8: =H7 -> 749208.58
A9: Margen EBITDA | C9: =C8/C6 -> 0.79771244 | D9: =D8/D6 -> 0.79689358 | E9: =E8/E6 -> 0.79735635 | F9: =F8/F6 -> 0.79757605 | G9: =G8/G6 -> 0.79752501 | H9: =H8/H6 -> 0.79743381
A10: D&A | C10: =Supuestos!$B$57*C6 -> 2564.5568 | D10: =Supuestos!$B$57*D6 -> 5398.1972 | E10: =Supuestos!$B$57*E6 -> 5773.4304 | F10: =Supuestos!$B$57*F6 -> 6100.2363 | G10: =Supuestos!$B$57*G6 -> 6362.3516 | H10: =Supuestos!$B$57*H6 -> 6610.8895 | I10: D&A / ingresos LTM × ingresos.
A11: Tasa de impuesto operacional en caja | C11: 0.168 | D11: 0.19 | E11: 0.215 | F11: 0.24 | G11: 0.27 | H11: 0.27 | I11: Exhibits v6: impuesto corriente / (EBITDA − costo financiero), 16,8% → 27%.
A12: Capex de proyectos en curso (MMUSD) | C12: 113.64 | D12: 215.08 | E12: 116.28 | F12: 0 | G12: 0 | H12: 0 | I12: Release 2Q26, pp. 12–14: remanente por proyecto repartido hasta su apertura.
A13: USDCLP promedio | C13: 929.55 | D13: 922.75 | E13: 914.75 | F13: 921 | G13: 921 | H13: 921 | I13: 2S26E promedio del semestre; 2027+ consenso ECFC; 2029+ constante.
A14: Capex de proyectos en curso (MM CLP) | C14: =C12*C13 -> 105634.06 | D14: =D12*D13 -> 198465.07 | E14: =E12*E13 -> 106367.13 | F14: =F12*F13 -> 0 | G14: =G12*G13 -> 0 | H14: =H12*H13 -> 0
A15: Capex de mantención + TI | C15: =Supuestos!$B$58*C5/2 -> 19359.971 | D15: =Supuestos!$B$58*D5 -> 42194.868 | E15: =Supuestos!$B$58*E5 -> 45127.869 | F15: =Supuestos!$B$58*F5 -> 47682.339 | G15: =Supuestos!$B$58*G5 -> 49731.156 | H15: =Supuestos!$B$58*H5 -> 51673.846 | I15: 5,5% de ingresos (2S26E: medio año de 2026E).
A16: Capex base total | C16: =C14+C15 -> 124994.03 | D16: =D14+D15 -> 240659.94 | E16: =E14+E15 -> 151495 | F16: =F14+F15 -> 47682.339 | G16: =G14+G15 -> 49731.156 | H16: =H14+H15 -> 51673.846 | I16: Sin la expansión post-pipeline (hoja Expansion).
A18: Ingreso anual por m² Chile (CLP) | C18: 341079.53 | D18: 360468.33 | E18: 378194.73 | F18: 395002.18 | G18: 411161.93 | H18: 426868.38 | I18: Exhibits v6, Forecast bloque D, Chile. Se aplica al GLA nuevo.
A19: Ingreso anual por m² Perú (PEN) | C19: 792.93865 | D19: 832.95944 | E19: 869.39102 | F19: 896.70772 | G19: 921.72945 | H19: 945.04514 | I19: Exhibits v6, Forecast bloque D, Perú.
A20: CLP por PEN (promedio) | C20: 267.99722 | D20: 275.85211 | E20: 279.34382 | F20: 284.77376 | G20: 287.56566 | H20: 290.38493 | I20: Exhibits v6, Forecast bloque A.

Sheet Expansion
A1: Expansión continua post-pipeline — capex con 2 años de construcción y rampa de ingresos
A2: Cada cohorte abre GLA nuevo al ritmo histórico. El capex se gasta en los 2 años previos a la apertura y los ingresos parten en el año de apertura con la rampa 35% / 90% / 100%. Se apaga con Supuestos E.
A4: Año del período | C4: 2S26E | D4: 2027E | E4: 2028E | F4: 2029E | G4: 2030E | H4: 2031E
A5: Año (número) | C5: 2026 | D5: 2027 | E5: 2028 | F5: 2029 | G5: 2030 | H5: 2031
A6: Índice de costo (IPC Chile, 2026 = 1) | C6: =(1+Supuestos!$B$34)^(C5-2026) -> 1 | D6: =(1+Supuestos!$B$34)^(D5-2026) -> 1.03 | E6: =(1+Supuestos!$B$34)^(E5-2026) -> 1.0609 | F6: =(1+Supuestos!$B$34)^(F5-2026) -> 1.092727 | G6: =(1+Supuestos!$B$34)^(G5-2026) -> 1.1255088 | H6: =(1+Supuestos!$B$34)^(H5-2026) -> 1.1592741
A7: Costo por m² (MM CLP) | C7: =Supuestos!$B$71*Supuestos!$B$72/1000000*C6 -> 3.3181974 | D7: =Supuestos!$B$71*Supuestos!$B$72/1000000*D6 -> 3.4177433 | E7: =Supuestos!$B$71*Supuestos!$B$72/1000000*E6 -> 3.5202756 | F7: =Supuestos!$B$71*Supuestos!$B$72/1000000*F6 -> 3.6258839 | G7: =Supuestos!$B$71*Supuestos!$B$72/1000000*G6 -> 3.7346604 | H7: =Supuestos!$B$71*Supuestos!$B$72/1000000*H6 -> 3.8467002 | J7: Costo del pipeline (USD/m²) × USDCLP 2026, indexado a IPC (obras en UF).
A8: Ingreso por m² de la expansión (CLP, mix Chile/Perú) | C8: =Supuestos!$B$75*Forecast_Base!C18+(1-Supuestos!$B$75)*Forecast_Base!C19*Forecast_Base!C20 -> 283080.83 | D8: =Supuestos!$B$75*Forecast_Base!D18+(1-Supuestos!$B$75)*Forecast_Base!D19*Forecast_Base!D20 -> 301513.07 | E8: =Supuestos!$B$75*Forecast_Base!E18+(1-Supuestos!$B$75)*Forecast_Base!E19*Forecast_Base!E20 -> 317145.96 | F8: =Supuestos!$B$75*Forecast_Base!F18+(1-Supuestos!$B$75)*Forecast_Base!F19*Forecast_Base!F20 -> 332010.27 | G8: =Supuestos!$B$75*Forecast_Base!G18+(1-Supuestos!$B$75)*Forecast_Base!G19*Forecast_Base!G20 -> 345255.59 | H8: =Supuestos!$B$75*Forecast_Base!H18+(1-Supuestos!$B$75)*Forecast_Base!H19*Forecast_Base!H20 -> 358103.33
A9: Margen EBITDA de la expansión | C9: =Supuestos!$B$75*Supuestos!$B$76+(1-Supuestos!$B$75)*Supuestos!$B$77 -> 0.80902183 | D9: =Supuestos!$B$75*Supuestos!$B$76+(1-Supuestos!$B$75)*Supuestos!$B$77 -> 0.80902183 | E9: =Supuestos!$B$75*Supuestos!$B$76+(1-Supuestos!$B$75)*Supuestos!$B$77 -> 0.80902183 | F9: =Supuestos!$B$75*Supuestos!$B$76+(1-Supuestos!$B$75)*Supuestos!$B$77 -> 0.80902183 | G9: =Supuestos!$B$75*Supuestos!$B$76+(1-Supuestos!$B$75)*Supuestos!$B$77 -> 0.80902183 | H9: =Supuestos!$B$75*Supuestos!$B$76+(1-Supuestos!$B$75)*Supuestos!$B$77 -> 0.80902183
A11: A. m² que abre cada cohorte | B11: m²
A12: =Supuestos!$B$67+0 -> 2029 | B12: =Supuestos!$B$66*Supuestos!$B$62 -> 27075.333 | J12: Las cohortes que abren después de 2031 tienen su capex dentro del horizonte: sostienen el valor terminal.
A13: =Supuestos!$B$67+1 -> 2030 | B13: =Supuestos!$B$66*Supuestos!$B$62 -> 27075.333
A14: =Supuestos!$B$67+2 -> 2031 | B14: =Supuestos!$B$66*Supuestos!$B$62 -> 27075.333
A15: =Supuestos!$B$67+3 -> 2032 | B15: =Supuestos!$B$66*Supuestos!$B$62 -> 27075.333
A16: =Supuestos!$B$67+4 -> 2033 | B16: =Supuestos!$B$66*Supuestos!$B$62 -> 27075.333
A18: B. Capex por cohorte (MM CLP)
A19: =A12 -> 2029 | C19: =IF(C$5=$A12-2,Supuestos!$B$68,IF(C$5=$A12-1,1-Supuestos!$B$68,0))*$B12*C$7 -> 0 | D19: =IF(D$5=$A12-2,Supuestos!$B$68,IF(D$5=$A12-1,1-Supuestos!$B$68,0))*$B12*D$7 -> 46268.27 | E19: =IF(E$5=$A12-2,Supuestos!$B$68,IF(E$5=$A12-1,1-Supuestos!$B$68,0))*$B12*E$7 -> 47656.318 | F19: =IF(F$5=$A12-2,Supuestos!$B$68,IF(F$5=$A12-1,1-Supuestos!$B$68,0))*$B12*F$7 -> 0 | G19: =IF(G$5=$A12-2,Supuestos!$B$68,IF(G$5=$A12-1,1-Supuestos!$B$68,0))*$B12*G$7 -> 0 | H19: =IF(H$5=$A12-2,Supuestos!$B$68,IF(H$5=$A12-1,1-Supuestos!$B$68,0))*$B12*H$7 -> 0
A20: =A13 -> 2030 | C20: =IF(C$5=$A13-2,Supuestos!$B$68,IF(C$5=$A13-1,1-Supuestos!$B$68,0))*$B13*C$7 -> 0 | D20: =IF(D$5=$A13-2,Supuestos!$B$68,IF(D$5=$A13-1,1-Supuestos!$B$68,0))*$B13*D$7 -> 0 | E20: =IF(E$5=$A13-2,Supuestos!$B$68,IF(E$5=$A13-1,1-Supuestos!$B$68,0))*$B13*E$7 -> 47656.318 | F20: =IF(F$5=$A13-2,Supuestos!$B$68,IF(F$5=$A13-1,1-Supuestos!$B$68,0))*$B13*F$7 -> 49086.008 | G20: =IF(G$5=$A13-2,Supuestos!$B$68,IF(G$5=$A13-1,1-Supuestos!$B$68,0))*$B13*G$7 -> 0 | H20: =IF(H$5=$A13-2,Supuestos!$B$68,IF(H$5=$A13-1,1-Supuestos!$B$68,0))*$B13*H$7 -> 0
A21: =A14 -> 2031 | C21: =IF(C$5=$A14-2,Supuestos!$B$68,IF(C$5=$A14-1,1-Supuestos!$B$68,0))*$B14*C$7 -> 0 | D21: =IF(D$5=$A14-2,Supuestos!$B$68,IF(D$5=$A14-1,1-Supuestos!$B$68,0))*$B14*D$7 -> 0 | E21: =IF(E$5=$A14-2,Supuestos!$B$68,IF(E$5=$A14-1,1-Supuestos!$B$68,0))*$B14*E$7 -> 0 | F21: =IF(F$5=$A14-2,Supuestos!$B$68,IF(F$5=$A14-1,1-Supuestos!$B$68,0))*$B14*F$7 -> 49086.008 | G21: =IF(G$5=$A14-2,Supuestos!$B$68,IF(G$5=$A14-1,1-Supuestos!$B$68,0))*$B14*G$7 -> 50558.588 | H21: =IF(H$5=$A14-2,Supuestos!$B$68,IF(H$5=$A14-1,1-Supuestos!$B$68,0))*$B14*H$7 -> 0
A22: =A15 -> 2032 | C22: =IF(C$5=$A15-2,Supuestos!$B$68,IF(C$5=$A15-1,1-Supuestos!$B$68,0))*$B15*C$7 -> 0 | D22: =IF(D$5=$A15-2,Supuestos!$B$68,IF(D$5=$A15-1,1-Supuestos!$B$68,0))*$B15*D$7 -> 0 | E22: =IF(E$5=$A15-2,Supuestos!$B$68,IF(E$5=$A15-1,1-Supuestos!$B$68,0))*$B15*E$7 -> 0 | F22: =IF(F$5=$A15-2,Supuestos!$B$68,IF(F$5=$A15-1,1-Supuestos!$B$68,0))*$B15*F$7 -> 0 | G22: =IF(G$5=$A15-2,Supuestos!$B$68,IF(G$5=$A15-1,1-Supuestos!$B$68,0))*$B15*G$7 -> 50558.588 | H22: =IF(H$5=$A15-2,Supuestos!$B$68,IF(H$5=$A15-1,1-Supuestos!$B$68,0))*$B15*H$7 -> 52075.346
A23: =A16 -> 2033 | C23: =IF(C$5=$A16-2,Supuestos!$B$68,IF(C$5=$A16-1,1-Supuestos!$B$68,0))*$B16*C$7 -> 0 | D23: =IF(D$5=$A16-2,Supuestos!$B$68,IF(D$5=$A16-1,1-Supuestos!$B$68,0))*$B16*D$7 -> 0 | E23: =IF(E$5=$A16-2,Supuestos!$B$68,IF(E$5=$A16-1,1-Supuestos!$B$68,0))*$B16*E$7 -> 0 | F23: =IF(F$5=$A16-2,Supuestos!$B$68,IF(F$5=$A16-1,1-Supuestos!$B$68,0))*$B16*F$7 -> 0 | G23: =IF(G$5=$A16-2,Supuestos!$B$68,IF(G$5=$A16-1,1-Supuestos!$B$68,0))*$B16*G$7 -> 0 | H23: =IF(H$5=$A16-2,Supuestos!$B$68,IF(H$5=$A16-1,1-Supuestos!$B$68,0))*$B16*H$7 -> 52075.346
A24: Total | C24: =SUM(C19:C23) -> 0 | D24: =SUM(D19:D23) -> 46268.27 | E24: =SUM(E19:E23) -> 95312.636 | F24: =SUM(F19:F23) -> 98172.015 | G24: =SUM(G19:G23) -> 101117.18 | H24: =SUM(H19:H23) -> 104150.69
A26: C. Ingresos por cohorte (MM CLP)
A27: =A12 -> 2029 | C27: =IF(C$5>=$A12,$B12*C$8/1000000*IF(C$5-$A12=0,Supuestos!$B$78,IF(C$5-$A12=1,Supuestos!$B$79,Supuestos!$B$80))*$C$39,0) -> 0 | D27: =IF(D$5>=$A12,$B12*D$8/1000000*IF(D$5-$A12=0,Supuestos!$B$78,IF(D$5-$A12=1,Supuestos!$B$79,Supuestos!$B$80))*$C$39,0) -> 0 | E27: =IF(E$5>=$A12,$B12*E$8/1000000*IF(E$5-$A12=0,Supuestos!$B$78,IF(E$5-$A12=1,Supuestos!$B$79,Supuestos!$B$80))*$C$39,0) -> 0 | F27: =IF(F$5>=$A12,$B12*F$8/1000000*IF(F$5-$A12=0,Supuestos!$B$78,IF(F$5-$A12=1,Supuestos!$B$79,Supuestos!$B$80))*$C$39,0) -> 3146.2511 | G27: =IF(G$5>=$A12,$B12*G$8/1000000*IF(G$5-$A12=0,Supuestos!$B$78,IF(G$5-$A12=1,Supuestos!$B$79,Supuestos!$B$80))*$C$39,0) -> 8413.1192 | H27: =IF(H$5>=$A12,$B12*H$8/1000000*IF(H$5-$A12=0,Supuestos!$B$78,IF(H$5-$A12=1,Supuestos!$B$79,Supuestos!$B$80))*$C$39,0) -> 9695.7671
A28: =A13 -> 2030 | C28: =IF(C$5>=$A13,$B13*C$8/1000000*IF(C$5-$A13=0,Supuestos!$B$78,IF(C$5-$A13=1,Supuestos!$B$79,Supuestos!$B$80))*$C$39,0) -> 0 | D28: =IF(D$5>=$A13,$B13*D$8/1000000*IF(D$5-$A13=0,Supuestos!$B$78,IF(D$5-$A13=1,Supuestos!$B$79,Supuestos!$B$80))*$C$39,0) -> 0 | E28: =IF(E$5>=$A13,$B13*E$8/1000000*IF(E$5-$A13=0,Supuestos!$B$78,IF(E$5-$A13=1,Supuestos!$B$79,Supuestos!$B$80))*$C$39,0) -> 0 | F28: =IF(F$5>=$A13,$B13*F$8/1000000*IF(F$5-$A13=0,Supuestos!$B$78,IF(F$5-$A13=1,Supuestos!$B$79,Supuestos!$B$80))*$C$39,0) -> 0 | G28: =IF(G$5>=$A13,$B13*G$8/1000000*IF(G$5-$A13=0,Supuestos!$B$78,IF(G$5-$A13=1,Supuestos!$B$79,Supuestos!$B$80))*$C$39,0) -> 3271.7686 | H28: =IF(H$5>=$A13,$B13*H$8/1000000*IF(H$5-$A13=0,Supuestos!$B$78,IF(H$5-$A13=1,Supuestos!$B$79,Supuestos!$B$80))*$C$39,0) -> 8726.1904
A29: =A14 -> 2031 | C29: =IF(C$5>=$A14,$B14*C$8/1000000*IF(C$5-$A14=0,Supuestos!$B$78,IF(C$5-$A14=1,Supuestos!$B$79,Supuestos!$B$80))*$C$39,0) -> 0 | D29: =IF(D$5>=$A14,$B14*D$8/1000000*IF(D$5-$A14=0,Supuestos!$B$78,IF(D$5-$A14=1,Supuestos!$B$79,Supuestos!$B$80))*$C$39,0) -> 0 | E29: =IF(E$5>=$A14,$B14*E$8/1000000*IF(E$5-$A14=0,Supuestos!$B$78,IF(E$5-$A14=1,Supuestos!$B$79,Supuestos!$B$80))*$C$39,0) -> 0 | F29: =IF(F$5>=$A14,$B14*F$8/1000000*IF(F$5-$A14=0,Supuestos!$B$78,IF(F$5-$A14=1,Supuestos!$B$79,Supuestos!$B$80))*$C$39,0) -> 0 | G29: =IF(G$5>=$A14,$B14*G$8/1000000*IF(G$5-$A14=0,Supuestos!$B$78,IF(G$5-$A14=1,Supuestos!$B$79,Supuestos!$B$80))*$C$39,0) -> 0 | H29: =IF(H$5>=$A14,$B14*H$8/1000000*IF(H$5-$A14=0,Supuestos!$B$78,IF(H$5-$A14=1,Supuestos!$B$79,Supuestos!$B$80))*$C$39,0) -> 3393.5185
A30: =A15 -> 2032 | C30: =IF(C$5>=$A15,$B15*C$8/1000000*IF(C$5-$A15=0,Supuestos!$B$78,IF(C$5-$A15=1,Supuestos!$B$79,Supuestos!$B$80))*$C$39,0) -> 0 | D30: =IF(D$5>=$A15,$B15*D$8/1000000*IF(D$5-$A15=0,Supuestos!$B$78,IF(D$5-$A15=1,Supuestos!$B$79,Supuestos!$B$80))*$C$39,0) -> 0 | E30: =IF(E$5>=$A15,$B15*E$8/1000000*IF(E$5-$A15=0,Supuestos!$B$78,IF(E$5-$A15=1,Supuestos!$B$79,Supuestos!$B$80))*$C$39,0) -> 0 | F30: =IF(F$5>=$A15,$B15*F$8/1000000*IF(F$5-$A15=0,Supuestos!$B$78,IF(F$5-$A15=1,Supuestos!$B$79,Supuestos!$B$80))*$C$39,0) -> 0 | G30: =IF(G$5>=$A15,$B15*G$8/1000000*IF(G$5-$A15=0,Supuestos!$B$78,IF(G$5-$A15=1,Supuestos!$B$79,Supuestos!$B$80))*$C$39,0) -> 0 | H30: =IF(H$5>=$A15,$B15*H$8/1000000*IF(H$5-$A15=0,Supuestos!$B$78,IF(H$5-$A15=1,Supuestos!$B$79,Supuestos!$B$80))*$C$39,0) -> 0
A31: =A16 -> 2033 | C31: =IF(C$5>=$A16,$B16*C$8/1000000*IF(C$5-$A16=0,Supuestos!$B$78,IF(C$5-$A16=1,Supuestos!$B$79,Supuestos!$B$80))*$C$39,0) -> 0 | D31: =IF(D$5>=$A16,$B16*D$8/1000000*IF(D$5-$A16=0,Supuestos!$B$78,IF(D$5-$A16=1,Supuestos!$B$79,Supuestos!$B$80))*$C$39,0) -> 0 | E31: =IF(E$5>=$A16,$B16*E$8/1000000*IF(E$5-$A16=0,Supuestos!$B$78,IF(E$5-$A16=1,Supuestos!$B$79,Supuestos!$B$80))*$C$39,0) -> 0 | F31: =IF(F$5>=$A16,$B16*F$8/1000000*IF(F$5-$A16=0,Supuestos!$B$78,IF(F$5-$A16=1,Supuestos!$B$79,Supuestos!$B$80))*$C$39,0) -> 0 | G31: =IF(G$5>=$A16,$B16*G$8/1000000*IF(G$5-$A16=0,Supuestos!$B$78,IF(G$5-$A16=1,Supuestos!$B$79,Supuestos!$B$80))*$C$39,0) -> 0 | H31: =IF(H$5>=$A16,$B16*H$8/1000000*IF(H$5-$A16=0,Supuestos!$B$78,IF(H$5-$A16=1,Supuestos!$B$79,Supuestos!$B$80))*$C$39,0) -> 0
A32: Total | C32: =SUM(C27:C31) -> 0 | D32: =SUM(D27:D31) -> 0 | E32: =SUM(E27:E31) -> 0 | F32: =SUM(F27:F31) -> 3146.2511 | G32: =SUM(G27:G31) -> 11684.888 | H32: =SUM(H27:H31) -> 21815.476
A33: EBITDA de la expansión | C33: =C32*C9 -> 0 | D33: =D32*D9 -> 0 | E33: =E32*E9 -> 0 | F33: =F32*F9 -> 2545.3858 | G33: =G32*G9 -> 9453.3292 | H33: =H32*H9 -> 17649.196
A35: D. Retorno de la expansión (alimenta el valor terminal)
A36: Yield on cost derivado (EBITDA maduro por m² / costo por m², 2026) | C36: =C8*C9/(C7*1000000) -> 0.069018971 | J36: Misma productividad que el forecast asume para el pipeline actual. El ingreso se indexa a inflación: es un yield real.
A37: Yield on cost usado | C37: =IF(Supuestos!$B$81="",C36,Supuestos!$B$81) -> 0.069018971
A38: RONIC real después de impuestos = yield × (1 − t) | C38: =C37*(1-Supuestos!$B$59) -> 0.050383849 | J38: Comparar con la WACC real (hoja WACC): si el RONIC es menor, crecer destruye valor.
A39: Ajuste de productividad de la expansión = yield usado / derivado | C39: =C37/C36 -> 1 | J39: Multiplica los ingresos de la expansión.

Sheet Capital_Trabajo
A1: Capital de trabajo — saldos de los EEFF y supuesto del modelo
A4: A. Saldos de balance operativos (MM CLP; EEFF consolidados Plaza S.A. y Filiales)
A5: Cuenta | C5: dic-23 | D5: dic-24 | E5: dic-25 | F5: mar-26 | G5: Fuente
A6: (+) Deudores comerciales y otras cuentas por cobrar corrientes | C6: 109044.23 | D6: 111058.3 | E6: 122369.81 | F6: 96333.76 | G6: dic-23: EEFF mar-24, p. 3 · dic-24: EEFF jun-25, p. 3 · dic-25 y mar-26: EEFF mar-26, p. 3 (M$ / 1.000).
A7: (+) Cuentas por cobrar a entidades relacionadas corrientes | C7: 45909.292 | D7: 19565.384 | E7: 13695.594 | F7: 9043.354 | G7: Arriendos por cobrar a tiendas del grupo controlador: operativo.
A8: Cuentas por pagar comerciales y otras cuentas por pagar (total) | C8: 115756.87 | D8: 95843.191 | E8: 122277.68 | F8: 169311.26 | G8: Incluye la provisión del dividendo mínimo (Nota 2.25), que es financiamiento y se excluye.
A9: menos: dividendo mínimo provisionado estimado (30% × utilidad distribuible) | C9: 59262 | D9: 71491.5 | E9: 110793.6 | G9: Nota 2.25. Supone sin dividendos provisorios.
A10: (−) Cuentas por pagar comerciales operativas (sin dividendos) | C10: =C8-C9 -> 56494.871 | D10: =D8-D9 -> 24351.691 | E10: =E8-E9 -> 11484.079
A11: (−) Cuentas por pagar a entidades relacionadas corrientes | C11: 34486.698 | D11: 2641.613 | E11: 2296.174 | F11: 2306.468
A12: (−) Otros pasivos no financieros corrientes | C12: 10367.061 | D12: 23176.757 | E12: 20246.646 | F12: 14591.09 | G12: Principalmente arriendos cobrados por anticipado y garantías: operativo.
A13: Ingresos del año | C13: 419904 | D13: 494605 | E13: 653911 | G13: Exhibits v6, Inputs.
A14: Excluidos: caja, deuda financiera y activos/pasivos por impuestos (los impuestos ya están en caja en el NOPAT).
A16: B. Capital de trabajo neto operativo
A17: Capital de trabajo neto operativo | C17: =C6+C7-C10-C11-C12 -> 53604.896 | D17: =D6+D7-D10-D11-D12 -> 80453.622 | E17: =E6+E7-E10-E11-E12 -> 102038.5
A18: Capital de trabajo neto / ingresos | C18: =C17/C13 -> 0.12765988 | D18: =D17/D13 -> 0.16266237 | E18: =E17/E13 -> 0.15604341
A19: Referencia: Δ capital de trabajo neto / Δ ingresos (dic-23 → dic-25) | E19: =(E17-C17)/(E13-C13) -> 0.20697503 | G19: Distorsionado: dic-24 ya consolida Perú pero los ingresos 2024 solo traen un mes.
A20: Supuesto del modelo: capital de trabajo neto / ingresos constante al nivel de dic-25 | F20: =E18 -> 0.15604341 | G20: Inversión anual = este % × Δ ingresos. Va a Supuestos (sección F).
A22: C. Lectura
A23: 1. Capital de trabajo neto operativo = deudores + cuentas por cobrar relacionadas − cuentas por pagar comerciales (sin dividendos) − cuentas por pagar relacionadas − otros pasivos no financieros.
A24: 2. La provisión del dividendo mínimo se resta de las cuentas por pagar porque es una obligación con accionistas, no de la operación.
A25: 3. Limitación: las cuentas por pagar comerciales también incluyen proveedores de obras (capex). Sin el desglose de la Nota 14/15 no se pueden separar.
A26: 4. Hay estacionalidad (mar-26: deudores bajan por recaudación, cuentas por pagar suben por el dividendo): se compara cierre contra cierre.
A27: 5. Se usa el nivel de dic-25 porque es el primer cierre con Perú completo tanto en balance como en ingresos.
A29: D. Referencia: brecha EBITDA − flujo operativo (MM CLP)
C30: FY2024 | D30: FY2025 | E30: 1S26
A31: EBITDA | C31: 380637 | D31: 526228 | E31: 270574
A32: Flujo operativo (EEFF) | C32: 300822 | D32: 441135 | E32: 258193
A33: Brecha = impuestos pagados + capital de trabajo + otros | C33: =C31-C32 -> 79815 | D33: =D31-D32 -> 85093 | E33: =E31-E32 -> 12381 | G33: Exhibits v6 (Inputs, E4_Cash). Mezcla impuestos y capital de trabajo: solo referencial.

Sheet DCF
A1: DCF de FCFF — Mallplaza · CLP nominales · valorización 30-06-2026 · WACC por período
A2: Flujos 2S26E–2031E con la expansión continua; valor terminal con reinversión explícita (solo el crecimiento real exige capex). Convención de mitad de período. Cada período se descuenta con su propia WACC (hoja WACC).
A4: MM CLP | C4: 2S26E | D4: 2027E | E4: 2028E | F4: 2029E | G4: 2030E | H4: 2031E | I4: Terminal (2032E)
A5: Ingresos base | C5: =Forecast_Base!C6 -> 364468.94 | D5: =Forecast_Base!D6 -> 767179.42 | E5: =Forecast_Base!E6 -> 820506.7 | F5: =Forecast_Base!F6 -> 866951.61 | G5: =Forecast_Base!G6 -> 904202.83 | H5: =Forecast_Base!H6 -> 939524.47
A6: Ingresos expansión | C6: =Expansion!C32 -> 0 | D6: =Expansion!D32 -> 0 | E6: =Expansion!E32 -> 0 | F6: =Expansion!F32 -> 3146.2511 | G6: =Expansion!G32 -> 11684.888 | H6: =Expansion!H32 -> 21815.476
A7: Ingresos totales | C7: =C5+C6 -> 364468.94 | D7: =D5+D6 -> 767179.42 | E7: =E5+E6 -> 820506.7 | F7: =F5+F6 -> 870097.86 | G7: =G5+G6 -> 915887.72 | H7: =H5+H6 -> 961339.95 | I7: =C34*(1+Supuestos!$B$88) -> 1007656.8
A8: Crecimiento ingresos (año calendario) | C8: =(Forecast_Base!C5+C6)/Supuestos!$B$56-1 -> 0.07659748 | D8: =D7/Forecast_Base!C5-1 -> 0.089745147 | E8: =E7/D7-1 -> 0.069510831 | F8: =F7/E7-1 -> 0.060439677 | G8: =G7/F7-1 -> 0.052626099 | H8: =H7/G7-1 -> 0.049626424
A9: EBITDA base | C9: =Forecast_Base!C8 -> 290741.41 | D9: =Forecast_Base!D8 -> 611360.36 | E9: =Forecast_Base!E8 -> 654236.23 | F9: =Forecast_Base!F8 -> 691459.84 | G9: =Forecast_Base!G8 -> 721124.37 | H9: =Forecast_Base!H8 -> 749208.58
A10: EBITDA expansión | C10: =Expansion!C33 -> 0 | D10: =Expansion!D33 -> 0 | E10: =Expansion!E33 -> 0 | F10: =Expansion!F33 -> 2545.3858 | G10: =Expansion!G33 -> 9453.3292 | H10: =Expansion!H33 -> 17649.196
A11: EBITDA total | C11: =C9+C10 -> 290741.41 | D11: =D9+D10 -> 611360.36 | E11: =E9+E10 -> 654236.23 | F11: =F9+F10 -> 694005.23 | G11: =G9+G10 -> 730577.7 | H11: =H9+H10 -> 766857.78 | I11: =C35*(1+Supuestos!$B$88) -> 804002.48
A12: Margen EBITDA | C12: =C11/C7 -> 0.79771244 | D12: =D11/D7 -> 0.79689358 | E12: =E11/E7 -> 0.79735635 | F12: =F11/F7 -> 0.79761744 | G12: =G11/G7 -> 0.79767169 | H12: =H11/H7 -> 0.79769677 | I12: =I11/I7 -> 0.79789319
A13: (−) D&A | C13: =Supuestos!$B$57*C7 -> 2564.5568 | D13: =Supuestos!$B$57*D7 -> 5398.1972 | E13: =Supuestos!$B$57*E7 -> 5773.4304 | F13: =Supuestos!$B$57*F7 -> 6122.3747 | G13: =Supuestos!$B$57*G7 -> 6444.5714 | H13: =Supuestos!$B$57*H7 -> 6764.3924 | I13: =Supuestos!$B$57*I7 -> 7090.297
A14: EBIT | C14: =C11-C13 -> 288176.85 | D14: =D11-D13 -> 605962.16 | E14: =E11-E13 -> 648462.8 | F14: =F11-F13 -> 687882.85 | G14: =G11-G13 -> 724133.13 | H14: =H11-H13 -> 760093.38 | I14: =I11-I13 -> 796912.18
A15: Tasa de impuesto operacional | C15: =Forecast_Base!C11 -> 0.168 | D15: =Forecast_Base!D11 -> 0.19 | E15: =Forecast_Base!E11 -> 0.215 | F15: =Forecast_Base!F11 -> 0.24 | G15: =Forecast_Base!G11 -> 0.27 | H15: =Forecast_Base!H11 -> 0.27 | I15: =Supuestos!$B$59 -> 0.27
A16: (−) Impuestos operacionales | C16: =-C14*C15 -> -48413.711 | D16: =-D14*D15 -> -115132.81 | E16: =-E14*E15 -> -139419.5 | F16: =-F14*F15 -> -165091.88 | G16: =-G14*G15 -> -195515.95 | H16: =-H14*H15 -> -205225.21 | I16: =-I14*I15 -> -215166.29
A17: NOPAT | C17: =C14+C16 -> 239763.14 | D17: =D14+D16 -> 490829.35 | E17: =E14+E16 -> 509043.29 | F17: =F14+F16 -> 522790.97 | G17: =G14+G16 -> 528617.18 | H17: =H14+H16 -> 554868.17 | I17: =I14+I16 -> 581745.89
A18: (+) D&A | C18: =C13 -> 2564.5568 | D18: =D13 -> 5398.1972 | E18: =E13 -> 5773.4304 | F18: =F13 -> 6122.3747 | G18: =G13 -> 6444.5714 | H18: =H13 -> 6764.3924 | I18: =I13 -> 7090.297
A19: (−) Capex base (pipeline + mantención) | C19: =-Forecast_Base!C16 -> -124994.03 | D19: =-Forecast_Base!D16 -> -240659.94 | E19: =-Forecast_Base!E16 -> -151495 | F19: =-Forecast_Base!F16 -> -47682.339 | G19: =-Forecast_Base!G16 -> -49731.156 | H19: =-Forecast_Base!H16 -> -51673.846 | I19: =-Supuestos!$B$58*I7 -> -55421.122 | J19: Terminal: mantención 5,5% de ingresos.
A20: (−) Capex expansión / reinversión terminal | C20: =-Expansion!C24 -> 0 | D20: =-Expansion!D24 -> -46268.27 | E20: =-Expansion!E24 -> -95312.636 | F20: =-Expansion!F24 -> -98172.015 | G20: =-Expansion!G24 -> -101117.18 | H20: =-Expansion!H24 -> -104150.69 | I20: =-Supuestos!$B$89/Expansion!$C$38*I17 -> 0 | J20: Terminal: reinversión = g real / RONIC × NOPAT (value driver).
A21: (−) Inversión en capital de trabajo | C21: =-Supuestos!$B$84*Supuestos!$B$85*(Forecast_Base!C5-Supuestos!$B$56)/2 -> -3907.946 | D21: =-Supuestos!$B$84*Supuestos!$B$85*(D7-Forecast_Base!C5) -> -9858.8987 | E21: =-Supuestos!$B$84*Supuestos!$B$85*(E7-D7) -> -8321.3704 | F21: =-Supuestos!$B$84*Supuestos!$B$85*(F7-E7) -> -7738.3736 | G21: =-Supuestos!$B$84*Supuestos!$B$85*(G7-F7) -> -7145.2052 | H21: =-Supuestos!$B$84*Supuestos!$B$85*(H7-G7) -> -7092.5212 | I21: =-Supuestos!$B$84*Supuestos!$B$85*(I7-C34) -> -4579.7533 | J21: % del Δ ingresos (Supuestos F). 2S26E: medio año.
A22: FCFF | C22: =C17+C18+C19+C20+C21 -> 113425.72 | D22: =D17+D18+D19+D20+D21 -> 199440.44 | E22: =E17+E18+E19+E20+E21 -> 259687.72 | F22: =F17+F18+F19+F20+F21 -> 375320.62 | G22: =G17+G18+G19+G20+G21 -> 377068.22 | H22: =H17+H18+H19+H20+H21 -> 398715.5 | I22: =I17+I18+I19+I20+I21 -> 528835.31
A24: Descuento: WACC por período
A25: WACC nominal del período (hoja WACC) | C25: =WACC!C43 -> 0.10536861 | D25: =WACC!D43 -> 0.10509036 | E25: =WACC!E43 -> 0.10482887 | F25: =WACC!F43 -> 0.10458351 | G25: =WACC!G43 -> 0.1043537 | H25: =WACC!H43 -> 0.10413887 | I25: =WACC!I43 -> 0.10413887
A26: Fracción de año del período | C26: 0.5 | D26: 1 | E26: 1 | F26: 1 | G26: 1 | H26: 1
A27: Factor de descuento al cierre del período | C27: =(1+C25)^-C26 -> 0.95114436 | D27: =C27*(1+D25)^-D26 -> 0.86069374 | E27: =D27*(1+E25)^-E26 -> 0.77902902 | F27: =E27*(1+F25)^-F26 -> 0.70526946 | G27: =F27*(1+G25)^-G26 -> 0.63862643 | H27: =G27*(1+H25)^-H26 -> 0.57839322
A28: Factor de descuento a mitad del período | C28: =(1+C25)^-(C26/2) -> 0.9752663 | D28: =C27*(1+D25)^-(D26/2) -> 0.90478948 | E28: =D27*(1+E25)^-(E26/2) -> 0.81884394 | F28: =E27*(1+F25)^-(F26/2) -> 0.74123233 | G28: =F27*(1+G25)^-(G26/2) -> 0.67112124 | H28: =G27*(1+H25)^-(H26/2) -> 0.6077641 | J28: 2S26E a 0,25 años; luego la mitad de cada año desde el 30-06-2026.
A29: Valor presente del FCFF | C29: =C22*C28 -> 110620.28 | D29: =D22*D28 -> 180451.61 | E29: =E22*E28 -> 212643.72 | F29: =F22*F28 -> 278199.78 | G29: =G22*G28 -> 253058.49 | H29: =H22*H28 -> 242324.97
A31: Normalización 2031: base + expansión financiada (cohortes cuyo capex cae completo en el horizonte) a madurez
A32: Último año de apertura con capex completo dentro del horizonte | C32: =Expansion!H5+1 -> 2032 | J32: El capex de esas cohortes ya está en el FCFF explícito, pero sus ingresos maduran después de 2031: el año terminal los cuenta al 100%. La cohorte siguiente (solo parte del capex dentro) queda en la reinversión terminal.
A33: m² maduros que se suman al año terminal | C33: =SUMIF(Expansion!$A$12:$A$16,"<="&C32,Expansion!$B$12:$B$16) -> 108301.33
A34: Ingresos 2031 normalizados | C34: =Forecast_Base!H5+C33*Expansion!H8/1000000*Expansion!C39 -> 978307.54
A35: EBITDA 2031 normalizado | C35: =Forecast_Base!H7+(C34-Forecast_Base!H5)*Expansion!H9 -> 780584.93
A37: Valor de la empresa → valor por acción
A38: WACC terminal (estructura objetivo) | C38: =I25 -> 0.10413887
A39: Crecimiento terminal nominal (g) | C39: =Supuestos!$B$88 -> 0.03
A40: Tasa de reinversión terminal (g real / RONIC) | C40: =Supuestos!$B$89/Expansion!$C$38 -> 0
A41: Valor terminal al 31-12-2031 = FCFF 2032E / (WACC terminal − g) | C41: =I22/(C38-C39) -> 7133037.4
A42: Valor presente del valor terminal | C42: =C41*H27 -> 4125700.4
A43: Suma VP del FCFF explícito | C43: =SUM(C29:H29) -> 1277298.8
A44: Enterprise value | C44: =C43+C42 -> 5402999.3
...

Sheet Deuda
A1: Deuda — trayectoria desde la estructura actual hasta el objetivo de largo plazo
A2: DFN(t) = DFN(t−1) − FCFF + costo financiero y reajuste UF (después de impuestos) + dividendos ordinarios + distribución adicional. La distribución adicional (recompra o dividendo extra) cierra la brecha con el DFN/EBITDA objetivo. No entra en el EV (FCFF desapalancado): define la estructura de capital de la WACC.
A4: MM CLP | C4: 2S26E | D4: 2027E | E4: 2028E | F4: 2029E | G4: 2030E | H4: 2031E
A5: Años desde 30-06-2026 al cierre del período | C5: =DCF!C26 -> 0.5 | D5: =C5+DCF!D26 -> 1.5 | E5: =D5+DCF!E26 -> 2.5 | F5: =E5+DCF!F26 -> 3.5 | G5: =F5+DCF!G26 -> 4.5 | H5: =G5+DCF!H26 -> 5.5
A6: EBITDA año calendario (para el ratio) | C6: =Forecast_Base!C7+DCF!C10 -> 561315.41 | D6: =DCF!D11 -> 611360.36 | E6: =DCF!E11 -> 654236.23 | F6: =DCF!F11 -> 694005.23 | G6: =DCF!G11 -> 730577.7 | H6: =DCF!H11 -> 766857.78 | J6: 2S26E: EBITDA 2026E año completo (LTM al cierre).
A7: DFN de apertura | C7: =Supuestos!$B$10 -> 1285740 | D7: =C21 -> 1382589.9 | E7: =D21 -> 1632637.8 | F7: =E21 -> 1882810 | G7: =F21 -> 2141179.6 | H7: =G21 -> 2405518.4
A8: DFN / EBITDA de apertura | C8: =Supuestos!$B$41 -> 2.3594374 | D8: =C22 -> 2.4631249 | E8: =D22 -> 2.6704999 | F8: =E22 -> 2.8778749 | G8: =F22 -> 3.08525 | H8: =G22 -> 3.292625
A9: Costo financiero neto / DFN (con spread por apalancamiento) | C9: =Supuestos!$B$46+Supuestos!$B$40*Supuestos!$B$45*MAX(0,C8-Supuestos!$B$41) -> 0.0308 | D9: =Supuestos!$B$46+Supuestos!$B$40*Supuestos!$B$45*MAX(0,D8-Supuestos!$B$41) -> 0.031059219 | E9: =Supuestos!$B$46+Supuestos!$B$40*Supuestos!$B$45*MAX(0,E8-Supuestos!$B$41) -> 0.031577656 | F9: =Supuestos!$B$46+Supuestos!$B$40*Supuestos!$B$45*MAX(0,F8-Supuestos!$B$41) -> 0.032096094 | G9: =Supuestos!$B$46+Supuestos!$B$40*Supuestos!$B$45*MAX(0,G8-Supuestos!$B$41) -> 0.032614531 | H9: =Supuestos!$B$46+Supuestos!$B$40*Supuestos!$B$45*MAX(0,H8-Supuestos!$B$41) -> 0.033132969 | J9: 3,08% inicial + spread por cada vuelta sobre el nivel inicial.
A10: (−) FCFF | C10: =-DCF!C22 -> -113425.72 | D10: =-DCF!D22 -> -199440.44 | E10: =-DCF!E22 -> -259687.72 | F10: =-DCF!F22 -> -375320.62 | G10: =-DCF!G22 -> -377068.22 | H10: =-DCF!H22 -> -398715.5
A11: Costo financiero neto antes de impuestos | C11: =C7*C9*DCF!C26 -> 19800.396 | D11: =D7*D9*DCF!D26 -> 42942.163 | E11: =E7*E9*DCF!E26 -> 51554.875 | F11: =F7*F9*DCF!F26 -> 60430.848 | G11: =G7*G9*DCF!G26 -> 69833.569 | H11: =H7*H9*DCF!H26 -> 79701.966
A12: (+) Costo financiero neto después de impuestos | C12: =C11*(1-DCF!C15) -> 16473.929 | D12: =D11*(1-DCF!D15) -> 34783.152 | E12: =E11*(1-DCF!E15) -> 40470.577 | F12: =F11*(1-DCF!F15) -> 45927.444 | G12: =G11*(1-DCF!G15) -> 50978.506 | H12: =H11*(1-DCF!H15) -> 58182.435
A13: Reajuste UF de la deuda antes de impuestos | C13: =C7*Supuestos!$B$47*Supuestos!$B$34*DCF!C26 -> 15236.019 | D13: =D7*Supuestos!$B$47*Supuestos!$B$34*DCF!D26 -> 32767.382 | E13: =E7*Supuestos!$B$47*Supuestos!$B$34*DCF!E26 -> 38693.515 | F13: =F7*Supuestos!$B$47*Supuestos!$B$34*DCF!F26 -> 44622.598 | G13: =G7*Supuestos!$B$47*Supuestos!$B$34*DCF!G26 -> 50745.956 | H13: =H7*Supuestos!$B$47*Supuestos!$B$34*DCF!H26 -> 57010.786
A14: (+) Reajuste UF después de impuestos | C14: =C13*(1-DCF!C15) -> 12676.368 | D14: =D13*(1-DCF!D15) -> 26541.579 | E14: =E13*(1-DCF!E15) -> 30374.41 | F14: =F13*(1-DCF!F15) -> 33913.174 | G14: =G13*(1-DCF!G15) -> 37044.548 | H14: =H13*(1-DCF!H15) -> 41617.874 | J14: v2: el reajuste UF es gasto financiero deducible (el VF lo sumaba sin escudo). Consistente con Kd nominal × (1 − t) en la WACC.
A15: Utilidad distribuible proxy (FFO − reajuste UF) | C15: =Supuestos!$B$51 -> 380038.82 | D15: =D6-DCF!D15*(D6-D11)-D11-D13 -> 427651.36 | E15: =E6-DCF!E15*(E6-E11)-E11-E13 -> 434411.34 | F15: =F6-DCF!F15*(F6-F11)-F11-F13 -> 436893.93 | G15: =G6-DCF!G15*(G6-G11)-G11-G13 -> 431597.26 | H15: =H6-DCF!H15*(H6-H11)-H11-H13 -> 444612.96 | J15: 2S26E: distribuible 2026E de Exhibits v6. Proxy sin minoritarios.
A16: (+) Dividendos ordinarios | C16: =Supuestos!$B$49-Supuestos!$B$50 -> 60107.8 | D16: =Supuestos!$B$48*C15 -> 152015.53 | E16: =Supuestos!$B$48*D15 -> 171060.54 | F16: =Supuestos!$B$48*E15 -> 173764.54 | G16: =Supuestos!$B$48*F15 -> 174757.57 | H16: =Supuestos!$B$48*G15 -> 172638.9 | J16: 2S26E: dividendos 2026E − pagado 1S26. 2027E+: payout × distribuible del año anterior.
A17: DFN de cierre antes de distribución adicional | C17: =C7+C10+C12+C14+C16 -> 1261572.4 | D17: =D7+D10+D12+D14+D16 -> 1396489.8 | E17: =E7+E10+E12+E14+E16 -> 1614855.6 | F17: =F7+F10+F12+F14+F16 -> 1761094.6 | G17: =G7+G10+G12+G14+G16 -> 2026892 | H17: =H7+H10+H12+H14+H16 -> 2279242.1
A18: DFN / EBITDA objetivo del período | C18: =IF(Supuestos!$B$40=1,Supuestos!$B$41+(Supuestos!$B$42-Supuestos!$B$41)*MIN(1,C5/Supuestos!$B$44),C17/C6) -> 2.4631249 | D18: =IF(Supuestos!$B$40=1,Supuestos!$B$41+(Supuestos!$B$42-Supuestos!$B$41)*MIN(1,D5/Supuestos!$B$44),D17/D6) -> 2.6704999 | E18: =IF(Supuestos!$B$40=1,Supuestos!$B$41+(Supuestos!$B$42-Supuestos!$B$41)*MIN(1,E5/Supuestos!$B$44),E17/E6) -> 2.8778749 | F18: =IF(Supuestos!$B$40=1,Supuestos!$B$41+(Supuestos!$B$42-Supuestos!$B$41)*MIN(1,F5/Supuestos!$B$44),F17/F6) -> 3.08525 | G18: =IF(Supuestos!$B$40=1,Supuestos!$B$41+(Supuestos!$B$42-Supuestos!$B$41)*MIN(1,G5/Supuestos!$B$44),G17/G6) -> 3.292625 | H18: =IF(Supuestos!$B$40=1,Supuestos!$B$41+(Supuestos!$B$42-Supuestos!$B$41)*MIN(1,H5/Supuestos!$B$44),H17/H6) -> 3.5 | J18: Convergencia lineal hasta el año objetivo (Supuestos C).
A19: DFN objetivo | C19: =C18*C6 -> 1382589.9 | D19: =D18*D6 -> 1632637.8 | E19: =E18*E6 -> 1882810 | F19: =F18*F6 -> 2141179.6 | G19: =G18*G6 -> 2405518.4 | H19: =H18*H6 -> 2684002.2
A20: (+) Distribución adicional a accionistas (recompra / dividendo extra) | C20: =IF(Supuestos!$B$40=1,C19-C17,0) -> 121017.56 | D20: =IF(Supuestos!$B$40=1,D19-D17,0) -> 236148.03 | E20: =IF(Supuestos!$B$40=1,E19-E17,0) -> 267954.44 | F20: =IF(Supuestos!$B$40=1,F19-F17,0) -> 380085.03 | G20: =IF(Supuestos!$B$40=1,G19-G17,0) -> 378626.38 | H20: =IF(Supuestos!$B$40=1,H19-H17,0) -> 404760.12 | J20: Negativo = la compañía tendría que retener caja para no superar el objetivo.
A21: DFN de cierre | C21: =C17+C20 -> 1382589.9 | D21: =D17+D20 -> 1632637.8 | E21: =E17+E20 -> 1882810 | F21: =F17+F20 -> 2141179.6 | G21: =G17+G20 -> 2405518.4 | H21: =H17+H20 -> 2684002.2
A22: DFN / EBITDA de cierre | C22: =C21/C6 -> 2.4631249 | D22: =D21/D6 -> 2.6704999 | E22: =E21/E6 -> 2.8778749 | F22: =F21/F6 -> 3.08525 | G22: =G21/G6 -> 3.292625 | H22: =H21/H6 -> 3.5
A23: Deuda financiera bruta de cierre (DFN + caja) | C23: =C21+Supuestos!$B$12 -> 1730210.9 | D23: =D21+Supuestos!$B$12 -> 1980258.8 | E23: =E21+Supuestos!$B$12 -> 2230431 | F23: =F21+Supuestos!$B$12 -> 2488800.6 | G23: =G21+Supuestos!$B$12 -> 2753139.4 | H23: =H21+Supuestos!$B$12 -> 3031623.2 | J23: Caja constante al nivel de jun-26.
A24: Capacidad de deuda remanente al objetivo de LP (objetivo × EBITDA − DFN) | C24: =Supuestos!$B$42*C6-C21 -> 582013.98 | D24: =Supuestos!$B$42*D6-D21 -> 507123.48 | E24: =Supuestos!$B$42*E6-E21 -> 407016.76 | F24: =Supuestos!$B$42*F6-F21 -> 287838.7 | G24: =Supuestos!$B$42*G6-G21 -> 151503.57 | H24: =Supuestos!$B$42*H6-H21 -> 0
A25: Distribuciones adicionales acumuladas | C25: =C20 -> 121017.56 | D25: =C25+D20 -> 357165.58 | E25: =D25+E20 -> 625120.02 | F25: =E25+F20 -> 1005205 | G25: =F25+G20 -> 1383831.4 | H25: =G25+H20 -> 1788591.5

Sheet APV
A1: APV — chequeo de consistencia: valor desapalancado + VP de los escudos fiscales de la deuda proyectada
A2: Los escudos se descuentan a Ku porque la deuda se reajusta con el tamaño de la empresa (objetivo como múltiplo del EBITDA), el mismo supuesto implícito en una WACC.
A4: Ku antes de conversión = Rf + βu × ERP + CRP | C4: =WACC!$C$22+WACC!$H$13*Supuestos!$B$22+WACC!$C$21 -> 0.10291119
A5: Ku nominal CLP | C5: =IF(AND(Supuestos!$B$21=1,Supuestos!$B$19=2),(1+C4)*(1+Supuestos!$B$34)/(1+Supuestos!$B$20)-1,C4) -> 0.11107598
A7: MM CLP | C7: 2S26E | D7: 2027E | E7: 2028E | F7: 2029E | G7: 2030E | H7: 2031E | I7: Terminal
A8: FCFF | C8: =DCF!C22 -> 113425.72 | D8: =DCF!D22 -> 199440.44 | E8: =DCF!E22 -> 259687.72 | F8: =DCF!F22 -> 375320.62 | G8: =DCF!G22 -> 377068.22 | H8: =DCF!H22 -> 398715.5 | I8: =DCF!I22 -> 528835.31
A9: Factor de descuento a Ku, cierre | C9: =(1+$C$5)^-DCF!C26 -> 0.9486983 | D9: =C9*(1+$C$5)^-DCF!D26 -> 0.85385546 | E9: =D9*(1+$C$5)^-DCF!E26 -> 0.76849422 | F9: =E9*(1+$C$5)^-DCF!F26 -> 0.69166666 | G9: =F9*(1+$C$5)^-DCF!G26 -> 0.62251968 | H9: =G9*(1+$C$5)^-DCF!H26 -> 0.56028543
A10: Factor de descuento a Ku, mitad | C10: =(1+$C$5)^-(DCF!C26/2) -> 0.97401145 | D10: =C9*(1+$C$5)^-(DCF!D26/2) -> 0.90002846 | E10: =D9*(1+$C$5)^-(DCF!E26/2) -> 0.81005122 | F10: =E9*(1+$C$5)^-(DCF!F26/2) -> 0.72906915 | G10: =F9*(1+$C$5)^-(DCF!G26/2) -> 0.65618299 | H10: =G9*(1+$C$5)^-(DCF!H26/2) -> 0.59058336
A11: VP del FCFF a Ku | C11: =C8*C10 -> 110477.95 | D11: =D8*D10 -> 179502.07 | E11: =E8*E10 -> 210360.35 | F11: =F8*F10 -> 273634.68 | G11: =G8*G10 -> 247425.75 | H11: =H8*H10 -> 235474.74 | I11: =I8/($C$5-Supuestos!$B$88)*H9 -> 3654580.8
A12: Deuda bruta de apertura | C12: =Supuestos!$B$10+Supuestos!$B$12 -> 1633361 | D12: =Deuda!C23 -> 1730210.9 | E12: =Deuda!D23 -> 1980258.8 | F12: =Deuda!E23 -> 2230431 | G12: =Deuda!F23 -> 2488800.6 | H12: =Deuda!G23 -> 2753139.4 | I12: =Deuda!H23 -> 3031623.2
A13: Kd nominal del período (hoja WACC) | C13: =WACC!C41 -> 0.067346995 | D13: =WACC!D41 -> 0.067880986 | E13: =WACC!E41 -> 0.068414977 | F13: =WACC!F41 -> 0.068948967 | G13: =WACC!G41 -> 0.069482958 | H13: =WACC!H41 -> 0.070016949 | I13: =WACC!I41 -> 0.070016949
A14: Escudo fiscal = t × Kd × D | C14: =Supuestos!$B$35*C13*C12*DCF!C26 -> 14850.264 | D14: =Supuestos!$B$35*D13*D12*DCF!D26 -> 31711.075 | E14: =Supuestos!$B$35*E13*E12*DCF!E26 -> 36579.427 | F14: =Supuestos!$B$35*F13*F12*DCF!F26 -> 41522.197 | G14: =Supuestos!$B$35*G13*G12*DCF!G26 -> 46690.891 | H14: =Supuestos!$B$35*H13*H12*DCF!H26 -> 52046.933 | I14: =Supuestos!$B$35*I13*I12*(1+Supuestos!$B$88) -> 59030.899 | J14: Terminal: escudo 2032E sobre la deuda de cierre 2031, creciendo con g.
A15: VP del escudo fiscal a Ku | C15: =C14*C10 -> 14464.327 | D15: =D14*D10 -> 28540.87 | E15: =E14*E10 -> 29631.209 | F15: =F14*F10 -> 30272.553 | G15: =G14*G10 -> 30637.769 | H15: =H14*H10 -> 30738.053 | I15: =I14/($C$5-Supuestos!$B$88)*H9 -> 407940.21
A17: Valor desapalancado (FCFF a Ku) | C17: =SUM(C11:I11) -> 4911456.4
A18: VP de los escudos fiscales | C18: =SUM(C15:I15) -> 572224.99
A19: Enterprise value APV | C19: =C17+C18 -> 5483681.3
A20: Valor del patrimonio | C20: =C19-Supuestos!$B$10-Supuestos!$B$11 -> 4147100.3
A21: Valor por acción APV (CLP) | C21: =C20/Supuestos!$B$9 -> 1893.6531
A22: de lo cual: valor sin deuda (CLP/acción) | C22: =(C17-Supuestos!$B$10-Supuestos!$B$11)/Supuestos!$B$9 -> 1632.3632
A23: de lo cual: escudos fiscales (CLP/acción) | C23: =C18/Supuestos!$B$9 -> 261.28995

Sheet Sensibilidad
A1: Sensibilidad — valor por acción DCF (CLP)
A3: Tabla 1: desplazamiento paralelo de la WACC de todos los períodos (filas) vs g nominal terminal (columnas). Fórmulas vivas.
A5: Δ WACC \ g | B5: 0.025 | C5: 0.03 | D5: 0.035 | E5: 0.04
A6: -0.01 | B6: =(SUM($C$30:$H$30)+B$25/(DCF!$I$25+$A$6-B$5)*$H$28-Supuestos!$B$10-Supuestos!$B$11)/Supuestos!$B$9 -> 2328.9076 | C6: =(SUM($C$30:$H$30)+C$25/(DCF!$I$25+$A$6-C$5)*$H$28-Supuestos!$B$10-Supuestos!$B$11)/Supuestos!$B$9 -> 2277.8022 | D6: =(SUM($C$30:$H$30)+D$25/(DCF!$I$25+$A$6-D$5)*$H$28-Supuestos!$B$10-Supuestos!$B$11)/Supuestos!$B$9 -> 2215.5004 | E6: =(SUM($C$30:$H$30)+E$25/(DCF!$I$25+$A$6-E$5)*$H$28-Supuestos!$B$10-Supuestos!$B$11)/Supuestos!$B$9 -> 2138.9
A7: -0.005 | B7: =(SUM($C$33:$H$33)+B$25/(DCF!$I$25+$A$7-B$5)*$H$31-Supuestos!$B$10-Supuestos!$B$11)/Supuestos!$B$9 -> 2109.1674 | C7: =(SUM($C$33:$H$33)+C$25/(DCF!$I$25+$A$7-C$5)*$H$31-Supuestos!$B$10-Supuestos!$B$11)/Supuestos!$B$9 -> 2051.7993 | D7: =(SUM($C$33:$H$33)+D$25/(DCF!$I$25+$A$7-D$5)*$H$31-Supuestos!$B$10-Supuestos!$B$11)/Supuestos!$B$9 -> 1983.1896 | E7: =(SUM($C$33:$H$33)+E$25/(DCF!$I$25+$A$7-E$5)*$H$31-Supuestos!$B$10-Supuestos!$B$11)/Supuestos!$B$9 -> 1900.4868
A8: 0 | B8: =(SUM($C$36:$H$36)+B$25/(DCF!$I$25+$A$8-B$5)*$H$34-Supuestos!$B$10-Supuestos!$B$11)/Supuestos!$B$9 -> 1917.8387 | C8: =(SUM($C$36:$H$36)+C$25/(DCF!$I$25+$A$8-C$5)*$H$34-Supuestos!$B$10-Supuestos!$B$11)/Supuestos!$B$9 -> 1856.812 | D8: =(SUM($C$36:$H$36)+D$25/(DCF!$I$25+$A$8-D$5)*$H$34-Supuestos!$B$10-Supuestos!$B$11)/Supuestos!$B$9 -> 1784.8799 | E8: =(SUM($C$36:$H$36)+E$25/(DCF!$I$25+$A$8-E$5)*$H$34-Supuestos!$B$10-Supuestos!$B$11)/Supuestos!$B$9 -> 1699.4919
A9: 0.005 | B9: =(SUM($C$39:$H$39)+B$25/(DCF!$I$25+$A$9-B$5)*$H$37-Supuestos!$B$10-Supuestos!$B$11)/Supuestos!$B$9 -> 1749.8355 | C9: =(SUM($C$39:$H$39)+C$25/(DCF!$I$25+$A$9-C$5)*$H$37-Supuestos!$B$10-Supuestos!$B$11)/Supuestos!$B$9 -> 1686.9439 | D9: =(SUM($C$39:$H$39)+D$25/(DCF!$I$25+$A$9-D$5)*$H$37-Supuestos!$B$10-Supuestos!$B$11)/Supuestos!$B$9 -> 1613.6784 | E9: =(SUM($C$39:$H$39)+E$25/(DCF!$I$25+$A$9-E$5)*$H$37-Supuestos!$B$10-Supuestos!$B$11)/Supuestos!$B$9 -> 1527.7883
A10: 0.01 | B10: =(SUM($C$42:$H$42)+B$25/(DCF!$I$25+$A$10-B$5)*$H$40-Supuestos!$B$10-Supuestos!$B$11)/Supuestos!$B$9 -> 1601.2133 | C10: =(SUM($C$42:$H$42)+C$25/(DCF!$I$25+$A$10-C$5)*$H$40-Supuestos!$B$10-Supuestos!$B$11)/Supuestos!$B$9 -> 1537.7009 | D10: =(SUM($C$42:$H$42)+D$25/(DCF!$I$25+$A$10-D$5)*$H$40-Supuestos!$B$10-Supuestos!$B$11)/Supuestos!$B$9 -> 1464.4349 | E10: =(SUM($C$42:$H$42)+E$25/(DCF!$I$25+$A$10-E$5)*$H$40-Supuestos!$B$10-Supuestos!$B$11)/Supuestos!$B$9 -> 1379.4419
A12: La celda resaltada debe igualar el valor por acción de la hoja DCF.
A14: Tabla 2 (estática): DFN/EBITDA objetivo (filas) vs spread por vuelta de apalancamiento (columnas). El D/E objetivo se recalcula con cada nivel. Generada cambiando Supuestos C; no se actualiza sola.
A15: DFN/EBITDA objetivo \ spread | B15: 0 | C15: 0.0025 | D15: 0.005
A16: Actual (2,36x, sin aumento) | B16: 1818.6 | C16: 1818.6 | D16: 1818.6
A17: 3,0x | B17: 1848.9 | C17: 1841.4 | D17: 1834
A18: 3,5x | B18: 1871.7 | C18: 1856.8 | D18: 1842.1
A19: 4,0x | B19: 1893.8 | C19: 1870.1 | D19: 1846.9
A20: Valores estáticos (no se recalculan). Resaltado = caso base.
A24: Auxiliar (no editar): FCFF 2032E según g
