Workbook

Sheet Supuestos
A1: Supuestos — modelo consolidado de valoración Mallplaza (Plaza S.A.)
A2: Única hoja de inputs del DCF, la WACC y los múltiplos. Azul = dato ingresado · negro = fórmula · verde = vínculo a otra hoja · fondo amarillo = supuesto clave del equipo. MM CLP salvo indicación.
A3: Tags: [R] reportado · [P] consenso / proyección del forecast · [C] cálculo · [S] supuesto del equipo.
A5: Concepto | B5: Valor | C5: Unidad | D5: Tag | E5: Fuente / comentario
A7: A. General y puente a patrimonio
A8: Fecha de valorización | B8: 30-06-2026 | C8: fecha | D8: S | E8: Coincide con la última DFN y minoritarios reportados (Release 2Q26).
A9: Precio de referencia | B9: 3555 | C9: CLP | D9: R | E9: Bloomberg PX_LAST al 30-09-2026 (archivo de comparables, Datos_BBG).
A10: Acciones en circulación | B10: 2190 | C10: MM | D10: R | E10: Bloomberg: market cap / precio (Datos_BBG).
A11: Deuda financiera neta 30-06-2026 (definición compañía) | B11: 1285740 | C11: MM CLP | D11: R | E11: Release 2Q26 / Análisis Razonado 1S26.
A12: Participaciones no controladoras (libro) 30-06-2026 | B12: 50841 | C12: MM CLP | D12: R | E12: Release 2Q26, estado de situación. Libro como proxy del valor de mercado [S].
A13: Caja y equivalentes 30-06-2026 | B13: 347621 | C13: MM CLP | D13: R | E13: Release 2Q26.
A14: EBITDA LTM 2T26 (definición compañía) | B14: 544935 | C14: MM CLP | D14: R | E14: Release 2Q26, p. 29.
A15: Deuda neta Mallplaza para múltiplos (BBG NET_DEBT) | B15: =Datos_BBG!M8 -> 1311568.6 | C15: MM CLP | D15: R | E15: Misma definición que los pares (Bloomberg), solo para el método de múltiplos.
A17: B. WACC (fórmulas en hoja WACC)
A18: Rf — bono del Tesoro de EE.UU. | B18: 0.049778 | C18: % | D18: R | E18: Tasa_WACC.xlsm, FFCF!C11 ("USA"). Referencia; no es la que usa el Ke del archivo.
A19: Rf — tasa "Chile" usada en el Ke | B19: 0.0543 | C19: % | D19: R | E19: Tasa_WACC.xlsm, FFCF!E11. El Ke del archivo (FFCF!B112) usa ESTA celda. Confirmar instrumento: si ya incluye riesgo Chile, el CRP Chile se cuenta dos veces.
A20: Rf usada en el Ke (1 = "Chile" 5,43% · 2 = EE.UU. 4,98%) | B20: 2 | C20: switch | D20: S | E20: Instrucción del equipo: Rf = bono de EE.UU.; el CRP se suma aparte (sin doble conteo).
A21: Inflación de largo plazo EE.UU. (breakeven 10Y, jun-26) | B21: 0.022431 | C21: % | D21: R | E21: Exhibits v6, E7_WACC: UST 10Y − TIPS 10Y al 30-06-2026 (Bloomberg USGG10YR / USGGT10Y).
A22: Convertir el Ke en USD a CLP con el diferencial de inflación (1 = sí) | B22: 1 | C22: switch | D22: S | E22: Con Rf de EE.UU. el Ke queda en dólares; el FCFF está en CLP nominales. Ke CLP = (1 + Ke USD) × (1 + inflación Chile) / (1 + inflación EE.UU.) − 1.
A23: Prima por riesgo de mercado (ERP) | B23: 0.0414 | C23: % | D23: R | E23: Damodaran (Tasa_WACC.xlsm, FFCF!B73).
A24: CRP Chile | B24: 0.0104 | C24: % | D24: R | E24: Tasa_WACC.xlsm, FFCF!C79.
A25: CRP Perú | B25: 0.0155 | C25: % | D25: R | E25: Tasa_WACC.xlsm, FFCF!C80.
A26: CRP Colombia | B26: 0.037 | C26: % | D26: R | E26: Tasa_WACC.xlsm, FFCF!C81.
A27: Ingresos LTM consolidados (ponderador CRP) | B27: 677333 | C27: MM CLP | D27: R | E27: Tasa_WACC.xlsm, FFCF!C83.
A28: Ingresos LTM Chile | B28: 486084 | C28: MM CLP | D28: R | E28: Tasa_WACC.xlsm, FFCF!C86.
A29: Ingresos LTM Perú | B29: 463174 | C29: miles PEN | D29: R | E29: Tasa_WACC.xlsm, FFCF!C90 (rotulado "miles de soles").
... A36: Tasa de impuesto Chile (escudo de la deuda y re-apalancamiento) | B36: 0.27 | C36: % | D36: R | E36: Ley de Impuesto a la Renta. La deuda está emitida en Chile (79% en UF).
A37: Deuda financiera bruta Mallplaza (estructura actual) | B37: =127178.9+1452136.3 -> 1579315.2 | C37: MM CLP | D37: R | E37: Tasa_WACC.xlsm, FFCF!G23:G24 (préstamos CP + deuda LP).
A38: Market cap Mallplaza (estructura de la WACC) | B38: 7905900 | C38: MM CLP | D38: R | E38: Tasa_WACC.xlsm, FFCF!G26.
A39: DFN / EBITDA objetivo (apalancamiento para crecer) | B39: 3.5 | C39: x | D39: S | E39: Supuesto del equipo: la compañía usa su bajo endeudamiento (2,36x jun-26) para financiar la expansión. Referencias: 3,78x dic-24; Parque Arauco 5,7x; Cencosud Shopping 2,1x.
A40: Estructura de capital de la WACC (1 = objetivo · 0 = actual) | B40: 1 | C40: switch | D40: S | E40: Con 1 la beta se re-apalanca y se pondera con la estructura objetivo. Con 0 se reproduce el Ke de 11,31% del archivo.
A42: C. Forecast base (motor operativo, Exhibits v6)
A43: Ingresos 1S26 real | B43: 339530 | C43: MM CLP | D43: R | E43: Release 2Q26, p. 31.
A44: EBITDA 1S26 real usado para aislar el 2S26 | B44: 270574 | C44: MM CLP | D44: R | E44: DCF del equipo (reconstrucción). El release informa 270.573 (p. 8): diferencia de redondeo.
A45: Ingresos 2025A | B45: 653911 | C45: MM CLP | D45: R | E45: EEFF dic-25 (para la variación de capital de trabajo del 2S26).
A46: D&A / ingresos | B46: 0.0070364208 | C46: % | D46: C | E46: D&A LTM / ingresos LTM (Exhibits v6, DCF_Valuation fila 6).
A47: Capex de mantención + TI / ingresos | B47: 0.055 | C47: % | D47: S | E47: Exhibits v6: entre 2024 (~4,8%) y UDM 2T26 (~6,6%).
A48: Tasa de impuesto operacional de largo plazo | B48: 0.27 | C48: % | D48: S | E48: Trayectoria 16,8% → 27% del forecast; 27% desde 2030.
A50: D. Expansión continua post-pipeline (supuesto nuevo)
A51: Incluir expansión continua (1 = sí) | B51: 1 | C51: switch | D51: S | E51: Supuesto del equipo: la compañía sigue expandiendo GLA después de 2028 a un ritmo parecido al histórico.
...

Sheet WACC
A1: WACC nominal en CLP — misma lógica que Tasa_WACC.xlsm (hoja FFCF), con tres correcciones
A2: Correcciones: (1) Kd real en UF pasado a nominal; (2) escudo fiscal (1 − t) que faltaba en FFCF!B120; (3) set de pares = coincidencia entre las betas y los comparables (función COUNTIF por ticker).
A4: A. Betas de los pares (datos de Tasa_WACC.xlsm, FFCF)
A5: Empresa | B5: Ticker BBG | C5: País | D5: Beta apalancada | E5: Deuda | F5: Market cap | G5: Impuesto | H5: Beta desapalancada | I5: En set común (1/0) | J5: Fuente / nota | K5: Beta incluida
A6: Parque Arauco | B6: PARAUCO CI | C6: Chile | D6: 1.25 | E6: =153323+1547183.9 -> 1700506.9 | F6: 3828031 | G6: 0.27 | H6: =D6/(1+(1-G6)*E6/F6) -> 0.94390614 | I6: =IF(COUNTIF(Datos_BBG!$B$4:$B$43,B6)>0,1,0) -> 1 | J6: Deuda = préstamos CP + deuda LP; market cap en MM CLP (FFCF!G28:G61). | K6: =IF(I6=1,H6,"") -> 0.94390614
A7: Cencosud Shopping | B7: CENCOMAL CI | C7: Chile | D7: 1.075 | E7: =2632.1+759521.6 -> 762153.7 | F7: 3942858 | G7: 0.27 | H7: =D7/(1+(1-G7)*E7/F7) -> 0.94206612 | I7: =IF(COUNTIF(Datos_BBG!$B$4:$B$43,B7)>0,1,0) -> 1 | K7: =IF(I7=1,H7,"") -> 0.94206612
A8: Allos | B8: ALOS3 BZ | C8: Brasil | D8: 1.164 | E8: =53136.3+907054.7 -> 960191 | F8: 2712166.2 | G8: 0.34 | H8: =D8/(1+(1-G8)*E8/F8) -> 0.94353351 | I8: =IF(COUNTIF(Datos_BBG!$B$4:$B$43,B8)>0,1,0) -> 1 | K8: =IF(I8=1,H8,"") -> 0.94353351
A9: Iguatemi | B9: IGTI11 BZ | C9: Brasil | D9: 0.908 | E9: =63046.9+584349.7 -> 647396.6 | F9: 1421560.1 | G9: 0.34 | H9: =D9/(1+(1-G9)*E9/F9) -> 0.69815413 | I9: =IF(COUNTIF(Datos_BBG!$B$4:$B$43,B9)>0,1,0) -> 1 | K9: =IF(I9=1,H9,"") -> 0.69815413
A10: Costa Verde | B10: n/d (no está en comparables) | C10: México | D10: 0.025 | E10: =13931.3+190036.2 -> 203967.5 | F10: 489349.7 | G10: 0.3 | H10: =D10/(1+(1-G10)*E10/F10) -> 0.0193533 | I10: =IF(COUNTIF(Datos_BBG!$B$4:$B$43,B10)>0,1,0) -> 0 | J10: Costa Verde no tiene comparables en Bloomberg: queda fuera por la regla de coincidencia. | K10: =IF(I10=1,H10,"")
A11: IRSA | B11: IRSA AR | C11: Argentina | D11: 0.427 | E11: =109097.3+515949.2 -> 625046.5 | F11: 1218777.1 | G11: 0.35 | H11: =D11/(1+(1-G11)*E11/F11) -> 0.32024582 | I11: =IF(COUNTIF(Datos_BBG!$B$4:$B$43,B11)>0,1,0) -> 1 | J11: IRSA entra porque está en ambas listas (en el archivo de comparables estaba como "Sensibilidad"). | K11: =IF(I11=1,H11,"") -> 0.32024582
A12: Multiplan | B12: MULT3 BZ | C12: Brasil | D12: 1.219 | E12: =118753.6+72724.7 -> 191478.3 | F12: 2959844.9 | G12: 0.34 | H12: =D12/(1+(1-G12)*E12/F12) -> 1.1690839 | I12: =IF(COUNTIF(Datos_BBG!$B$4:$B$43,B12)>0,1,0) -> 1 | K12: =IF(I12=1,H12,"") -> 1.1690839
A13: Beta desapalancada: mediana del set común | H13: =MEDIAN(K6:K12) -> 0.94279981 | I13: =COUNT(K6:K12) -> 6 | J13: Número de pares en la mediana.
A15: B. Estructura de capital de Mallplaza
A16: Deuda actual (bruta) | B16: =Supuestos!$B$37 -> 1579315.2
A17: Market cap | B17: =Supuestos!$B$38 -> 7905900
A18: D/E actual | B18: =B16/B17 -> 0.19976413
A19: Deuda objetivo = DFN/EBITDA objetivo × EBITDA LTM + caja | B19: =Supuestos!$B$39*Supuestos!$B$14+Supuestos!$B$13 -> 2254893.5 | C19: Deuda bruta = DFN objetivo + caja, para ser comparable con la deuda bruta actual.
A20: D/E objetivo | B20: =B19/B17 -> 0.28521655
A21: D/E usado | B21: =IF(Supuestos!$B$40=1,B20,B18) -> 0.28521655
A22: D/V usado | B22: =B21/(1+B21) -> 0.221921
A23: E/V usado | B23: =1-B22 -> 0.778079
A25: C. Costo del patrimonio (Ke = Rf + β × ERP + CRP)
A26: Rf usada | B26: =IF(Supuestos!$B$20=1,Supuestos!$B$19,Supuestos!$B$18) -> 0.049778
A27: Beta desapalancada (mediana) | B27: =WACC!$H$13 -> 0.94279981
A28: Beta re-apalancada Mallplaza | B28: =B27*(1+(1-Supuestos!$B$36)*B21) -> 1.1390984
A29: ERP | B29: =Supuestos!$B$23 -> 0.0414
A30: Ponderación Chile (ingresos) | B30: =Supuestos!$B$28/Supuestos!$B$27 -> 0.71764405
A31: Ingresos Perú en CLP | B31: =Supuestos!$B$29/1000*Supuestos!$B$31/Supuestos!$B$32 -> 125262.08
A32: Ingresos Colombia en CLP | B32: =Supuestos!$B$30*Supuestos!$B$31/Supuestos!$B$33 -> 74355.805
A33: Ponderación Perú | B33: =(1-B30)*B31/(B31+B32) -> 0.17718098 | C33: Igual que FFCF: Perú y Colombia se reparten el resto según sus ingresos en CLP.
A34: Ponderación Colombia | B34: =(1-B30)*B32/(B31+B32) -> 0.10517496
A35: CRP ponderado Mallplaza | B35: =B30*Supuestos!$B$24+B33*Supuestos!$B$25+B34*Supuestos!$B$26 -> 0.014101277
A36: Ke nominal CLP | B36: =IF(AND(Supuestos!$B$20=2,Supuestos!$B$22=1),(1+B26+B28*B29+B35)*(1+Supuestos!$B$35)/(1+Supuestos!$B$21)-1,B26+B28*B29+B35) -> 0.1192629 | C36: Rf + β × ERP + CRP; con Rf de EE.UU. se convierte de USD a CLP por el diferencial de inflación (Supuestos B).
A37: Control: Ke del archivo (Rf "Chile", estructura actual) | B37: =Supuestos!$B$19+B27*(1+(1-Supuestos!$B$36)*B18)*B29+B35 -> 0.11312513 | C37: Debe dar 11,31% (Tasa_WACC.xlsm, FFCF!B112).
A39: D. Costo de la deuda y WACC
A40: Kd real (UF) | B40: =Supuestos!$B$34 -> 0.036
A41: Kd nominal CLP = (1 + Kd real)(1 + inflación) − 1 | B41: =(1+B40)*(1+Supuestos!$B$35)-1 -> 0.06708
A42: Kd nominal después de impuestos | B42: =B41*(1-Supuestos!$B$36) -> 0.0489684
A43: WACC nominal CLP | B43: =B23*B36+B22*B42 -> 0.10366307
A44: WACC real implícita | B44: =(1+B43)/(1+Supuestos!$B$35)-1 -> 0.071517548
...

Sheet Forecast_Base
A1: Forecast base — motor operativo (Mallplaza_FA_Exhibits_v6.xlsx), 2S26E–2031E
A2: Cifras del forecast del equipo en azul (hoja Forecast de Exhibits v6), basadas en el pipeline anunciado hasta 2028. Sin la expansión post-2028 (hoja Expansion).
A4: MM CLP | B4: Tag | C4: 2S26E | D4: 2027E | E4: 2028E | F4: 2029E | G4: 2030E | H4: 2031E | J4: Fuente / supuesto
A5: Ingresos año calendario (2026E = año completo) | B5: P | C5: 703998.94 | D5: 767179.42 | E5: 820506.7 | F5: 866951.61 | G5: 904202.83 | H5: 939524.47 | J5: Exhibits v6, Forecast fila "Ingresos ordinarios consolidados".
A6: Ingresos del período (2S26E = 2026E − 1S26 real) | B6: C | C6: =C5-Supuestos!$B$43 -> 364468.94 | D6: =D5 -> 767179.42 | E6: =E5 -> 820506.7 | F6: =F5 -> 866951.61 | G6: =G5 -> 904202.83 | H6: =H5 -> 939524.47 | J6: 2S26E = 2026E − 1S26 real (Supuestos).
A7: EBITDA año calendario | B7: P | C7: 561315.41 | D7: 611360.36 | E7: 654236.23 | F7: 691459.84 | G7: 721124.37 | H7: 749208.58 | J7: Exhibits v6, Forecast bloque E.
A8: EBITDA del período | B8: C | C8: =C7-Supuestos!$B$44 -> 290741.41 | D8: =D7 -> 611360.36 | E8: =E7 -> 654236.23 | F8: =F7 -> 691459.84 | G8: =G7 -> 721124.37 | H8: =H7 -> 749208.58 | J8: 2S26E = 2026E − EBITDA 1S26 (Supuestos).
A9: Margen EBITDA | B9: C | C9: =C8/C6 -> 0.79771244 | D9: =D8/D6 -> 0.79689358 | E9: =E8/E6 -> 0.79735635 | F9: =F8/F6 -> 0.79757605 | G9: =G8/G6 -> 0.79752501 | H9: =H8/H6 -> 0.79743381
A10: D&A | B10: C | C10: =Supuestos!$B$46*C6 -> 2564.5568 | D10: =Supuestos!$B$46*D6 -> 5398.1972 | E10: =Supuestos!$B$46*E6 -> 5773.4304 | F10: =Supuestos!$B$46*F6 -> 6100.2363 | G10: =Supuestos!$B$46*G6 -> 6362.3516 | H10: =Supuestos!$B$46*H6 -> 6610.8895 | J10: D&A / ingresos LTM × ingresos (Exhibits v6, DCF_Valuation fila 3b).
A11: Tasa de impuesto operacional en caja | B11: P | C11: 0.168 | D11: 0.19 | E11: 0.215 | F11: 0.24 | G11: 0.27 | H11: 0.27 | J11: Exhibits v6: impuesto corriente / (EBITDA − costo financiero), 16,8% → 27%.
A12: Capex de proyectos en curso (MMUSD) | B12: P | C12: 113.64 | D12: 215.08 | E12: 116.28 | F12: 0 | G12: 0 | H12: 0 | J12: Release 2Q26, pp. 12–14: remanente por proyecto repartido hasta su apertura (Exhibits v6, bloque G).
A13: USDCLP promedio | B13: P | C13: 929.55 | D13: 922.75 | E13: 914.75 | F13: 921 | G13: 921 | H13: 921 | J13: Exhibits v6: 2S26E promedio del semestre; 2027+ promedio de fin de año (consenso ECFC); 2029+ constante.
A14: Capex de proyectos en curso (MM CLP) | B14: C | C14: =C12*C13 -> 105634.06 | D14: =D12*D13 -> 198465.07 | E14: =E12*E13 -> 106367.13 | F14: =F12*F13 -> 0 | G14: =G12*G13 -> 0 | H14: =H12*H13 -> 0
A15: Capex de mantención + TI | B15: C | C15: =Supuestos!$B$47*C5/2 -> 19359.971 | D15: =Supuestos!$B$47*D6 -> 42194.868 | E15: =Supuestos!$B$47*E6 -> 45127.869 | F15: =Supuestos!$B$47*F6 -> 47682.339 | G15: =Supuestos!$B$47*G6 -> 49731.156 | H15: =Supuestos!$B$47*H6 -> 51673.846 | J15: 5,5% de ingresos (2S26E: medio año de 2026E).
A16: Capex base total | B16: C | C16: =C14+C15 -> 124994.03 | D16: =D14+D15 -> 240659.94 | E16: =E14+E15 -> 151495 | F16: =F14+F15 -> 47682.339 | G16: =G14+G15 -> 49731.156 | H16: =H14+H15 -> 51673.846 | J16: Sin la expansión post-pipeline (ver hoja Expansion).
A18: Ingreso anual por m² Chile (CLP) | B18: P | C18: 341079.53 | D18: 360468.33 | E18: 378194.73 | F18: 395002.18 | G18: 411161.93 | H18: 426868.38 | J18: Exhibits v6, Forecast bloque D, Chile. Se aplica al GLA nuevo.
A19: Ingreso anual por m² Perú (PEN) | B19: P | C19: 792.93865 | D19: 832.95944 | E19: 869.39102 | F19: 896.70772 | G19: 921.72945 | H19: 945.04514 | J19: Exhibits v6, Forecast bloque D, Perú.
A20: CLP por PEN (promedio) | B20: P | C20: 267.99722 | D20: 275.85211 | E20: 279.34382 | F20: 284.77376 | G20: 287.56566 | H20: 290.38493 | J20: Exhibits v6, Forecast bloque A.

Sheet Expansion
A1: Expansión continua post-pipeline — capex con 2 años de construcción y rampa de ingresos
A2: Cada cohorte abre GLA nuevo al ritmo histórico. El capex se gasta en los 2 años previos a la apertura y los ingresos parten en el año de apertura con la rampa del forecast (35% / 90% / 100%). Se apaga con Supuestos "Incluir expansión".
A4: Año del período | C4: 2S26E | D4: 2027E | E4: 2028E | F4: 2029E | G4: 2030E | H4: 2031E
A5: Año (número) | C5: 2026 | D5: 2027 | E5: 2028 | F5: 2029 | G5: 2030 | H5: 2031
A6: Índice de costo (IPC Chile, 2026 = 1) | C6: =(1+Supuestos!$B$35)^(C5-2026) -> 1 | D6: =(1+Supuestos!$B$35)^(D5-2026) -> 1.03 | E6: =(1+Supuestos!$B$35)^(E5-2026) -> 1.0609 | F6: =(1+Supuestos!$B$35)^(F5-2026) -> 1.092727 | G6: =(1+Supuestos!$B$35)^(G5-2026) -> 1.1255088 | H6: =(1+Supuestos!$B$35)^(H5-2026) -> 1.1592741
A7: Costo por m² (MM CLP) | C7: =Supuestos!$B$60*Supuestos!$B$61*C6/1000000 -> 3.3181974 | D7: =Supuestos!$B$60*Supuestos!$B$61*D6/1000000 -> 3.4177433 | E7: =Supuestos!$B$60*Supuestos!$B$61*E6/1000000 -> 3.5202756 | F7: =Supuestos!$B$60*Supuestos!$B$61*F6/1000000 -> 3.6258839 | G7: =Supuestos!$B$60*Supuestos!$B$61*G6/1000000 -> 3.7346604 | H7: =Supuestos!$B$60*Supuestos!$B$61*H6/1000000 -> 3.8467002 | M7: Costo del pipeline en curso (USD/m²) × USDCLP 2026, indexado a IPC Chile (obras en UF).
A8: Ingreso por m² de la expansión (CLP, mix Chile/Perú) | C8: =Supuestos!$B$64*Forecast_Base!C18+(1-Supuestos!$B$64)*Forecast_Base!C19*Forecast_Base!C20 -> 283080.83 | D8: =Supuestos!$B$64*Forecast_Base!D18+(1-Supuestos!$B$64)*Forecast_Base!D19*Forecast_Base!D20 -> 301513.07 | E8: =Supuestos!$B$64*Forecast_Base!E18+(1-Supuestos!$B$64)*Forecast_Base!E19*Forecast_Base!E20 -> 317145.96 | F8: =Supuestos!$B$64*Forecast_Base!F18+(1-Supuestos!$B$64)*Forecast_Base!F19*Forecast_Base!F20 -> 332010.27 | G8: =Supuestos!$B$64*Forecast_Base!G18+(1-Supuestos!$B$64)*Forecast_Base!G19*Forecast_Base!G20 -> 345255.59 | H8: =Supuestos!$B$64*Forecast_Base!H18+(1-Supuestos!$B$64)*Forecast_Base!H19*Forecast_Base!H20 -> 358103.33 | M8: Mismo ingreso por m² que el forecast aplica al GLA nuevo del pipeline.
A9: Margen EBITDA de la expansión | C9: =Supuestos!$B$64*Supuestos!$B$65+(1-Supuestos!$B$64)*Supuestos!$B$66 -> 0.80902183 | D9: =Supuestos!$B$64*Supuestos!$B$65+(1-Supuestos!$B$64)*Supuestos!$B$66 -> 0.80902183 | E9: =Supuestos!$B$64*Supuestos!$B$65+(1-Supuestos!$B$64)*Supuestos!$B$66 -> 0.80902183 | F9: =Supuestos!$B$64*Supuestos!$B$65+(1-Supuestos!$B$64)*Supuestos!$B$66 -> 0.80902183 | G9: =Supuestos!$B$64*Supuestos!$B$65+(1-Supuestos!$B$64)*Supuestos!$B$66 -> 0.80902183 | H9: =Supuestos!$B$64*Supuestos!$B$65+(1-Supuestos!$B$64)*Supuestos!$B$66 -> 0.80902183
A11: A. m² que abre cada cohorte
A12: Cohorte (año de apertura) | B12: m²
A13: 2029 | B13: =IF(AND(Supuestos!$B$51=1,A13>=Supuestos!$B$56),Supuestos!$B$55,0) -> 27075.333 | J13: Cohortes 2032–2033 abren fuera del horizonte, pero su capex (2030–2031) cae dentro: sostiene el crecimiento del valor terminal.
A14: 2030 | B14: =IF(AND(Supuestos!$B$51=1,A14>=Supuestos!$B$56),Supuestos!$B$55,0) -> 27075.333
A15: 2031 | B15: =IF(AND(Supuestos!$B$51=1,A15>=Supuestos!$B$56),Supuestos!$B$55,0) -> 27075.333
A16: 2032 | B16: =IF(AND(Supuestos!$B$51=1,A16>=Supuestos!$B$56),Supuestos!$B$55,0) -> 27075.333
A17: 2033 | B17: =IF(AND(Supuestos!$B$51=1,A17>=Supuestos!$B$56),Supuestos!$B$55,0) -> 27075.333
A23: B. Capex por cohorte (MM CLP)
A24: 2029 | C24: =$B$13*C$7*(IF(C$5=$A$13-2,Supuestos!$B$57,0)+IF(C$5=$A$13-1,1-Supuestos!$B$57,0)) -> 0 | D24: =$B$13*D$7*(IF(D$5=$A$13-2,Supuestos!$B$57,0)+IF(D$5=$A$13-1,1-Supuestos!$B$57,0)) -> 46268.27 | E24: =$B$13*E$7*(IF(E$5=$A$13-2,Supuestos!$B$57,0)+IF(E$5=$A$13-1,1-Supuestos!$B$57,0)) -> 47656.318 | F24: =$B$13*F$7*(IF(F$5=$A$13-2,Supuestos!$B$57,0)+IF(F$5=$A$13-1,1-Supuestos!$B$57,0)) -> 0 | G24: =$B$13*G$7*(IF(G$5=$A$13-2,Supuestos!$B$57,0)+IF(G$5=$A$13-1,1-Supuestos!$B$57,0)) -> 0 | H24: =$B$13*H$7*(IF(H$5=$A$13-2,Supuestos!$B$57,0)+IF(H$5=$A$13-1,1-Supuestos!$B$57,0)) -> 0
A25: 2030 | C25: =$B$14*C$7*(IF(C$5=$A$14-2,Supuestos!$B$57,0)+IF(C$5=$A$14-1,1-Supuestos!$B$57,0)) -> 0 | D25: =$B$14*D$7*(IF(D$5=$A$14-2,Supuestos!$B$57,0)+IF(D$5=$A$14-1,1-Supuestos!$B$57,0)) -> 0 | E25: =$B$14*E$7*(IF(E$5=$A$14-2,Supuestos!$B$57,0)+IF(E$5=$A$14-1,1-Supuestos!$B$57,0)) -> 47656.318 | F25: =$B$14*F$7*(IF(F$5=$A$14-2,Supuestos!$B$57,0)+IF(F$5=$A$14-1,1-Supuestos!$B$57,0)) -> 49086.008 | G25: =$B$14*G$7*(IF(G$5=$A$14-2,Supuestos!$B$57,0)+IF(G$5=$A$14-1,1-Supuestos!$B$57,0)) -> 0 | H25: =$B$14*H$7*(IF(H$5=$A$14-2,Supuestos!$B$57,0)+IF(H$5=$A$14-1,1-Supuestos!$B$57,0)) -> 0
A26: 2031 | C26: =$B$15*C$7*(IF(C$5=$A$15-2,Supuestos!$B$57,0)+IF(C$5=$A$15-1,1-Supuestos!$B$57,0)) -> 0 | D26: =$B$15*D$7*(IF(D$5=$A$15-2,Supuestos!$B$57,0)+IF(D$5=$A$15-1,1-Supuestos!$B$57,0)) -> 0 | E26: =$B$15*E$7*(IF(E$5=$A$15-2,Supuestos!$B$57,0)+IF(E$5=$A$15-1,1-Supuestos!$B$57,0)) -> 0 | F26: =$B$15*F$7*(IF(F$5=$A$15-2,Supuestos!$B$57,0)+IF(F$5=$A$15-1,1-Supuestos!$B$57,0)) -> 49086.008 | G26: =$B$15*G$7*(IF(G$5=$A$15-2,Supuestos!$B$57,0)+IF(G$5=$A$15-1,1-Supuestos!$B$57,0)) -> 50558.588 | H26: =$B$15*H$7*(IF(H$5=$A$15-2,Supuestos!$B$57,0)+IF(H$5=$A$15-1,1-Supuestos!$B$57,0)) -> 0
A27: 2032 | C27: =$B$16*C$7*(IF(C$5=$A$16-2,Supuestos!$B$57,0)+IF(C$5=$A$16-1,1-Supuestos!$B$57,0)) -> 0 | D27: =$B$16*D$7*(IF(D$5=$A$16-2,Supuestos!$B$57,0)+IF(D$5=$A$16-1,1-Supuestos!$B$57,0)) -> 0 | E27: =$B$16*E$7*(IF(E$5=$A$16-2,Supuestos!$B$57,0)+IF(E$5=$A$16-1,1-Supuestos!$B$57,0)) -> 0 | F27: =$B$16*F$7*(IF(F$5=$A$16-2,Supuestos!$B$57,0)+IF(F$5=$A$16-1,1-Supuestos!$B$57,0)) -> 0 | G27: =$B$16*G$7*(IF(G$5=$A$16-2,Supuestos!$B$57,0)+IF(G$5=$A$16-1,1-Supuestos!$B$57,0)) -> 50558.588 | H27: =$B$16*H$7*(IF(H$5=$A$16-2,Supuestos!$B$57,0)+IF(H$5=$A$16-1,1-Supuestos!$B$57,0)) -> 52075.346
A28: 2033 | C28: =$B$17*C$7*(IF(C$5=$A$17-2,Supuestos!$B$57,0)+IF(C$5=$A$17-1,1-Supuestos!$B$57,0)) -> 0 | D28: =$B$17*D$7*(IF(D$5=$A$17-2,Supuestos!$B$57,0)+IF(D$5=$A$17-1,1-Supuestos!$B$57,0)) -> 0 | E28: =$B$17*E$7*(IF(E$5=$A$17-2,Supuestos!$B$57,0)+IF(E$5=$A$17-1,1-Supuestos!$B$57,0)) -> 0 | F28: =$B$17*F$7*(IF(F$5=$A$17-2,Supuestos!$B$57,0)+IF(F$5=$A$17-1,1-Supuestos!$B$57,0)) -> 0 | G28: =$B$17*G$7*(IF(G$5=$A$17-2,Supuestos!$B$57,0)+IF(G$5=$A$17-1,1-Supuestos!$B$57,0)) -> 0 | H28: =$B$17*H$7*(IF(H$5=$A$17-2,Supuestos!$B$57,0)+IF(H$5=$A$17-1,1-Supuestos!$B$57,0)) -> 52075.346
A29: Total | C29: =SUM(C24:C28) -> 0 | D29: =SUM(D24:D28) -> 46268.27 | E29: =SUM(E24:E28) -> 95312.636 | F29: =SUM(F24:F28) -> 98172.015 | G29: =SUM(G24:G28) -> 101117.18 | H29: =SUM(H24:H28) -> 104150.69
A31: C. Ingresos por cohorte (MM CLP)
A32: 2029 | C32: =$B$13*C$8/1000000*$B$45*IF(C$5<$A$13,0,IF(C$5=$A$13,Supuestos!$B$67,IF(C$5=$A$13+1,Supuestos!$B$68,Supuestos!$B$69))) -> 0 | D32: =$B$13*D$8/1000000*$B$45*IF(D$5<$A$13,0,IF(D$5=$A$13,Supuestos!$B$67,IF(D$5=$A$13+1,Supuestos!$B$68,Supuestos!$B$69))) -> 0 | E32: =$B$13*E$8/1000000*$B$45*IF(E$5<$A$13,0,IF(E$5=$A$13,Supuestos!$B$67,IF(E$5=$A$13+1,Supuestos!$B$68,Supuestos!$B$69))) -> 0 | F32: =$B$13*F$8/1000000*$B$45*IF(F$5<$A$13,0,IF(F$5=$A$13,Supuestos!$B$67,IF(F$5=$A$13+1,Supuestos!$B$68,Supuestos!$B$69))) -> 3146.2511 | G32: =$B$13*G$8/1000000*$B$45*IF(G$5<$A$13,0,IF(G$5=$A$13,Supuestos!$B$67,IF(G$5=$A$13+1,Supuestos!$B$68,Supuestos!$B$69))) -> 8413.1192 | H32: =$B$13*H$8/1000000*$B$45*IF(H$5<$A$13,0,IF(H$5=$A$13,Supuestos!$B$67,IF(H$5=$A$13+1,Supuestos!$B$68,Supuestos!$B$69))) -> 9695.7671
A33: 2030 | C33: =$B$14*C$8/1000000*$B$45*IF(C$5<$A$14,0,IF(C$5=$A$14,Supuestos!$B$67,IF(C$5=$A$14+1,Supuestos!$B$68,Supuestos!$B$69))) -> 0 | D33: =$B$14*D$8/1000000*$B$45*IF(D$5<$A$14,0,IF(D$5=$A$14,Supuestos!$B$67,IF(D$5=$A$14+1,Supuestos!$B$68,Supuestos!$B$69))) -> 0 | E33: =$B$14*E$8/1000000*$B$45*IF(E$5<$A$14,0,IF(E$5=$A$14,Supuestos!$B$67,IF(E$5=$A$14+1,Supuestos!$B$68,Supuestos!$B$69))) -> 0 | F33: =$B$14*F$8/1000000*$B$45*IF(F$5<$A$14,0,IF(F$5=$A$14,Supuestos!$B$67,IF(F$5=$A$14+1,Supuestos!$B$68,Supuestos!$B$69))) -> 0 | G33: =$B$14*G$8/1000000*$B$45*IF(G$5<$A$14,0,IF(G$5=$A$14,Supuestos!$B$67,IF(G$5=$A$14+1,Supuestos!$B$68,Supuestos!$B$69))) -> 3271.7686 | H33: =$B$14*H$8/1000000*$B$45*IF(H$5<$A$14,0,IF(H$5=$A$14,Supuestos!$B$67,IF(H$5=$A$14+1,Supuestos!$B$68,Supuestos!$B$69))) -> 8726.1904
A34: 2031 | C34: =$B$15*C$8/1000000*$B$45*IF(C$5<$A$15,0,IF(C$5=$A$15,Supuestos!$B$67,IF(C$5=$A$15+1,Supuestos!$B$68,Supuestos!$B$69))) -> 0 | D34: =$B$15*D$8/1000000*$B$45*IF(D$5<$A$15,0,IF(D$5=$A$15,Supuestos!$B$67,IF(D$5=$A$15+1,Supuestos!$B$68,Supuestos!$B$69))) -> 0 | E34: =$B$15*E$8/1000000*$B$45*IF(E$5<$A$15,0,IF(E$5=$A$15,Supuestos!$B$67,IF(E$5=$A$15+1,Supuestos!$B$68,Supuestos!$B$69))) -> 0 | F34: =$B$15*F$8/1000000*$B$45*IF(F$5<$A$15,0,IF(F$5=$A$15,Supuestos!$B$67,IF(F$5=$A$15+1,Supuestos!$B$68,Supuestos!$B$69))) -> 0 | G34: =$B$15*G$8/1000000*$B$45*IF(G$5<$A$15,0,IF(G$5=$A$15,Supuestos!$B$67,IF(G$5=$A$15+1,Supuestos!$B$68,Supuestos!$B$69))) -> 0 | H34: =$B$15*H$8/1000000*$B$45*IF(H$5<$A$15,0,IF(H$5=$A$15,Supuestos!$B$67,IF(H$5=$A$15+1,Supuestos!$B$68,Supuestos!$B$69))) -> 3393.5185
A35: 2032 | C35: =$B$16*C$8/1000000*$B$45*IF(C$5<$A$16,0,IF(C$5=$A$16,Supuestos!$B$67,IF(C$5=$A$16+1,Supuestos!$B$68,Supuestos!$B$69))) -> 0 | D35: =$B$16*D$8/1000000*$B$45*IF(D$5<$A$16,0,IF(D$5=$A$16,Supuestos!$B$67,IF(D$5=$A$16+1,Supuestos!$B$68,Supuestos!$B$69))) -> 0 | E35: =$B$16*E$8/1000000*$B$45*IF(E$5<$A$16,0,IF(E$5=$A$16,Supuestos!$B$67,IF(E$5=$A$16+1,Supuestos!$B$68,Supuestos!$B$69))) -> 0 | F35: =$B$16*F$8/1000000*$B$45*IF(F$5<$A$16,0,IF(F$5=$A$16,Supuestos!$B$67,IF(F$5=$A$16+1,Supuestos!$B$68,Supuestos!$B$69))) -> 0 | G35: =$B$16*G$8/1000000*$B$45*IF(G$5<$A$16,0,IF(G$5=$A$16,Supuestos!$B$67,IF(G$5=$A$16+1,Supuestos!$B$68,Supuestos!$B$69))) -> 0 | H35: =$B$16*H$8/1000000*$B$45*IF(H$5<$A$16,0,IF(H$5=$A$16,Supuestos!$B$67,IF(H$5=$A$16+1,Supuestos!$B$68,Supuestos!$B$69))) -> 0
A36: 2033 | C36: =$B$17*C$8/1000000*$B$45*IF(C$5<$A$17,0,IF(C$5=$A$17,Supuestos!$B$67,IF(C$5=$A$17+1,Supuestos!$B$68,Supuestos!$B$69))) -> 0 | D36: =$B$17*D$8/1000000*$B$45*IF(D$5<$A$17,0,IF(D$5=$A$17,Supuestos!$B$67,IF(D$5=$A$17+1,Supuestos!$B$68,Supuestos!$B$69))) -> 0 | E36: =$B$17*E$8/1000000*$B$45*IF(E$5<$A$17,0,IF(E$5=$A$17,Supuestos!$B$67,IF(E$5=$A$17+1,Supuestos!$B$68,Supuestos!$B$69))) -> 0 | F36: =$B$17*F$8/1000000*$B$45*IF(F$5<$A$17,0,IF(F$5=$A$17,Supuestos!$B$67,IF(F$5=$A$17+1,Supuestos!$B$68,Supuestos!$B$69))) -> 0 | G36: =$B$17*G$8/1000000*$B$45*IF(G$5<$A$17,0,IF(G$5=$A$17,Supuestos!$B$67,IF(G$5=$A$17+1,Supuestos!$B$68,Supuestos!$B$69))) -> 0 | H36: =$B$17*H$8/1000000*$B$45*IF(H$5<$A$17,0,IF(H$5=$A$17,Supuestos!$B$67,IF(H$5=$A$17+1,Supuestos!$B$68,Supuestos!$B$69))) -> 0
A37: Total | C37: =SUM(C32:C36) -> 0 | D37: =SUM(D32:D36) -> 0 | E37: =SUM(E32:E36) -> 0 | F37: =SUM(F32:F36) -> 3146.2511 | G37: =SUM(G32:G36) -> 11684.888 | H37: =SUM(H32:H36) -> 21815.476
A39: EBITDA de la expansión | C39: =C37*C9 -> 0 | D39: =D37*D9 -> 0 | E39: =E37*E9 -> 0 | F39: =F37*F9 -> 2545.3858 | G39: =G37*G9 -> 9453.3292 | H39: =H37*H9 -> 17649.196
A41: D. Retorno de la expansión (alimenta el valor terminal)
A42: Yield on cost derivado (EBITDA maduro por m² / costo por m², 2026) | B42: =C8*C9/1000000/C7 -> 0.069018971 | J42: Ingreso promedio por m² del portafolio × margen / costo por m² del pipeline. Es la misma productividad que el forecast asume para el pipeline actual. El ingreso se indexa a inflación, así que es un yield real.
A43: Yield on cost usado | B43: =IF(ISNUMBER(Supuestos!$B$70),Supuestos!$B$70,B42) -> 0.069018971
A44: RONIC real después de impuestos = yield × (1 − t) | B44: =B43*(1-Supuestos!$B$48) -> 0.050383849 | J44: Comparar con la WACC real (hoja WACC): si el RONIC es menor, crecer destruye valor.
A45: Ajuste de productividad de la expansión = yield usado / derivado | B45: =B43/B42 -> 1 | J45: Multiplica los ingresos de la expansión: si se ingresa un yield propio, el EBITDA explícito y el valor terminal quedan consistentes.

Sheet Capital_Trabajo
A1: Capital de trabajo — saldos de los EEFF y supuesto del modelo
A3: A. Saldos de balance operativos (MM CLP; EEFF consolidados Plaza S.A. y Filiales, estado de situación financiera)
B4: dic-23 | C4: dic-24 | D4: dic-25 | E4: mar-26 | F4: Fuente
A5: (+) Deudores comerciales y otras cuentas por cobrar corrientes | B5: 109044.23 | C5: 111058.3 | D5: 122369.81 | E5: 96333.76 | F5: dic-23: EEFF interinos mar-24, p. 3 · dic-24: EEFF interinos jun-25, p. 3 · dic-25 y mar-26: EEFF interinos mar-26, p. 3 (M$ / 1.000).
A6: (+) Cuentas por cobrar a entidades relacionadas corrientes | B6: 45909.292 | C6: 19565.384 | D6: 13695.594 | E6: 9043.354 | F6: Mismas fuentes. Arriendos por cobrar a tiendas del grupo controlador: operativo.
A7: Cuentas por pagar comerciales y otras cuentas por pagar (total) | B7: 115756.87 | C7: 95843.191 | D7: 122277.68 | E7: 169311.26 | F7: Incluye la provisión del dividendo mínimo (Nota 2.25), que es financiamiento y se excluye.
A8: menos: dividendo mínimo provisionado estimado (30% × utilidad distribuible) | B8: =0.3*197540 -> 59262 | C8: =0.3*238305 -> 71491.5 | D8: =0.3*369312 -> 110793.6 | F8: Nota 2.25: al cierre se provisiona el 30% de la utilidad líquida distribuible (Nota 20e/21e, Exhibits v6). Supone sin dividendos provisorios.
A9: (−) Cuentas por pagar comerciales operativas (sin dividendos) | B9: =B7-B8 -> 56494.871 | C9: =C7-C8 -> 24351.691 | D9: =D7-D8 -> 11484.079
A10: (−) Cuentas por pagar a entidades relacionadas corrientes | B10: 34486.698 | C10: 2641.613 | D10: 2296.174 | E10: 2306.468
A11: (−) Otros pasivos no financieros corrientes | B11: 10367.061 | C11: 23176.757 | D11: 20246.646 | E11: 14591.09 | F11: Principalmente arriendos cobrados por anticipado y garantías: operativo.
A12: Ingresos del año | B12: 419904 | C12: 494605 | D12: 653911 | F12: Exhibits v6, Inputs.
A13: Excluidos: caja, deuda financiera y activos/pasivos por impuestos (los impuestos ya están en caja en el NOPAT).
A14: B. Capital de trabajo neto operativo
A15: Capital de trabajo neto operativo | B15: =B5+B6-B9-B10-B11 -> 53604.896 | C15: =C5+C6-C9-C10-C11 -> 80453.622 | D15: =D5+D6-D9-D10-D11 -> 102038.5
A16: Capital de trabajo neto / ingresos | B16: =B15/B12 -> 0.12765988 | C16: =C15/C12 -> 0.16266237 | D16: =D15/D12 -> 0.15604341
A17: Referencia: Δ capital de trabajo neto / Δ ingresos (dic-23 → dic-25) | D17: =(D15-B15)/(D12-B12) -> 0.20697503 | F17: Distorsionado: dic-24 ya consolida Perú pero los ingresos 2024 solo traen un mes; y las cuentas con relacionadas cayeron fuerte en 2024.
A18: Supuesto del modelo: capital de trabajo neto / ingresos constante al nivel de dic-25 | D18: =D16 -> 0.15604341 | F18: Inversión anual = este % × Δ ingresos. Va a Supuestos (sección E).
A20: C. Lectura
A21: 1. Capital de trabajo neto operativo = deudores + cuentas por cobrar relacionadas − cuentas por pagar comerciales (sin dividendos) − cuentas por pagar relacionadas
A22: − otros pasivos no financieros. Se excluyen caja, deuda e impuestos.
A23: 2. La provisión del dividendo mínimo se resta de las cuentas por pagar porque es una obligación con accionistas, no de la operación.
A24: 3. Limitación: las cuentas por pagar comerciales también incluyen proveedores de obras (capex). Sin el desglose de la Nota 14/15 no se pueden separar.
A25: 4. Hay estacionalidad (mar-26: deudores bajan por recaudación, cuentas por pagar suben por el dividendo; Release 1Q26, pp. 37–38): se compara cierre contra cierre.
A26: 5. Se usa el nivel de dic-25 porque es el primer cierre con Perú completo tanto en balance como en ingresos.
A29: D. Referencia: brecha EBITDA − flujo operativo (MM CLP)
B30: FY2024 | C30: FY2025 | D30: 1S26
A31: EBITDA | B31: 380637 | C31: 526228 | D31: 270574 | F31: Exhibits v6 (Inputs, E4_Cash). Mezcla impuestos y capital de trabajo: solo referencial.
A32: Flujo operativo (EEFF) | B32: 300822 | C32: 441135 | D32: 258193
A33: Brecha = impuestos pagados + capital de trabajo + otros | B33: =B31-B32 -> 79815 | C33: =C31-C32 -> 85093 | D33: =D31-D32 -> 12381
A36: E. Capital de trabajo neto operativo: histórico y proyectado (MM CLP)
B37: 2023A | C37: 2024A | D37: 2025A | E37: 2026E | F37: 2027E | G37: 2028E | H37: 2029E | I37: 2030E | J37: 2031E
A38: Ingresos | B38: =B12 -> 419904 | C38: =C12 -> 494605 | D38: =D12 -> 653911 | E38: =Forecast_Base!C5+DCF!C6 -> 703998.94 | F38: =DCF!D7 -> 767179.42 | G38: =DCF!E7 -> 820506.7 | H38: =DCF!F7 -> 870097.86 | I38: =DCF!G7 -> 915887.72 | J38: =DCF!H7 -> 961339.95
A39: Capital de trabajo neto operativo | B39: =B15 -> 53604.896 | C39: =C15 -> 80453.622 | D39: =D15 -> 102038.5 | E39: =Supuestos!$B$74*E38 -> 109854.39 | F39: =Supuestos!$B$74*F38 -> 119713.29 | G39: =Supuestos!$B$74*G38 -> 128034.66 | H39: =Supuestos!$B$74*H38 -> 135773.04 | I39: =Supuestos!$B$74*I38 -> 142918.24 | J39: =Supuestos!$B$74*J38 -> 150010.76
A40: CTN / ingresos | B40: =B39/B38 -> 0.12765988 | C40: =C39/C38 -> 0.16266237 | D40: =D39/D38 -> 0.15604341 | E40: =E39/E38 -> 0.15604341 | F40: =F39/F38 -> 0.15604341 | G40: =G39/G38 -> 0.15604341 | H40: =H39/H38 -> 0.15604341 | I40: =I39/I38 -> 0.15604341 | J40: =J39/J38 -> 0.15604341
A41: Δ capital de trabajo neto (inversión) | C41: =C39-B39 -> 26848.726 | D41: =D39-C39 -> 21584.879 | E41: =E39-D39 -> 7815.8921 | F41: =F39-E39 -> 9858.8987 | G41: =G39-F39 -> 8321.3704 | H41: =H39-G39 -> 7738.3736 | I41: =I39-H39 -> 7145.2052 | J41: =J39-I39 -> 7092.5212
A42: Δ ingresos | C42: =C38-B38 -> 74701 | D42: =D38-C38 -> 159306 | E42: =E38-D38 -> 50087.935 | F42: =F38-E38 -> 63180.488 | G42: =G38-F38 -> 53327.279 | H42: =H38-G38 -> 49591.16 | I42: =I38-H38 -> 45789.856 | J42: =J38-I38 -> 45452.232
A43: Δ CTN / Δ ingresos | C43: =C41/C42 -> 0.35941588 | D43: =D41/D42 -> 0.1354932 | E43: =E41/E42 -> 0.15604341 | F43: =F41/F42 -> 0.15604341 | G43: =G41/G42 -> 0.15604341 | H43: =H41/H42 -> 0.15604341 | I43: =I41/I42 -> 0.15604341 | J43: =J41/J42 -> 0.15604341
A44: Variación en el DCF (2026E: solo 2S26) | E44: =-DCF!C21 -> 3907.946 | F44: =-DCF!D21 -> 9858.8987 | G44: =-DCF!E21 -> 8321.3704 | H44: =-DCF!F21 -> 7738.3736 | I44: =-DCF!G21 -> 7145.2052 | J44: =-DCF!H21 -> 7092.5212
A45: 2024: el balance de dic-24 ya consolida Open Plaza Perú pero los ingresos 2024 solo un mes (por eso 36%). 2025: primer año limpio. Proyección: CTN = 15,6% de los ingresos de cada año → la inversión anual es 15,6% del aumento de ingresos.

Sheet DCF
A1: DCF de FCFF — Mallplaza · CLP nominales · fecha de valorización 30-06-2026
A2: Flujos 2S26E–2031E con la expansión continua; valor terminal con reinversión explícita (solo el crecimiento real exige capex). Convención de mitad de período.
A4: MM CLP | C4: 2S26E | D4: 2027E | E4: 2028E | F4: 2029E | G4: 2030E | H4: 2031E | I4: Terminal (2032E)
A5: Ingresos base | C5: =Forecast_Base!C6 -> 364468.94 | D5: =Forecast_Base!D6 -> 767179.42 | E5: =Forecast_Base!E6 -> 820506.7 | F5: =Forecast_Base!F6 -> 866951.61 | G5: =Forecast_Base!G6 -> 904202.83 | H5: =Forecast_Base!H6 -> 939524.47
A6: Ingresos expansión | C6: =Expansion!C37 -> 0 | D6: =Expansion!D37 -> 0 | E6: =Expansion!E37 -> 0 | F6: =Expansion!F37 -> 3146.2511 | G6: =Expansion!G37 -> 11684.888 | H6: =Expansion!H37 -> 21815.476
A7: Ingresos totales | C7: =C5+C6 -> 364468.94 | D7: =D5+D6 -> 767179.42 | E7: =E5+E6 -> 820506.7 | F7: =F5+F6 -> 870097.86 | G7: =G5+G6 -> 915887.72 | H7: =H5+H6 -> 961339.95 | I7: =I29*(1+Supuestos!$B$77) -> 1007656.8
A8: Crecimiento ingresos (año calendario) | C8: =(Forecast_Base!C5+C6)/Supuestos!$B$45-1 -> 0.07659748 | D8: =D7/(Forecast_Base!C5+C6)-1 -> 0.089745147 | E8: =E7/D7-1 -> 0.069510831 | F8: =F7/E7-1 -> 0.060439677 | G8: =G7/F7-1 -> 0.052626099 | H8: =H7/G7-1 -> 0.049626424
A9: EBITDA base | C9: =Forecast_Base!C8 -> 290741.41 | D9: =Forecast_Base!D8 -> 611360.36 | E9: =Forecast_Base!E8 -> 654236.23 | F9: =Forecast_Base!F8 -> 691459.84 | G9: =Forecast_Base!G8 -> 721124.37 | H9: =Forecast_Base!H8 -> 749208.58
A10: EBITDA expansión | C10: =Expansion!C39 -> 0 | D10: =Expansion!D39 -> 0 | E10: =Expansion!E39 -> 0 | F10: =Expansion!F39 -> 2545.3858 | G10: =Expansion!G39 -> 9453.3292 | H10: =Expansion!H39 -> 17649.196
A11: EBITDA total | C11: =C9+C10 -> 290741.41 | D11: =D9+D10 -> 611360.36 | E11: =E9+E10 -> 654236.23 | F11: =F9+F10 -> 694005.23 | G11: =G9+G10 -> 730577.7 | H11: =H9+H10 -> 766857.78 | I11: =I30*(1+Supuestos!$B$77) -> 804002.48
A12: Margen EBITDA | C12: =C11/C7 -> 0.79771244 | D12: =D11/D7 -> 0.79689358 | E12: =E11/E7 -> 0.79735635 | F12: =F11/F7 -> 0.79761744 | G12: =G11/G7 -> 0.79767169 | H12: =H11/H7 -> 0.79769677 | I12: =I11/I7 -> 0.79789319
A13: (−) D&A | C13: =Supuestos!$B$46*C7 -> 2564.5568 | D13: =Supuestos!$B$46*D7 -> 5398.1972 | E13: =Supuestos!$B$46*E7 -> 5773.4304 | F13: =Supuestos!$B$46*F7 -> 6122.3747 | G13: =Supuestos!$B$46*G7 -> 6444.5714 | H13: =Supuestos!$B$46*H7 -> 6764.3924 | I13: =Supuestos!$B$46*I7 -> 7090.297
A14: EBIT | C14: =C11-C13 -> 288176.85 | D14: =D11-D13 -> 605962.16 | E14: =E11-E13 -> 648462.8 | F14: =F11-F13 -> 687882.85 | G14: =G11-G13 -> 724133.13 | H14: =H11-H13 -> 760093.38 | I14: =I11-I13 -> 796912.18
A15: Tasa de impuesto operacional | C15: =Forecast_Base!C11 -> 0.168 | D15: =Forecast_Base!D11 -> 0.19 | E15: =Forecast_Base!E11 -> 0.215 | F15: =Forecast_Base!F11 -> 0.24 | G15: =Forecast_Base!G11 -> 0.27 | H15: =Forecast_Base!H11 -> 0.27 | I15: =Supuestos!$B$48 -> 0.27
A16: (−) Impuestos operacionales | C16: =-C14*C15 -> -48413.711 | D16: =-D14*D15 -> -115132.81 | E16: =-E14*E15 -> -139419.5 | F16: =-F14*F15 -> -165091.88 | G16: =-G14*G15 -> -195515.95 | H16: =-H14*H15 -> -205225.21 | I16: =-I14*I15 -> -215166.29
A17: NOPAT | C17: =C14+C16 -> 239763.14 | D17: =D14+D16 -> 490829.35 | E17: =E14+E16 -> 509043.29 | F17: =F14+F16 -> 522790.97 | G17: =G14+G16 -> 528617.18 | H17: =H14+H16 -> 554868.17 | I17: =I14+I16 -> 581745.89
A18: (+) D&A | C18: =C13 -> 2564.5568 | D18: =D13 -> 5398.1972 | E18: =E13 -> 5773.4304 | F18: =F13 -> 6122.3747 | G18: =G13 -> 6444.5714 | H18: =H13 -> 6764.3924 | I18: =I13 -> 7090.297
A19: (−) Capex base (pipeline + mantención) | C19: =-Forecast_Base!C16 -> -124994.03 | D19: =-Forecast_Base!D16 -> -240659.94 | E19: =-Forecast_Base!E16 -> -151495 | F19: =-Forecast_Base!F16 -> -47682.339 | G19: =-Forecast_Base!G16 -> -49731.156 | H19: =-Forecast_Base!H16 -> -51673.846 | I19: =-Supuestos!$B$47*I7 -> -55421.122 | J19: Terminal: mantención 5,5% de ingresos.
A20: (−) Capex expansión | C20: =-Expansion!C29 -> 0 | D20: =-Expansion!D29 -> -46268.27 | E20: =-Expansion!E29 -> -95312.636 | F20: =-Expansion!F29 -> -98172.015 | G20: =-Expansion!G29 -> -101117.18 | H20: =-Expansion!H29 -> -104150.69 | I20: =-Supuestos!$B$78/Expansion!$B$44*I17 -> 0 | J20: Terminal: reinversión = g real / RONIC × NOPAT (value driver). Reemplaza al capex de expansión explícito.
A21: (−) Inversión en capital de trabajo | C21: =-Supuestos!$B$73*Supuestos!$B$74*(Forecast_Base!C5+C6-Supuestos!$B$45)/2 -> -3907.946 | D21: =-Supuestos!$B$73*Supuestos!$B$74*(D7-Forecast_Base!C5-C6) -> -9858.8987 | E21: =-Supuestos!$B$73*Supuestos!$B$74*(E7-D7) -> -8321.3704 | F21: =-Supuestos!$B$73*Supuestos!$B$74*(F7-E7) -> -7738.3736 | G21: =-Supuestos!$B$73*Supuestos!$B$74*(G7-F7) -> -7145.2052 | H21: =-Supuestos!$B$73*Supuestos!$B$74*(H7-G7) -> -7092.5212 | I21: =-Supuestos!$B$73*Supuestos!$B$74*I29*Supuestos!$B$77 -> -4579.7533 | J21: % del Δ ingresos (Supuestos E).
A22: FCFF | C22: =C17+C18+C19+C20+C21 -> 113425.72 | D22: =D17+D18+D19+D20+D21 -> 199440.44 | E22: =E17+E18+E19+E20+E21 -> 259687.72 | F22: =F17+F18+F19+F20+F21 -> 375320.62 | G22: =G17+G18+G19+G20+G21 -> 377068.22 | H22: =H17+H18+H19+H20+H21 -> 398715.5 | I22: =I17+I18+I19+I20+I21 -> 528835.31
A24: Período de descuento (años desde 30-06-2026) | C24: 0.25 | D24: 1 | E24: 2 | F24: 3 | G24: 4 | H24: 5 | J24: 2S26E a 0,25 años; luego la mitad de cada año desde el 30-06-2026.
A25: Factor de descuento | C25: =1/(1+WACC!$B$43)^C24 -> 0.97564286 | D25: =1/(1+WACC!$B$43)^D24 -> 0.90607362 | E25: =1/(1+WACC!$B$43)^E24 -> 0.82096941 | F25: =1/(1+WACC!$B$43)^F24 -> 0.74385873 | G25: =1/(1+WACC!$B$43)^G24 -> 0.67399077 | H25: =1/(1+WACC!$B$43)^H24 -> 0.61068526
A26: Valor presente del FCFF | C26: =C22*C25 -> 110662.99 | D26: =D22*D25 -> 180707.72 | E26: =E22*E25 -> 213195.67 | F26: =F22*F25 -> 279185.52 | G26: =G22*G25 -> 254140.5 | H26: =H22*H25 -> 243489.68
A28: Normalización 2031: base + expansión financiada (cohortes ≤ 2032) a madurez
A29: Ingresos 2031 normalizados | I29: =H5+SUMIF(Expansion!$A$13:$A$17,"<="&2032,Expansion!$B$13:$B$17)*Expansion!H$8*Expansion!$B$45/1000000 -> 978307.54 | J29: El capex de las cohortes que abren hasta 2032 ya está en el FCFF explícito, pero sus ingresos maduran después de 2031: el año terminal los cuenta a madurez (100%) para no castigar dos veces. La cohorte 2033 (solo 50% del capex dentro) queda en la reinversión terminal.
A30: EBITDA 2031 normalizado | I30: =H9+SUMIF(Expansion!$A$13:$A$17,"<="&2032,Expansion!$B$13:$B$17)*Expansion!H$8*Expansion!$B$45/1000000*Expansion!H$9 -> 780584.93
A31: EBIT 2031 normalizado | I31: =I30-Supuestos!$B$46*I29 -> 773701.14
A33: Valor de la empresa → valor por acción
A34: WACC nominal CLP | B34: =WACC!$B$43 -> 0.10366307
A35: Crecimiento terminal nominal (g) | B35: =Supuestos!$B$77 -> 0.03
A36: Tasa de reinversión terminal (g real / RONIC) | B36: =Supuestos!$B$78/Expansion!$B$44 -> 0
A37: Valor terminal al 31-12-2031 = FCFF 2032E / (WACC − g) | B37: =I22/(B34-B35) -> 7179109.9
A38: Valor presente del valor terminal (5,5 años) | B38: =B37/(1+B34)^5.5 -> 4173205.6
A39: Suma VP del FCFF explícito | B39: =SUM(C26:H26) -> 1281382.1
A40: Enterprise value | B40: =B38+B39 -> 5454587.7
A41: (−) Deuda financiera neta 30-06-2026 | B41: =-Supuestos!$B$11 -> -1285740
A42: (−) Minoritarios (libro) | B42: =-Supuestos!$B$12 -> -50841
A43: Valor del patrimonio | B43: =B40+B41+B42 -> 4118006.7
A44: Acciones (MM) | B44: =Supuestos!$B$10 -> 2190
...

Sheet Deuda
A1: Chequeo de endeudamiento — ¿la expansión se puede financiar con deuda hasta el objetivo?
A2: No entra en el valor (el FCFF es desapalancado): verifica que la estructura objetivo de la WACC sea alcanzable. DFN(t) = DFN(t−1) − FCFF + intereses después de impuestos + reajuste UF + dividendos.
A4: MM CLP | C4: 2S26E | D4: 2027E | E4: 2028E | F4: 2029E | G4: 2030E | H4: 2031E
A5: DFN de apertura | C5: =Supuestos!$B$11 -> 1285740 | D5: =C10 -> 1264132 | E5: =D10 -> 1278204.6 | F5: =E10 -> 1253196.5 | G5: =F10 -> 1117862.5 | H5: =G10 -> 979785.02
A6: (−) FCFF | C6: =-DCF!C22 -> -113425.72 | D6: =-DCF!D22 -> -199440.44 | E6: =-DCF!E22 -> -259687.72 | F6: =-DCF!F22 -> -375320.62 | G6: =-DCF!G22 -> -377068.22 | H6: =-DCF!H22 -> -398715.5
A7: (+) Costo financiero neto después de impuestos | C7: =Supuestos!$B$93*C5*0.5*(1-DCF!C15) -> 16473.929 | D7: =Supuestos!$B$93*D5*1*(1-DCF!D15) -> 31537.566 | E7: =Supuestos!$B$93*E5*1*(1-DCF!E15) -> 30904.431 | F7: =Supuestos!$B$93*F5*1*(1-DCF!F15) -> 29334.824 | G7: =Supuestos!$B$93*G5*1*(1-DCF!G15) -> 25134.021 | H7: =Supuestos!$B$93*H5*1*(1-DCF!H15) -> 22029.486
A8: (+) Reajuste UF de la deuda | C8: =Supuestos!$B$94*Supuestos!$B$35*C5*0.5 -> 15236.019 | D8: =Supuestos!$B$94*Supuestos!$B$35*D5*1 -> 29959.929 | E8: =Supuestos!$B$94*Supuestos!$B$35*E5*1 -> 30293.449 | F8: =Supuestos!$B$94*Supuestos!$B$35*F5*1 -> 29700.758 | G8: =Supuestos!$B$94*Supuestos!$B$35*G5*1 -> 26493.342 | H8: =Supuestos!$B$94*Supuestos!$B$35*H5*1 -> 23220.905
A9: (+) Dividendos pagados | C9: =Supuestos!$B$96-Supuestos!$B$97 -> 60107.8 | D9: =Supuestos!$B$95*C13 -> 152015.53 | E9: =Supuestos!$B$95*D13 -> 173481.76 | F9: =Supuestos!$B$95*E13 -> 180951.02 | G9: =Supuestos!$B$95*F13 -> 187363.36 | H9: =Supuestos!$B$95*G13 -> 192677.74 | J9: 2S26E: dividendos 2026E − pagado 1S26. 2027E+: payout × distribuible del año anterior (desfase de un año).
A10: DFN de cierre | C10: =SUM(C5:C9) -> 1264132 | D10: =SUM(D5:D9) -> 1278204.6 | E10: =SUM(E5:E9) -> 1253196.5 | F10: =SUM(F5:F9) -> 1117862.5 | G10: =SUM(G5:G9) -> 979785.02 | H10: =SUM(H5:H9) -> 818997.65
A11: EBITDA del período (anualizado en 2S26E) | C11: =DCF!C11*2 -> 581482.81 | D11: =DCF!D11*1 -> 611360.36 | E11: =DCF!E11*1 -> 654236.23 | F11: =DCF!F11*1 -> 694005.23 | G11: =DCF!G11*1 -> 730577.7 | H11: =DCF!H11*1 -> 766857.78
A12: DFN / EBITDA | C12: =C10/C11 -> 2.1739801 | D12: =D10/D11 -> 2.0907548 | E12: =E10/E11 -> 1.9155108 | F12: =F10/F11 -> 1.6107408 | G12: =G10/G11 -> 1.3411099 | H12: =H10/H11 -> 1.0679916
A13: Utilidad distribuible proxy (FFO − reajuste UF) | C13: 380038.82 | D13: =DCF!D11-Supuestos!$B$93*D5-DCF!D15*(DCF!D11-Supuestos!$B$93*D5)-D8 -> 433704.4 | E13: =DCF!E11-Supuestos!$B$93*E5-DCF!E15*(DCF!E11-Supuestos!$B$93*E5)-E8 -> 452377.56 | F13: =DCF!F11-Supuestos!$B$93*F5-DCF!F15*(DCF!F11-Supuestos!$B$93*F5)-F8 -> 468408.39 | G13: =DCF!G11-Supuestos!$B$93*G5-DCF!G15*(DCF!G11-Supuestos!$B$93*G5)-G8 -> 481694.36 | H13: =DCF!H11-Supuestos!$B$93*H5-DCF!H15*(DCF!H11-Supuestos!$B$93*H5)-H8 -> 514555.78 | J13: 2S26E: distribuible 2026E de Exhibits v6 (año completo). Proxy sin minoritarios.
A14: Capacidad de deuda al objetivo (objetivo × EBITDA − DFN) | C14: =Supuestos!$B$39*C11-C10 -> 771057.8 | D14: =Supuestos!$B$39*D11-D10 -> 861556.65 | E14: =Supuestos!$B$39*E11-E10 -> 1036630.3 | F14: =Supuestos!$B$39*F11-F10 -> 1311155.8 | G14: =Supuestos!$B$39*G11-G10 -> 1577236.9 | H14: =Supuestos!$B$39*H11-H10 -> 1865004.6 | J14: Positivo = espacio para más deuda sin superar el objetivo.

Sheet Comparables
A1: Comparables — múltiplos LTM y NTM con el mismo set de pares que la WACC
A2: Set común = empresas con beta en la WACC y con datos en Bloomberg (columna "Set"). Estadístico principal: 70% mediana Chile + 30% mediana del set común (Supuestos G). MM CLP con TC del 30-06-2026; precio 30-09-2026.
W3: Columnas auxiliares para las medianas (no editar)
A4: Empresa | B4: Ticker | C4: País | D4: Set (1/0) | E4: Chile (1/0) | F4: Market cap | G4: Deuda neta | H4: Minoritarios | I4: EV | J4: Ingresos LTM | K4: EBITDA LTM | L4: EBIT LTM | M4: Utilidad LTM | N4: Patrimonio | O4: EBITDA NTM | P4: EV/EBITDA LTM | Q4: EV/EBITDA NTM | R4: EV/EBIT LTM | S4: P/E LTM | T4: P/BV | W4: EV/EBITDA LTM set | X4: EV/EBITDA LTM Chile | Y4: EV/EBITDA NTM set | Z4: EV/EBITDA NTM Chile | AA4: EV/EBIT LTM set | AB4: EV/EBIT LTM Chile | AC4: P/E LTM set | AD4: P/E LTM Chile | AE4: P/BV set | AF4: P/BV Chile | AG4: EV/EBITDA LTM resto | AH4: EV/EBITDA NTM resto | AI4: EV/EBIT LTM resto | AJ4: P/E LTM resto | AK4: P/BV resto
A5: =Datos_BBG!A8 -> Mallplaza | B5: =Datos_BBG!B8 -> MALLPLAZ CI | C5: =Datos_BBG!D8 -> Chile | D5: Target | E5: — | F5: =Datos_BBG!O8*Datos_BBG!S8 -> 7785450 | G5: =Datos_BBG!M8*Datos_BBG!S8 -> 1311568.6 | H5: =Datos_BBG!N8*Datos_BBG!S8 -> 50841.428 | I5: =F5+G5+H5 -> 9147860 | J5: =Datos_BBG!G8*Datos_BBG!S8 -> 677333.31 | K5: =Datos_BBG!H8*Datos_BBG!S8 -> 544935 | L5: =Datos_BBG!J8*Datos_BBG!S8 -> 540372.73 | M5: =Datos_BBG!K8*Datos_BBG!S8 -> 1258052.7 | N5: =Datos_BBG!L8*Datos_BBG!S8 -> 4820897.8 | O5: =Datos_BBG!H47*Datos_BBG!S47 -> 617130.34 | P5: =IF(OR(K5<=0),"NM",IF(I5/K5>Supuestos!$B$83,"NM",I5/K5)) -> 16.787066 | Q5: =IF(OR(O5<=0),"NM",IF(I5/O5>Supuestos!$B$83,"NM",I5/O5)) -> 14.823222 | R5: =IF(OR(L5<=0),"NM",IF(I5/L5>Supuestos!$B$83,"NM",I5/L5)) -> 16.928797 | S5: =IF(OR(M5<=0,Datos_BBG!Q8=1),"NM",IF(F5/M5>Supuestos!$B$83,"NM",F5/M5)) -> 6.1884925 | T5: =IF(OR(N5<=0),"NM",IF(F5/N5>Supuestos!$B$83,"NM",F5/N5)) -> 1.6149378
A6: =Datos_BBG!A13 -> Parque Arauco | B6: =Datos_BBG!B13 -> PARAUCO CI | C6: =Datos_BBG!D13 -> Chile | D6: =IF(COUNTIF(WACC!$B$6:$B$12,B6)>0,1,0) -> 1 | E6: =IF(C6="Chile",1,0) -> 1 | F6: =Datos_BBG!O13*Datos_BBG!S13 -> 3440408.4 | G6: =Datos_BBG!M13*Datos_BBG!S13 -> 1602287.6 | H6: =Datos_BBG!N13*Datos_BBG!S13 -> 386791.14 | I6: =F6+G6+H6 -> 5429487.2 | J6: =Datos_BBG!G13*Datos_BBG!S13 -> 416366.83 | K6: =Datos_BBG!H13*Datos_BBG!S13 -> 294411 | L6: =Datos_BBG!J13*Datos_BBG!S13 -> 289515.61 | M6: =Datos_BBG!K13*Datos_BBG!S13 -> 154352.78 | N6: =Datos_BBG!L13*Datos_BBG!S13 -> 1961393.2 | O6: =Datos_BBG!H48*Datos_BBG!S48 -> 342581.95 | P6: =IF(OR(K6<=0),"NM",IF(I6/K6>Supuestos!$B$83,"NM",I6/K6)) -> 18.441862 | Q6: =IF(OR(O6<=0),"NM",IF(I6/O6>Supuestos!$B$83,"NM",I6/O6)) -> 15.848725 | R6: =IF(OR(L6<=0),"NM",IF(I6/L6>Supuestos!$B$83,"NM",I6/L6)) -> 18.753694 | S6: =IF(OR(M6<=0,Datos_BBG!Q13=1),"NM",IF(F6/M6>Supuestos!$B$83,"NM",F6/M6)) -> 22.289255 | T6: =IF(OR(N6<=0),"NM",IF(F6/N6>Supuestos!$B$83,"NM",F6/N6)) -> 1.7540636 | W6: =IF(AND(D6=1,ISNUMBER(P6)),P6,"") -> 18.441862 | X6: =IF(AND(D6=1,E6=1,ISNUMBER(P6)),P6,"") -> 18.441862 | Y6: =IF(AND(D6=1,ISNUMBER(Q6)),Q6,"") -> 15.848725 | Z6: =IF(AND(D6=1,E6=1,ISNUMBER(Q6)),Q6,"") -> 15.848725 | AA6: =IF(AND(D6=1,ISNUMBER(R6)),R6,"") -> 18.753694 | AB6: =IF(AND(D6=1,E6=1,ISNUMBER(R6)),R6,"") -> 18.753694 | AC6: =IF(AND(D6=1,ISNUMBER(S6)),S6,"") -> 22.289255 | AD6: =IF(AND(D6=1,E6=1,ISNUMBER(S6)),S6,"") -> 22.289255 | AE6: =IF(AND(D6=1,ISNUMBER(T6)),T6,"") -> 1.7540636 | AF6: =IF(AND(D6=1,E6=1,ISNUMBER(T6)),T6,"") -> 1.7540636 | AG6: =IF(AND(D6=1,E6=0,ISNUMBER(P6)),P6,"") | AH6: =IF(AND(D6=1,E6=0,ISNUMBER(Q6)),Q6,"") | AI6: =IF(AND(D6=1,E6=0,ISNUMBER(R6)),R6,"") | AJ6: =IF(AND(D6=1,E6=0,ISNUMBER(S6)),S6,"") | AK6: =IF(AND(D6=1,E6=0,ISNUMBER(T6)),T6,"")
A7: =Datos_BBG!A18 -> Cencosud Shopping | B7: =Datos_BBG!B18 -> CENCOMAL CI | C7: =Datos_BBG!D18 -> Chile | D7: =IF(COUNTIF(WACC!$B$6:$B$12,B7)>0,1,0) -> 1 | E7: =IF(C7="Chile",1,0) -> 1 | F7: =Datos_BBG!O18*Datos_BBG!S18 -> 3710182.6 | G7: =Datos_BBG!M18*Datos_BBG!S18 -> 852533.94 | H7: =Datos_BBG!N18*Datos_BBG!S18 -> 6464.021 | I7: =F7+G7+H7 -> 4569180.6 | J7: =Datos_BBG!G18*Datos_BBG!S18 -> 390677.95 | K7: =Datos_BBG!H18*Datos_BBG!S18 -> 350561.25 | L7: =Datos_BBG!J18*Datos_BBG!S18 -> 349975.94 | M7: =Datos_BBG!K18*Datos_BBG!S18 -> 353938.28 | N7: =Datos_BBG!L18*Datos_BBG!S18 -> 3136456.8 | O7: =Datos_BBG!H49*Datos_BBG!S49 -> 392093.8 | P7: =IF(OR(K7<=0),"NM",IF(I7/K7>Supuestos!$B$83,"NM",I7/K7)) -> 13.033901 | Q7: =IF(OR(O7<=0),"NM",IF(I7/O7>Supuestos!$B$83,"NM",I7/O7)) -> 11.653284 | R7: =IF(OR(L7<=0),"NM",IF(I7/L7>Supuestos!$B$83,"NM",I7/L7)) -> 13.055699 | S7: =IF(OR(M7<=0,Datos_BBG!Q18=1),"NM",IF(F7/M7>Supuestos!$B$83,"NM",F7/M7)) -> 10.482569 | T7: =IF(OR(N7<=0),"NM",IF(F7/N7>Supuestos!$B$83,"NM",F7/N7)) -> 1.1829216 | W7: =IF(AND(D7=1,ISNUMBER(P7)),P7,"") -> 13.033901 | X7: =IF(AND(D7=1,E7=1,ISNUMBER(P7)),P7,"") -> 13.033901 | Y7: =IF(AND(D7=1,ISNUMBER(Q7)),Q7,"") -> 11.653284 | Z7: =IF(AND(D7=1,E7=1,ISNUMBER(Q7)),Q7,"") -> 11.653284 | AA7: =IF(AND(D7=1,ISNUMBER(R7)),R7,"") -> 13.055699 | AB7: =IF(AND(D7=1,E7=1,ISNUMBER(R7)),R7,"") -> 13.055699 | AC7: =IF(AND(D7=1,ISNUMBER(S7)),S7,"") -> 10.482569 | AD7: =IF(AND(D7=1,E7=1,ISNUMBER(S7)),S7,"") -> 10.482569 | AE7: =IF(AND(D7=1,ISNUMBER(T7)),T7,"") -> 1.1829216 | AF7: =IF(AND(D7=1,E7=1,ISNUMBER(T7)),T7,"") -> 1.1829216 | AG7: =IF(AND(D7=1,E7=0,ISNUMBER(P7)),P7,"") | AH7: =IF(AND(D7=1,E7=0,ISNUMBER(Q7)),Q7,"") | AI7: =IF(AND(D7=1,E7=0,ISNUMBER(R7)),R7,"") | AJ7: =IF(AND(D7=1,E7=0,ISNUMBER(S7)),S7,"") | AK7: =IF(AND(D7=1,E7=0,ISNUMBER(T7)),T7,"")
A8: =Datos_BBG!A23 -> Multiplan | B8: =Datos_BBG!B23 -> MULT3 BZ | C8: =Datos_BBG!D23 -> Brasil | D8: =IF(COUNTIF(WACC!$B$6:$B$12,B8)>0,1,0) -> 1 | E8: =IF(C8="Chile",1,0) -> 0 | F8: =Datos_BBG!O23*Datos_BBG!S23 -> 2907890.3 | G8: =Datos_BBG!M23*Datos_BBG!S23 -> 888983.2 | H8: =Datos_BBG!N23*Datos_BBG!S23 -> 33.049177 | I8: =F8+G8+H8 -> 3796906.6 | J8: =Datos_BBG!G23*Datos_BBG!S23 -> 570440.4 | K8: =Datos_BBG!H23*Datos_BBG!S23 -> 421296.08 | L8: =Datos_BBG!J23*Datos_BBG!S23 -> 397146.06 | M8: =Datos_BBG!K23*Datos_BBG!S23 -> 247648.38 | N8: =Datos_BBG!L23*Datos_BBG!S23 -> 1206875.9 | O8: =Datos_BBG!H50*Datos_BBG!S50 -> 376773.26 | P8: =IF(OR(K8<=0),"NM",IF(I8/K8>Supuestos!$B$83,"NM",I8/K8)) -> 9.0124423 | Q8: =IF(OR(O8<=0),"NM",IF(I8/O8>Supuestos!$B$83,"NM",I8/O8)) -> 10.077431 | R8: =IF(OR(L8<=0),"NM",IF(I8/L8>Supuestos!$B$83,"NM",I8/L8)) -> 9.560479 | S8: =IF(OR(M8<=0,Datos_BBG!Q23=1),"NM",IF(F8/M8>Supuestos!$B$83,"NM",F8/M8)) -> 11.742012 | T8: =IF(OR(N8<=0),"NM",IF(F8/N8>Supuestos!$B$83,"NM",F8/N8)) -> 2.4094361 | W8: =IF(AND(D8=1,ISNUMBER(P8)),P8,"") -> 9.0124423 | X8: =IF(AND(D8=1,E8=1,ISNUMBER(P8)),P8,"") | Y8: =IF(AND(D8=1,ISNUMBER(Q8)),Q8,"") -> 10.077431 | Z8: =IF(AND(D8=1,E8=1,ISNUMBER(Q8)),Q8,"") | AA8: =IF(AND(D8=1,ISNUMBER(R8)),R8,"") -> 9.560479 | AB8: =IF(AND(D8=1,E8=1,ISNUMBER(R8)),R8,"") | AC8: =IF(AND(D8=1,ISNUMBER(S8)),S8,"") -> 11.742012 | AD8: =IF(AND(D8=1,E8=1,ISNUMBER(S8)),S8,"") | AE8: =IF(AND(D8=1,ISNUMBER(T8)),T8,"") -> 2.4094361 | AF8: =IF(AND(D8=1,E8=1,ISNUMBER(T8)),T8,"") | AG8: =IF(AND(D8=1,E8=0,ISNUMBER(P8)),P8,"") -> 9.0124423 | AH8: =IF(AND(D8=1,E8=0,ISNUMBER(Q8)),Q8,"") -> 10.077431 | AI8: =IF(AND(D8=1,E8=0,ISNUMBER(R8)),R8,"") -> 9.560479 | AJ8: =IF(AND(D8=1,E8=0,ISNUMBER(S8)),S8,"") -> 11.742012 | AK8: =IF(AND(D8=1,E8=0,ISNUMBER(T8)),T8,"") -> 2.4094361
A9: =Datos_BBG!A28 -> Allos | B9: =Datos_BBG!B28 -> ALOS3 BZ | C9: =Datos_BBG!D28 -> Brasil | D9: =IF(COUNTIF(WACC!$B$6:$B$12,B9)>0,1,0) -> 1 | E9: =IF(C9="Chile",1,0) -> 0 | F9: =Datos_BBG!O28*Datos_BBG!S28 -> 2656187.5 | G9: =Datos_BBG!M28*Datos_BBG!S28 -> 1221640.7 | H9: =Datos_BBG!N28*Datos_BBG!S28 -> 17188.966 | I9: =F9+G9+H9 -> 3895017.2 | J9: =Datos_BBG!G28*Datos_BBG!S28 -> 524937.58 | K9: =Datos_BBG!H28*Datos_BBG!S28 -> 388838.75 | L9: =Datos_BBG!J28*Datos_BBG!S28 -> 276308.45 | M9: =Datos_BBG!K28*Datos_BBG!S28 -> 166950.15 | N9: =Datos_BBG!L28*Datos_BBG!S28 -> 2296067.8 | O9: =Datos_BBG!H51*Datos_BBG!S51 -> 413640.61 | P9: =IF(OR(K9<=0),"NM",IF(I9/K9>Supuestos!$B$83,"NM",I9/K9)) -> 10.01705 | Q9: =IF(OR(O9<=0),"NM",IF(I9/O9>Supuestos!$B$83,"NM",I9/O9)) -> 9.4164284 | R9: =IF(OR(L9<=0),"NM",IF(I9/L9>Supuestos!$B$83,"NM",I9/L9)) -> 14.096627 | S9: =IF(OR(M9<=0,Datos_BBG!Q28=1),"NM",IF(F9/M9>Supuestos!$B$83,"NM",F9/M9)) -> 15.910064 | T9: =IF(OR(N9<=0),"NM",IF(F9/N9>Supuestos!$B$83,"NM",F9/N9)) -> 1.1568419 | W9: =IF(AND(D9=1,ISNUMBER(P9)),P9,"") -> 10.01705 | X9: =IF(AND(D9=1,E9=1,ISNUMBER(P9)),P9,"") | Y9: =IF(AND(D9=1,ISNUMBER(Q9)),Q9,"") -> 9.4164284 | Z9: =IF(AND(D9=1,E9=1,ISNUMBER(Q9)),Q9,"") | AA9: =IF(AND(D9=1,ISNUMBER(R9)),R9,"") -> 14.096627 | AB9: =IF(AND(D9=1,E9=1,ISNUMBER(R9)),R9,"") | AC9: =IF(AND(D9=1,ISNUMBER(S9)),S9,"") -> 15.910064 | AD9: =IF(AND(D9=1,E9=1,ISNUMBER(S9)),S9,"") | AE9: =IF(AND(D9=1,ISNUMBER(T9)),T9,"") -> 1.1568419 | AF9: =IF(AND(D9=1,E9=1,ISNUMBER(T9)),T9,"") | AG9: =IF(AND(D9=1,E9=0,ISNUMBER(P9)),P9,"") -> 10.01705 | AH9: =IF(AND(D9=1,E9=0,ISNUMBER(Q9)),Q9,"") -> 9.4164284 | AI9: =IF(AND(D9=1,E9=0,ISNUMBER(R9)),R9,"") -> 14.096627 | AJ9: =IF(AND(D9=1,E9=0,ISNUMBER(S9)),S9,"") -> 15.910064 | AK9: =IF(AND(D9=1,E9=0,ISNUMBER(T9)),T9,"") -> 1.1568419
A10: =Datos_BBG!A33 -> Iguatemi | B10: =Datos_BBG!B33 -> IGTI11 BZ | C10: =Datos_BBG!D33 -> Brasil | D10: =IF(COUNTIF(WACC!$B$6:$B$12,B10)>0,1,0) -> 1 | E10: =IF(C10="Chile",1,0) -> 0 | F10: =Datos_BBG!O33*Datos_BBG!S33 -> 1381189.7 | G10: =Datos_BBG!M33*Datos_BBG!S33 -> 382047.95 | H10: =Datos_BBG!N33*Datos_BBG!S33 -> 38.944435 | I10: =F10+G10+H10 -> 1763276.6 | J10: =Datos_BBG!G33*Datos_BBG!S33 -> 272862.76 | K10: =Datos_BBG!H33*Datos_BBG!S33 -> 201422.94 | L10: =Datos_BBG!J33*Datos_BBG!S33 -> 178237.78 | M10: =Datos_BBG!K33*Datos_BBG!S33 -> 114077 | N10: =Datos_BBG!L33*Datos_BBG!S33 -> 881991.06 | O10: =Datos_BBG!H52*Datos_BBG!S52 -> 238273.43 | P10: =IF(OR(K10<=0),"NM",IF(I10/K10>Supuestos!$B$83,"NM",I10/K10)) -> 8.7541002 | Q10: =IF(OR(O10<=0),"NM",IF(I10/O10>Supuestos!$B$83,"NM",I10/O10)) -> 7.4002234 | R10: =IF(OR(L10<=0),"NM",IF(I10/L10>Supuestos!$B$83,"NM",I10/L10)) -> 9.892833 | S10: =IF(OR(M10<=0,Datos_BBG!Q33=1),"NM",IF(F10/M10>Supuestos!$B$83,"NM",F10/M10)) -> 12.107521 | T10: =IF(OR(N10<=0),"NM",IF(F10/N10>Supuestos!$B$83,"NM",F10/N10)) -> 1.5659906 | W10: =IF(AND(D10=1,ISNUMBER(P10)),P10,"") -> 8.7541002 | X10: =IF(AND(D10=1,E10=1,ISNUMBER(P10)),P10,"") | Y10: =IF(AND(D10=1,ISNUMBER(Q10)),Q10,"") -> 7.4002234 | Z10: =IF(AND(D10=1,E10=1,ISNUMBER(Q10)),Q10,"") | AA10: =IF(AND(D10=1,ISNUMBER(R10)),R10,"") -> 9.892833 | AB10: =IF(AND(D10=1,E10=1,ISNUMBER(R10)),R10,"") | AC10: =IF(AND(D10=1,ISNUMBER(S10)),S10,"") -> 12.107521 | AD10: =IF(AND(D10=1,E10=1,ISNUMBER(S10)),S10,"") | AE10: =IF(AND(D10=1,ISNUMBER(T10)),T10,"") -> 1.5659906 | AF10: =IF(AND(D10=1,E10=1,ISNUMBER(T10)),T10,"") | AG10: =IF(AND(D10=1,E10=0,ISNUMBER(P10)),P10,"") -> 8.7541002 | AH10: =IF(AND(D10=1,E10=0,ISNUMBER(Q10)),Q10,"") -> 7.4002234 | AI10: =IF(AND(D10=1,E10=0,ISNUMBER(R10)),R10,"") -> 9.892833 | AJ10: =IF(AND(D10=1,E10=0,ISNUMBER(S10)),S10,"") -> 12.107521 | AK10: =IF(AND(D10=1,E10=0,ISNUMBER(T10)),T10,"") -> 1.5659906
A11: =Datos_BBG!A38 -> IRSA | B11: =Datos_BBG!B38 -> IRSA AR | C11: =Datos_BBG!D38 -> Argentina | D11: =IF(COUNTIF(WACC!$B$6:$B$12,B11)>0,1,0) -> 1 | E11: =IF(C11="Chile",1,0) -> 0 | F11: =Datos_BBG!O38*Datos_BBG!S38 -> 1140416.5 | G11: =Datos_BBG!M38*Datos_BBG!S38 -> 561235.18 | H11: =Datos_BBG!N38*Datos_BBG!S38 -> 87538.904 | I11: =F11+G11+H11 -> 1789190.5 | J11: =Datos_BBG!G38*Datos_BBG!S38 -> 409298.64 | K11: =Datos_BBG!H38*Datos_BBG!S38 -> 145686.2 | L11: =Datos_BBG!J38*Datos_BBG!S38 -> 135134.94 | M11: =Datos_BBG!K38*Datos_BBG!S38 -> 244905.54 | N11: =Datos_BBG!L38*Datos_BBG!S38 -> 1418831.5 | O11: =Datos_BBG!H53*Datos_BBG!S53 -> 286774.76 | P11: =IF(OR(K11<=0),"NM",IF(I11/K11>Supuestos!$B$83,"NM",I11/K11)) -> 12.281125 | Q11: =IF(OR(O11<=0),"NM",IF(I11/O11>Supuestos!$B$83,"NM",I11/O11)) -> 6.2390099 | R11: =IF(OR(L11<=0),"NM",IF(I11/L11>Supuestos!$B$83,"NM",I11/L11)) -> 13.240029 | S11: =IF(OR(M11<=0,Datos_BBG!Q38=1),"NM",IF(F11/M11>Supuestos!$B$83,"NM",F11/M11)) -> 4.6565564 | T11: =IF(OR(N11<=0),"NM",IF(F11/N11>Supuestos!$B$83,"NM",F11/N11)) -> 0.80377159 | W11: =IF(AND(D11=1,ISNUMBER(P11)),P11,"") -> 12.281125 | X11: =IF(AND(D11=1,E11=1,ISNUMBER(P11)),P11,"") | Y11: =IF(AND(D11=1,ISNUMBER(Q11)),Q11,"") -> 6.2390099 | Z11: =IF(AND(D11=1,E11=1,ISNUMBER(Q11)),Q11,"") | AA11: =IF(AND(D11=1,ISNUMBER(R11)),R11,"") -> 13.240029 | AB11: =IF(AND(D11=1,E11=1,ISNUMBER(R11)),R11,"") | AC11: =IF(AND(D11=1,ISNUMBER(S11)),S11,"") -> 4.6565564 | AD11: =IF(AND(D11=1,E11=1,ISNUMBER(S11)),S11,"") | AE11: =IF(AND(D11=1,ISNUMBER(T11)),T11,"") -> 0.80377159 | AF11: =IF(AND(D11=1,E11=1,ISNUMBER(T11)),T11,"") | AG11: =IF(AND(D11=1,E11=0,ISNUMBER(P11)),P11,"") -> 12.281125 | AH11: =IF(AND(D11=1,E11=0,ISNUMBER(Q11)),Q11,"") -> 6.2390099 | AI11: =IF(AND(D11=1,E11=0,ISNUMBER(R11)),R11,"") -> 13.240029 | AJ11: =IF(AND(D11=1,E11=0,ISNUMBER(S11)),S11,"") -> 4.6565564 | AK11: =IF(AND(D11=1,E11=0,ISNUMBER(T11)),T11,"") -> 0.80377159
A12: =Datos_BBG!A43 -> Fibra Danhos | B12: =Datos_BBG!B43 -> DANHOS13 MM | C12: =Datos_BBG!D43 -> México | D12: =IF(COUNTIF(WACC!$B$6:$B$12,B12)>0,1,0) -> 0 | E12: =IF(C12="Chile",1,0) -> 0 | F12: =Datos_BBG!O43*Datos_BBG!S43 -> 2383999.4 | G12: =Datos_BBG!M43*Datos_BBG!S43 -> 618003.43 | H12: =Datos_BBG!N43*Datos_BBG!S43 -> 155940.9 | I12: =F12+G12+H12 -> 3157943.8 | J12: =Datos_BBG!G43*Datos_BBG!S43 -> 417411.61 | K12: =Datos_BBG!H43*Datos_BBG!S43 -> 277625.06 | L12: =Datos_BBG!J43*Datos_BBG!S43 -> 276925.52 | M12: =Datos_BBG!K43*Datos_BBG!S43 -> 301542.11 | N12: =Datos_BBG!L43*Datos_BBG!S43 -> 3445417.1 | O12: =Datos_BBG!H54*Datos_BBG!S54 -> 313368.82 | P12: =IF(OR(K12<=0),"NM",IF(I12/K12>Supuestos!$B$83,"NM",I12/K12)) -> 11.374851 | Q12: =IF(OR(O12<=0),"NM",IF(I12/O12>Supuestos!$B$83,"NM",I12/O12)) -> 10.077403 | R12: =IF(OR(L12<=0),"NM",IF(I12/L12>Supuestos!$B$83,"NM",I12/L12)) -> 11.403585 | S12: =IF(OR(M12<=0,Datos_BBG!Q43=1),"NM",IF(F12/M12>Supuestos!$B$83,"NM",F12/M12)) -> 7.9060247 | T12: =IF(OR(N12<=0),"NM",IF(F12/N12>Supuestos!$B$83,"NM",F12/N12)) -> 0.69193348 | W12: =IF(AND(D12=1,ISNUMBER(P12)),P12,"") | X12: =IF(AND(D12=1,E12=1,ISNUMBER(P12)),P12,"") | Y12: =IF(AND(D12=1,ISNUMBER(Q12)),Q12,"") | Z12: =IF(AND(D12=1,E12=1,ISNUMBER(Q12)),Q12,"") | AA12: =IF(AND(D12=1,ISNUMBER(R12)),R12,"") | AB12: =IF(AND(D12=1,E12=1,ISNUMBER(R12)),R12,"") | AC12: =IF(AND(D12=1,ISNUMBER(S12)),S12,"") | AD12: =IF(AND(D12=1,E12=1,ISNUMBER(S12)),S12,"") | AE12: =IF(AND(D12=1,ISNUMBER(T12)),T12,"") | AF12: =IF(AND(D12=1,E12=1,ISNUMBER(T12)),T12,"") | AG12: =IF(AND(D12=1,E12=0,ISNUMBER(P12)),P12,"") | AH12: =IF(AND(D12=1,E12=0,ISNUMBER(Q12)),Q12,"") | AI12: =IF(AND(D12=1,E12=0,ISNUMBER(R12)),R12,"") | AJ12: =IF(AND(D12=1,E12=0,ISNUMBER(S12)),S12,"") | AK12: =IF(AND(D12=1,E12=0,ISNUMBER(T12)),T12,"")
A14: Estadísticos (excluyen a Mallplaza)
A15: Mediana set común | P15: =IFERROR(MEDIAN(W6:W12),"NM") -> 11.149088 | Q15: =IFERROR(MEDIAN(Y6:Y12),"NM") -> 9.7469298 | R15: =IFERROR(MEDIAN(AA6:AA12),"NM") -> 13.147864 | S15: =IFERROR(MEDIAN(AC6:AC12),"NM") -> 11.924767 | T15: =IFERROR(MEDIAN(AE6:AE12),"NM") -> 1.3744561
A16: Mediana Chile (set común) | P16: =IFERROR(MEDIAN(X6:X12),"NM") -> 15.737882 | Q16: =IFERROR(MEDIAN(Z6:Z12),"NM") -> 13.751005 | R16: =IFERROR(MEDIAN(AB6:AB12),"NM") -> 15.904696 | S16: =IFERROR(MEDIAN(AD6:AD12),"NM") -> 16.385912 | T16: =IFERROR(MEDIAN(AF6:AF12),"NM") -> 1.4684926
A17: Mediana resto (set común sin Chile) | P17: =IFERROR(MEDIAN(AG6:AG12),"NM") -> 9.5147461 | Q17: =IFERROR(MEDIAN(AH6:AH12),"NM") -> 8.4083259 | R17: =IFERROR(MEDIAN(AI6:AI12),"NM") -> 11.566431 | S17: =IFERROR(MEDIAN(AJ6:AJ12),"NM") -> 11.924767 | T17: =IFERROR(MEDIAN(AK6:AK12),"NM") -> 1.3614163
