Workbook

Sheet Datos
A1: Fecha | B1: MALLPLAZA | C1: BCP10 | D1: BCU10 | E1: IPSA | G1: Notas
A2: 45474 | B2: 1345.04 | C2: 6.27 | E2: 6406.94 | G2: MALLPLAZA: cierre diario en CLP (Investing.com, columna "Último"). Ver hoja Verificacion.
A3: 45475 | B3: 1342.18 | C3: 6.28 | E3: 6385.39 | G3: BCP10 / BCU10: tasa % anual, mercado secundario, 10 años (Banco Central de Chile, BDE).
A4: 45476 | B4: 1376.62 | C4: 6.24 | D4: 3.1 | E4: 6533.69 | G4: IPSA: MSCI IPSA Gross (Investing.com), en puntos. No es el S&P/CLX IPSA ni el índice de precio.
A5: 45477 | B5: 1385.8 | C5: 6.23 | D5: 3.1 | E5: 6532.51 | G5: Celdas vacías = sin dato ese día en la fuente. No se interpoló ni se estimó nada.
A6: 45478 | B6: 1381.56 | C6: 6.22 | D6: 3.1 | E6: 6483.67
A7: 45481 | B7: 1376.82 | C7: 6.19 | D7: 3.04 | E7: 6520.93
A8: 45482 | B8: 1381.56 | C8: 6.21 | D8: 3.02 | E8: 6470.13
A9: 45483 | B9: 1364.78 | C9: 6.23 | D9: 2.99 | E9: 6467.17
A10: 45484 | B10: 1364.78 | C10: 6.13 | D10: 2.92 | E10: 6544.62
A11: 45485 | B11: 1362.81 | C11: 6.11 | D11: 2.9 | E11: 6550.01
A12: 45488 | B12: 1375.83 | C12: 6.12 | E12: 6566.38
A13: 45490 | B13: 1396.36 | C13: 6.07 | D13: 2.91 | E13: 6568.77
A14: 45491 | B14: 1440.77 | C14: 6.08 | D14: 2.88 | E14: 6576.7
A15: 45492 | B15: 1421.03 | C15: 6.1 | D15: 2.87 | E15: 6558.68
A16: 45495 | B16: 1440.77 | C16: 6.1 | D16: 2.87 | E16: 6600.64
A17: 45496 | B17: 1445.7 | C17: 6.1 | D17: 2.86 | E17: 6551.36
A18: 45497 | B18: 1435.83 | C18: 6.09 | D18: 2.83 | E18: 6513.85
A19: 45498 | B19: 1424.29 | C19: 6.08 | D19: 2.79 | E19: 6441.01
A20: 45499 | B20: 1440.77 | C20: 6.08 | D20: 2.77 | E20: 6432.16
A21: 45502 | B21: 1454.48 | C21: 6.15 | D21: 2.75 | E21: 6486.19
A22: 45503 | B22: 1450.63 | C22: 6.15 | D22: 2.76 | E22: 6466.13
A23: 45504 | B23: 1440.77 | C23: 6.1 | D23: 2.7 | E23: 6440.56
A24: 45505 | B24: 1445.7 | C24: 6.05 | D24: 2.66 | E24: 6418.15
... A40: 45530 | B40: 1513.1 | C40: 5.71 | D40: 2.38 | E40: 6442.19
A41: 45531 | B41: 1503.92 | C41: 5.73 | E41: 6379.46
A42: 45532 | B42: 1487.15 | C42: 5.71 | D42: 2.39 | E42: 6385.52
A43: 45533 | B43: 1526.62 | C43: 5.71 | D43: 2.42 | E43: 6448.28
A44: 45534 | B44: 1490.21 | C44: 5.64 | D44: 2.37 | E44: 6459.96
A45: 45537 | B45: 1519.71 | C45: 5.64 | E45: 6456.25
A46: 45538 | B46: 1520.21 | C46: 5.61 | D46: 2.38 | E46: 6387.18
A47: 45539 | B47: 1510.63 | C47: 5.56 | E47: 6389.05
A48: 45540 | B48: 1529.48 | C48: 5.53 | E48: 6361.59
A49: 45541 | B49: 1506.29 | C49: 5.5 | D49: 2.26 | E49: 6245.42
A50: 45544 | B50: 1478.76 | C50: 5.49 | E50: 6232.11
A51: 45545 | B51: 1460.5 | C51: 5.41 | D51: 2.2 | E51: 6214.86
A52: 45546 | B52: 1491.29 | C52: 5.37 | D52: 2.12 | E52: 6301.58
A53: 45547 | B53: 1509.05 | C53: 5.37 | D53: 2.1 | E53: 6343.16
A54: 45548 | B54: 1502.94 | C54: 5.31 | E54: 6351.31
A55: 45551 | B55: 1521.69 | C55: 5.32 | E55: 6346.81
...

Sheet Verificacion
A1: Verificación de series — Mallplaza vs tasas (Chile)
A2: Rango pedido: 30-06-2024 a 30-09-2026. Fecha de extracción: 17-10-2026. Valores calculados con fórmulas sobre la hoja Datos.
A4: Fecha de control 1 | B4: 46203
A5: Fecha de control 2 | B5: 46295
A7: Serie (columna) | B7: Valor al 30-06-2026 | C7: Valor al 30-09-2026 | D7: N.º observaciones | E7: Primera fecha con dato | F7: Última fecha con dato | G7: Unidad | H7: Fuente (URL) | I7: Nombre de la serie en la fuente
A8: MALLPLAZA (B) | B8: =INDEX(Datos!B$2:B$560,MATCH($B$4,Datos!$A$2:$A$560,0)) -> 3800 | C8: =INDEX(Datos!B$2:B$560,MATCH($B$5,Datos!$A$2:$A$560,0)) -> 3555 | D8: =COUNT(Datos!B$2:B$560) -> 559 | E8: =INDEX(Datos!$A$2:$A$560,MATCH(TRUE(),INDEX(ISNUMBER(Datos!B$2:B$560),0),0)) -> 45474 | F8: =LOOKUP(2,1/ISNUMBER(Datos!B$2:B$560),Datos!$A$2:$A$560) -> 46295 | G8: CLP por acción (cierre) | H8: https://es.investing.com/equities/plaza-historical-data | I8: Plaza (MALLPLAZA) — Datos históricos, columna "Último", frecuencia diaria. Santiago, valores en CLP
A9: BCP10 (C) | B9: =INDEX(Datos!C$2:C$560,MATCH($B$4,Datos!$A$2:$A$560,0)) -> 5.43 | C9: =INDEX(Datos!C$2:C$560,MATCH($B$5,Datos!$A$2:$A$560,0)) -> 6.25 | D9: =COUNT(Datos!C$2:C$560) -> 439 | E9: =INDEX(Datos!$A$2:$A$560,MATCH(TRUE(),INDEX(ISNUMBER(Datos!C$2:C$560),0),0)) -> 45474 | F9: =LOOKUP(2,1/ISNUMBER(Datos!C$2:C$560),Datos!$A$2:$A$560) -> 46295 | G9: % anual (nominal) | H9: https://si3.bcentral.cl/Siete/ES/Siete/Cuadro/CAP_TASA_INTERES/MN_TASA_INTERES_09/TMS_15/T311 | I9: Tasas de interés mercado secundario, bonos, en pesos (porcentaje) — "Bonos en pesos a 10 años (BCP,BTP)", frecuencia Diaria. Código BDE no visible en la tabla pública; no se anota.
A10: BCU10 (D) | B10: =INDEX(Datos!D$2:D$560,MATCH($B$4,Datos!$A$2:$A$560,0)) -> 2.5 | C10: =INDEX(Datos!D$2:D$560,MATCH($B$5,Datos!$A$2:$A$560,0)) -> 2.82 | D10: =COUNT(Datos!D$2:D$560) -> 484 | E10: =INDEX(Datos!$A$2:$A$560,MATCH(TRUE(),INDEX(ISNUMBER(Datos!D$2:D$560),0),0)) -> 45476 | F10: =LOOKUP(2,1/ISNUMBER(Datos!D$2:D$560),Datos!$A$2:$A$560) -> 46295 | G10: % anual (real, en UF) | H10: https://si3.bcentral.cl/Siete/ES/Siete/Cuadro/CAP_TASA_INTERES/MN_TASA_INTERES_09/TMS_16/T312 | I10: Tasas de interés mercado secundario, bonos, en UF (porcentaje) — "Bonos en UF a 10 años (BCU, BTU)", frecuencia Diaria. Código BDE no visible en la tabla pública; no se anota.
A11: IPSA (E) | B11: =INDEX(Datos!E$2:E$560,MATCH($B$4,Datos!$A$2:$A$560,0)) -> 10839.8 | C11: =INDEX(Datos!E$2:E$560,MATCH($B$5,Datos!$A$2:$A$560,0)) -> 10969.49 | D11: =COUNT(Datos!E$2:E$560) -> 559 | E11: =INDEX(Datos!$A$2:$A$560,MATCH(TRUE(),INDEX(ISNUMBER(Datos!E$2:E$560),0),0)) -> 45474 | F11: =LOOKUP(2,1/ISNUMBER(Datos!E$2:E$560),Datos!$A$2:$A$560) -> 46295 | G11: Puntos de índice | H11: https://es.investing.com/indices/ipsa-historical-data | I11: MSCI IPSA Gross (MMXIPSAGC) — columna "Último", diaria. Sustituye al S&P/CLX IPSA (ver notas).
A13: Comprobación pedida
A14: MALLPLAZA cerró en 3.555 el 30-09-2026 | B14: =IF(C8=3555,"SÍ: confirmado (Investing.com)","NO: cerró en "&C8) -> SÍ: confirmado (Investing.com)
A15: Yahoo Finance (MALLPLAZA.SN) para esa fecha | B15: 3900 | C15: No coincide: Yahoo no se usó para el final de la serie (ver notas).
A18: Notas y problemas
A19: 1) MALLPLAZA — fuente elegida: Investing.com ("Último"). Es la única que coincide con el cierre de 3.555 del 30-09-2026. Yahoo repite 3.950 del 17-07-2026 al 11-09-2026 (41 cierres) y 3.900 del 17-09-2026 al 01-10-2026; Investing muestra precios distintos esos días.
A20: 2) MALLPLAZA — NO se puede asegurar que sea cierre "sin ajustar por dividendos": comparando con Yahoo (cierre bruto) en los 560 días comunes, Investing coincide exacto en 363 días; del 01-07-2024 al 11-12-2024 (107 días) está ~1,3% bajo Yahoo (factor 0,98682 constante, típico de ajuste por dividendo), y hay otros tramos con diferencias (abr-2025, mar-2026, algunos días sueltos). Detalle día a día en la hoja Comparacion_MALLPLAZA.
A21: 3) MALLPLAZA — la serie de Yahoo (cierre bruto) se incluye completa en la hoja MALLPLAZA_Yahoo solo como referencia, hasta el 01-10-2026. Su tramo desde el 17-07-2026 no es confiable.
A22: 4) IPSA — la fuente pedida (S&P/CLX IPSA) no está disponible: Yahoo no tiene ese índice (solo MSCI IPSA y ETFs) e Investing.com lista "MSCI IPSA Gross" y "MSCI IPSA CLP Price". El MSCI IPSA CLP Price solo mostraba historial desde el 10-09-2026, por lo que se usó MSCI IPSA Gross (incluye dividendos, no es el IPSA de precio). Conviene tenerlo presente al estimar sensibilidades.
A23: 5) BCP10 / BCU10 — el Banco Central publica estas tasas solo los días con transacciones en el mercado secundario; los días sin dato se dejan vacíos (no se interpoló). Tabla pública, sin iniciar sesión. Se usó la tabla de mercado secundario (no la de bonos licitados).
A24: 6) Las fechas de Datos son la unión de los días con dato en al menos una serie entre 30-06-2024 y 30-09-2026. Al 30-06-2024 (domingo) no hay datos; la primera fila es el 01-07-2024.
A25: 7) Las series de MALLPLAZA e IPSA se transcribieron desde la pantalla de Investing.com/Yahoo a archivos de trabajo, validadas con recuento y suma de control (570/570 y 561/561 filas); la descarga directa de CSV falló tras varias descargas.

Sheet Comparacion_MALLPLAZA
A1: Fecha | B1: Investing (usado en Datos) | C1: Yahoo (cierre bruto) | D1: Diferencia % | E1: Observación
A2: 45471 | C2: 1369.9 | D2: =IF(AND(ISNUMBER(B2),ISNUMBER(C2)),B2/C2-1,"")
A3: 45474 | B3: 1345.04 | C3: 1363 | D3: =IF(AND(ISNUMBER(B3),ISNUMBER(C3)),B3/C3-1,"") -> -0.013176816
A4: 45475 | B4: 1342.18 | C4: 1360.1 | D4: =IF(AND(ISNUMBER(B4),ISNUMBER(C4)),B4/C4-1,"") -> -0.013175502
A5: 45476 | B5: 1376.62 | C5: 1395 | D5: =IF(AND(ISNUMBER(B5),ISNUMBER(C5)),B5/C5-1,"") -> -0.013175627
A6: 45477 | B6: 1385.8 | C6: 1404.3 | D6: =IF(AND(ISNUMBER(B6),ISNUMBER(C6)),B6/C6-1,"") -> -0.013173823
A7: 45478 | B7: 1381.56 | C7: 1400 | D7: =IF(AND(ISNUMBER(B7),ISNUMBER(C7)),B7/C7-1,"") -> -0.013171429
A8: 45481 | B8: 1376.82 | C8: 1395.2 | D8: =IF(AND(ISNUMBER(B8),ISNUMBER(C8)),B8/C8-1,"") -> -0.013173739
A9: 45482 | B9: 1381.56 | C9: 1400 | D9: =IF(AND(ISNUMBER(B9),ISNUMBER(C9)),B9/C9-1,"") -> -0.013171429
A10: 45483 | B10: 1364.78 | C10: 1383 | D10: =IF(AND(ISNUMBER(B10),ISNUMBER(C10)),B10/C10-1,"") -> -0.013174259
A11: 45484 | B11: 1364.78 | C11: 1383 | D11: =IF(AND(ISNUMBER(B11),ISNUMBER(C11)),B11/C11-1,"") -> -0.013174259
A12: 45485 | B12: 1362.81 | C12: 1381 | D12: =IF(AND(ISNUMBER(B12),ISNUMBER(C12)),B12/C12-1,"") -> -0.013171615
A13: 45488 | B13: 1375.83 | C13: 1394.2 | D13: =IF(AND(ISNUMBER(B13),ISNUMBER(C13)),B13/C13-1,"") -> -0.013176015
A14: 45490 | B14: 1396.36 | C14: 1415 | D14: =IF(AND(ISNUMBER(B14),ISNUMBER(C14)),B14/C14-1,"") -> -0.013173145
... A562: 46296 | B562: 3599.9 | C562: 3900 | D562: =IF(AND(ISNUMBER(B562),ISNUMBER(C562)),B562/C562-1,"") -> -0.076948718

Sheet MALLPLAZA_Yahoo
A1: Fecha | B1: Close Yahoo MALLPLAZA.SN (CLP, sin ajustar) | D1: Fuente: https://finance.yahoo.com/quote/MALLPLAZA.SN/history (datos del servicio de gráficos de Yahoo). Solo referencia: tramo desde 17-07-2026 poco confiable.
A2: 45471 | B2: 1369.9
A3: 45474 | B3: 1363
A4: 45475 | B4: 1360.1
A5: 45476 | B5: 1395
A6: 45477 | B6: 1404.3
A7: 45478 | B7: 1400
A8: 45481 | B8: 1395.2
A9: 45482 | B9: 1400
A10: 45483 | B10: 1383
A11: 45484 | B11: 1383
A12: 45485 | B12: 1381
A13: 45488 | B13: 1394.2
... A562: 46296 | B562: 3900
