Workbook

Sheet README
A1: Mallplaza (Plaza S.A.) — Financial Analysis exhibits v5 · 05-10-2026 (v4 + hoja FCFF_DCF: interfaz forecast ↔ valuation)
A2: Borrador de trabajo del equipo. Todo número debe verificarse contra la fuente citada en Inputs antes de entrar al informe.
A4: Convención de colores: azul = dato ingresado [R]/[C]; negro = fórmula; verde = vínculo a la hoja Inputs; amarillo = alerta.
A5: Hojas: Inputs · Forecast · Forecast_link · FCFF_DCF · Peers_inputs · E1_DuPont · E2_FFO_bridge · E3_Growth · E4_Cash · E5_Leverage · E6_Debt · E7_WACC
A6: Para actualizar: cambiar solo valores azules en Inputs, Peers_inputs, E6 (tabla de bonos) o E7 (tabla de tasas).
A7: Pendientes: covenant (E5); tasas de descuento de los pares (CMF); GLA de Colombia por año (E3); IPC mensual Colombia (E3); ticker Colombia USD 10Y (E7); ingresos 2019–2020 y EBITDA 2019 (E1); fecha de cierre de Gran Plaza (Forecast); dueño del motor operativo con valuation.
A8: v3 (28-09): Inputs +26 filas (tipo de cambio, inflación, PI por país, Chile segmento); nueva hoja Peers_inputs; E1 bloque C (pares); E3 bloque B (moneda local y real) + gráfico; E5 bloque de pares; nueva hoja E7_WACC con gráfico. E2, E4 y E6 sin cambios.
A9: v4 (05-10): nueva hoja Forecast (motor operativo); Forecast_link vinculado; Inputs: utilidad 2022 reformulada 157.667, distribuible 2023 = 197.540 [R] y 2022 [C], balances 2022; E7: WACC jun-25 y residuos semestrales 2025.
A11: v6+ (16-10): nueva hoja E8_ROIC_RONIC (ROIC 2025 = NOPAT / capital promedio a valor razonable; RONIC de la expansión).

Sheet Inputs
A1: Inputs — datos reportados [R] y supuestos [S] (MM CLP salvo indicación)
A3: Clave | B3: Concepto | C3: Valor | D3: Unidad | E3: Período | F3: Tag | G3: Fuente
A4: rev23 | B4: Ingresos ordinarios | C4: 419904 | D4: MM CLP | E4: FY2023 | F4: R | G4: EEFF dic-24, EERR (comparativo)
A5: rev24 | B5: Ingresos ordinarios | C5: 494605 | D5: MM CLP | E5: FY2024 | F5: R | G5: EEFF dic-25, EERR (reformulado)
A6: rev25 | B6: Ingresos ordinarios | C6: 653911 | D6: MM CLP | E6: FY2025 | F6: R | G6: EEFF dic-25, EERR
A7: rev1s25 | B7: Ingresos ordinarios | C7: 316108 | D7: MM CLP | E7: 1S25 | F7: R | G7: EEFF jun-26, EERR (comparativo)
A8: rev1s26 | B8: Ingresos ordinarios | C8: 339530 | D8: MM CLP | E8: 1S26 | F8: R | G8: EEFF jun-26, EERR
A9: ebitda24 | B9: EBITDA (definición compañía) | C9: 380637 | D9: MM CLP | E9: FY2024 | F9: R | G9: Análisis Razonado 2025
A10: ebitda25 | B10: EBITDA (definición compañía) | C10: 526228 | D10: MM CLP | E10: FY2025 | F10: R | G10: Análisis Razonado 2025; reconciliado WP §2.1
A11: ni_cons25 | B11: Ganancia consolidada | C11: 1440978 | D11: MM CLP | E11: FY2025 | F11: R | G11: EEFF dic-25, EERR
A12: ni24 | B12: Utilidad atribuible a la controladora | C12: 335934 | D12: MM CLP | E12: FY2024 | F12: R | G12: EEFF dic-25, EERR
A13: ni25 | B13: Utilidad atribuible a la controladora | C13: 1431012 | D13: MM CLP | E13: FY2025 | F13: R | G13: EEFF dic-25, EERR
A14: nci25 | B14: Utilidad atribuible a no controladores | C14: 9967 | D14: MM CLP | E14: FY2025 | F14: R | G14: EEFF dic-25, EERR
A15: oif25 | B15: Otros ingresos por función (incl. valor razonable 1.447.136) | C15: 1448943 | D15: MM CLP | E15: FY2025 | F15: R | G15: EEFF dic-25, Nota 23.2
... A89: dist23 | B89: Utilidad líquida distribuible | C89: 197540 | D89: MM CLP | E89: FY2023 | F89: R | G89: EEFF dic-23, Nota 21e (utilidad líquida y distribuible). Reemplaza la inferida 148.155
A90: rev19 | B90: Ingresos ordinarios | D90: MM CLP | E90: FY2019 | F90: P | G90: PENDIENTE: Bloomberg FA (export existente)
A91: rev20 | B91: Ingresos ordinarios | D91: MM CLP | E91: FY2020 | F91: P | G91: PENDIENTE: Bloomberg FA (export existente)
A92: ebitda19 | B92: EBITDA (definición compañía) | D92: MM CLP | E92: FY2019 | F92: P | G92: PENDIENTE: Bloomberg ARD_REF_EBITDA_IS
A93: ta21r | B93: Total activos REFORMULADO al 01-01-2022 | C93: 4094996 | D93: MM CLP | E93: 01-01-22 | F93: R | G93: EEFF dic-23, balance reformulado al 01-01-2022
A94: ta22 | B94: Total activos | C94: 4513943 | D94: MM CLP | E94: dic-22 | F94: R | G94: EEFF dic-23, balance reformulado al 31-12-2022
A95: eq21r | B95: Patrimonio atribuible REFORMULADO al 01-01-2022 | C95: 2167172 | D95: MM CLP | E95: 01-01-22 | F95: R | G95: EEFF dic-23, patrimonio atribuible reformulado al 01-01-2022
A96: eq22 | B96: Patrimonio atribuible | C96: 2263298 | D96: MM CLP | E96: dic-22 | F96: R | G96: EEFF dic-23, patrimonio atribuible reformulado al 31-12-2022
A97: dist22 | B97: Utilidad líquida distribuible | C97: 95856 | D97: MM CLP | E97: FY2022 | F97: C | G97: Proxy: 157.667 − valor razonable 79.489 × (1 − 22,24%); 22,24% = impuesto diferido / valor razonable de la Nota 21e 2023 (43.537 / 195.756). EEFF dic-23, Notas 24.2 y 21e. La compañía no publica la cifra 2022 bajo NIC 40
A98: payout | B98: Payout sobre utilidad distribuible (política) | C98: 0.4 | D98: % | E98: Política | F98: R | G98: Acuerdo de directorio 25-01-2017; EEFF dic-25 Nota 20e
A99: bank25 | B99: Obligaciones con bancos | C99: 301600 | D99: MM CLP | E99: dic-25 | F99: R | G99: EEFF dic-25, Nota 14
A100: co23 | B100: Ingresos segmento Colombia | C100: 36360 | D100: MM CLP | E100: FY2023 | F100: R | G100: Bloomberg FA GEO (WP §55)
A101: fx_cop23 | B101: CLP por COP, promedio del período | C101: 0.197936 | D101: CLP/COP | E101: FY2023 (feb–dic) | F101: C | G101: Bloomberg USDCLP/USDCOP REGN Curncy, PX_LAST diario, cruces día a día y promediados; export 28-09-2026 (WP §82). USDCLP parte 31-01-2023
A102: fx_cop24 | B102: CLP por COP, promedio del período | C102: 0.232018 | D102: CLP/COP | E102: FY2024 | F102: C | G102: Ídem (WP §82)
A103: fx_cop25 | B103: CLP por COP, promedio del período | C103: 0.235126 | D103: CLP/COP | E103: FY2025 | F103: C | G103: Ídem (WP §82)
A104: fx_cop1s25 | B104: CLP por COP, promedio del período | C104: 0.22793 | D104: CLP/COP | E104: 1S25 | F104: C | G104: Ídem (WP §82)
... A125: shares | B125: Acciones en circulación | C125: 2190 | D125: MM acciones | E125: sep-26 | F125: R | G125: Bloomberg DES 27-09-2026

Sheet Forecast
A1: Forecast — motor operativo 2026E–2031E (CLP nominales; drivers en real por país, nominalizados con IPC y tipo de cambio de consenso)
A2: Borrador de trabajo [S] para el equipo. Azul = input; amarillo = supuesto clave a discutir; negro = fórmula; verde = vínculo a otra hoja. Alimenta Forecast_link → E1. Caso base: sin Gran Plaza y sin "Otros proyectos Chile" (46.500 m² sin fecha); ambos con interruptor.
A3: Tags: [R] reportado · [P] consenso de mercado (Bloomberg ECFC, composite de contribuidores, privado, 05-10-2026) · [C] cálculo · [S] supuesto propio.
A5: A. Macro (fin de año salvo IPC, que es promedio anual) | B5: Tag | C5: 2025A | D5: 2026E | E5: 2027E | F5: 2028E | G5: 2029E | H5: 2030E | I5: 2031E | J5: Fuente / supuesto
A6: IPC Chile (YoY%) | B6: P / S | C6: 0.042 | D6: 0.037 | E6: 0.032 | F6: 0.03 | G6: 0.03 | H6: 0.03 | I6: 0.03 | J6: ECFC Chile 2025–2028 [P]; 2029–2031 = meta BCCh 3% [S]
A7: IPC Perú (YoY%) | B7: P / S | C7: 0.015 | D7: 0.038 | E7: 0.026 | F7: 0.024 | G7: 0.02 | H7: 0.02 | I7: 0.02 | J7: ECFC Perú 2025–2028 [P]; 2029–2031 = centro del rango meta BCRP (1%–3%) [S]
A8: IPC Colombia (promedio, YoY%) | B8: P / S | C8: 0.051 | D8: 0.06 | E8: 0.054 | F8: 0.041 | G8: 0.035 | H8: 0.03 | I8: 0.03 | J8: ECFC Colombia 2025–2028 [P]; 2029 convergencia; 2030–2031 = meta BanRep 3% [S]
A9: Tasa de política BCCh (fin de año) | B9: P / S | C9: 0.045 | D9: 0.0452 | E9: 0.0456 | F9: 0.0433 | G9: 0.0433 | H9: 0.0433 | I9: 0.0433 | J9: ECFC Chile [P]; 2029+ se mantiene [S]. Referencia, no se usa en fórmulas
A10: USDCLP (fin de año) | B10: P / S | C10: 900.58 | D10: 937 | E10: 908.5 | F10: 921 | G10: =F10 -> 921 | H10: =G10 -> 921 | I10: =H10 -> 921 | J10: ECFC [P]; 2029+ se mantiene [S] (solo afecta capex en USD de "Otros proyectos Chile" si se activa)
A11: USDPEN (fin de año) | B11: P | C11: 3.36 | D11: 3.39 | E11: 3.3 | F11: 3.25 | J11: ECFC Perú [P]
A12: USDCOP (fin de año) | B12: P | C12: 3775 | D12: 3213 | E12: 3288 | F12: 3500 | J12: ECFC Colombia [P]
A13: CLP por PEN (fin de año) | B13: C | C13: =C10/C11 -> 268.02976 | D13: =D10/D11 -> 276.40118 | E13: =E10/E11 -> 275.30303 | F13: =F10/F11 -> 283.38462 | G13: =F13*(1+G6)/(1+G7) -> 286.1629 | H13: =G13*(1+H6)/(1+H7) -> 288.96841 | I13: =H13*(1+I6)/(1+I7) -> 291.80144 | J13: Cruce de consenso 2025–2028; 2029+ paridad de poder de compra relativa con IPC de cada país [S]
A14: CLP por COP (fin de año) | B14: C | C14: =C10/C12 -> 0.23856424 | D14: =D10/D12 -> 0.29162776 | E14: =E10/E12 -> 0.27630779 | F14: =F10/F12 -> 0.26314286 | G14: =F14*(1+G6)/(1+G8) -> 0.26187164 | H14: =G14*(1+H6)/(1+H8) -> 0.26187164 | I14: =H14*(1+I6)/(1+I8) -> 0.26187164 | J14: Cruce de consenso 2025–2028; 2029+ paridad de poder de compra relativa con IPC de cada país [S]
A15: CLP por PEN (promedio) | B15: C | C15: =Inputs!C107 -> 266.84002 | D15: =G34/G31 -> 267.99722 | E15: =(D13+E13)/2 -> 275.85211 | F15: =(E13+F13)/2 -> 279.34382 | G15: =(F13+G13)/2 -> 284.77376 | H15: =(G13+H13)/2 -> 287.56566 | I15: =(H13+I13)/2 -> 290.38493 | J15: 2025A promedio real (Inputs); 2026E desde el puente semestral (bloque B); 2027+ promedio de fin de año t−1 y t [S]
A16: CLP por COP (promedio) | B16: C | C16: =Inputs!C103 -> 0.235126 | D16: =G35/G32 -> 0.26340869 | E16: =(D14+E14)/2 -> 0.28396777 | F16: =(E14+F14)/2 -> 0.26972532 | G16: =(F14+G14)/2 -> 0.26250725 | H16: =(G14+H14)/2 -> 0.26187164 | I16: =(H14+I14)/2 -> 0.26187164 | J16: 2025A promedio real (Inputs); 2026E desde el puente semestral (bloque B); 2027+ promedio de fin de año t−1 y t [S]
A17: USDCLP (promedio) | B17: C | D17: =(C10+D10)/2 -> 918.79 | E17: =(D10+E10)/2 -> 922.75 | F17: =(E10+F10)/2 -> 914.75 | G17: =(F10+G10)/2 -> 921 | H17: =(G10+H10)/2 -> 921 | I17: =(H10+I10)/2 -> 921 | J17: 2025A promedio real (Inputs); 2026E desde el puente semestral (bloque B); 2027+ promedio de fin de año t−1 y t [S]
A19: B. Puente 2026E = 1S26 real + 2S26E (moneda local) | C19: 1S25 | D19: 2S25 | E19: 1S26 | F19: 2S26E | G19: 2026E | J19: Fuente / supuesto
A20: Cierre jun-26: USDCLP | B20: R | E20: 922.1 | J20: Release 2T26, nota de tipo de cambio de la tabla de proyectos
A21: Cierre jun-26: USDPEN | B21: R | E21: 3.41 | J21: Ídem
A22: Cierre jun-26: USDCOP | B22: R | E22: 3416.45 | J22: Ídem
A23: CLP por PEN (promedio del semestre) | B23: C | C23: =Inputs!C108 -> 259.72007 | D23: =2*Inputs!C107-Inputs!C108 -> 273.95997 | E23: =Inputs!C109 -> 262.11386 | F23: =(E20/E21+D13)/2 -> 273.40587 | J23: 2S25 = 2 × promedio anual − 1S25 (aproxima pesos iguales por semestre); 2S26E = promedio entre cierre jun-26 y fin de 2026 de consenso [S]
A24: CLP por COP (promedio del semestre) | B24: C | C24: =Inputs!C104 -> 0.22793 | D24: =2*Inputs!C103-Inputs!C104 -> 0.242322 | E24: =Inputs!C105 -> 0.244951 | F24: =(E20/E22+D14)/2 -> 0.2807639 | J24: Ídem
A25: USDCLP (promedio 2S26E) | B25: C | F25: =(E20+D10)/2 -> 929.55 | J25: Para convertir el capex en USD del 2S26
A26: Ingresos segmento Chile (MM CLP) | B26: R | C26: =Inputs!C29 -> 230626 | D26: =Inputs!C36-Inputs!C29 -> 239338 | E26: =Inputs!C30 -> 244588 | J26: EEFF Notas de segmentos (Inputs)
A27: Ingresos segmento Perú (MM CLP) | B27: R | C27: =Inputs!C33 -> 56496 | D27: =Inputs!C40-Inputs!C33 -> 64824 | E27: =Inputs!C34 -> 61532 | J27: Ídem
A28: Ingresos segmento Colombia (MM CLP) | B28: R | C28: =Inputs!C31 -> 29393 | D28: =Inputs!C38-Inputs!C31 -> 33234 | E28: =Inputs!C32 -> 33899 | J28: Ídem
A29: Crecimiento local 1S26 vs 1S25 (Chile / Perú / Colombia) → se aplica al 2S26E | B29: S | C29: =E30/C30-1 -> 0.060539575 | D29: =E31/C31-1 -> 0.079192337 | E29: =E32/C32-1 -> 0.073161901 | J29: Columnas C/D/E de esta fila = Chile / Perú / Colombia (no semestres). Supuesto clave [S]: el 2S26 repite el crecimiento local del 1S26; las aperturas de 2026 (8.900 m²) quedan dentro
A30: Chile (MM CLP) | B30: C | C30: =C26 -> 230626 | D30: =D26 -> 239338 | E30: =E26 -> 244588 | F30: =D26*(1+E26/C26-1) -> 253827.42 | G30: =E30+F30 -> 498415.42
A31: Perú (MM PEN) | B31: C | C31: =C27/C23 -> 217.52651 | D31: =D27/D23 -> 236.61851 | E31: =E27/E23 -> 234.75294 | F31: =D31*E31/C31 -> 255.35689 | G31: =E31+F31 -> 490.10983
A32: Colombia (MM COP) | B32: C | C32: =C28/C24 -> 128956.26 | D32: =D28/D24 -> 137148.09 | E32: =E28/E24 -> 138390.94 | F32: =D32*E32/C32 -> 147182.11 | G32: =E32+F32 -> 285573.05
A33: 2026E Chile en CLP | B33: C | F33: =F30 -> 253827.42 | G33: =E26+F30 -> 498415.42
A34: 2026E Perú en CLP | B34: C | F34: =F31*F23 -> 69816.072 | G34: =E27+F31*F23 -> 131348.07
A35: 2026E Colombia en CLP | B35: C | F35: =F32*F24 -> 41323.423 | G35: =E28+F32*F24 -> 75222.423
A37: C. Pipeline de GLA (m² agregados por año de apertura) y maduración | B37: Tag | C37: 2025A | D37: 2026E | E37: 2027E | F37: 2028E | G37: 2029E | H37: 2030E | I37: 2031E | J37: Fuente / supuesto
A38: Factor de ingreso: año de apertura | B38: S | D38: 0.35 | J38: [S] apertura a mitad de año (50%) × 70% de productividad en el primer año
A39: Factor de ingreso: segundo año | B39: S | D39: 0.9 | J39: [S]
A40: Factor de ingreso: tercer año en adelante | B40: S | D40: 1 | J40: [S]
A41: GLA nuevo Chile por año de apertura (m²) | B41: R | D41: 7600 | E41: 37150 | F41: 23150 | J41: Release 2T26, "Proyectos de Expansión en Curso" (Trébol, Oeste, Norte, La Serena)
A42: GLA nuevo Perú por año de apertura (m²) | B42: R | D42: 1300 | E42: 35800 | F42: 18700 | J42: Release 2T26 (Trujillo, Piura, Angamos, La Marina)
A43: "Otros proyectos Chile" incluidos (1 = sí) | B43: S | D43: 1 | J43: v7: activado — pipeline completo con fecha (170.200 m²); Memoria 2025, p. 45: apertura en 2028
...

Sheet Forecast_link
A1: Forecast_link — insumos proyectados 2026E–2031E (vinculados a la hoja Forecast)
A2: Vinculado a la hoja Forecast (motor operativo). Si valuation mantiene un modelo propio, reemplazar estos vínculos por sus cifras: deben ser idénticas a las del DCF/NAV.
A4: Línea (MM CLP) | B4: 2026E | C4: 2027E | D4: 2028E | E4: 2029E | F4: 2030E | G4: 2031E
A5: Ingresos ordinarios | B5: =Forecast!D95 -> 703998.94 | C5: =Forecast!E95 -> 767179.42 | D5: =Forecast!F95 -> 826661.82 | E5: =Forecast!G95 -> 883482.45 | F5: =Forecast!H95 -> 923321.86 | G5: =Forecast!I95 -> 959373.85
A6: EBITDA (definición compañía) | B6: =Forecast!D104 -> 561315.41 | C6: =Forecast!E104 -> 611360.36 | D6: =Forecast!F104 -> 659160.32 | E6: =Forecast!G104 -> 704684.52 | F6: =Forecast!H104 -> 736419.6 | G6: =Forecast!I104 -> 765088.08
A7: FFO atribuible | B7: =Forecast!D114 -> 428521.01 | C7: =Forecast!E114 -> 457343.87 | D7: =Forecast!F114 -> 479815.31 | E7: =Forecast!G114 -> 500558.62 | F7: =Forecast!H114 -> 509123.66 | G7: =Forecast!I114 -> 535305.59
A8: Utilidad líquida distribuible (normalizada) | B8: =Forecast!D119 -> 380038.82 | C8: =Forecast!E119 -> 415490.8 | D8: =Forecast!F119 -> 440070.47 | E8: =Forecast!G119 -> 462674.09 | F8: =Forecast!H119 -> 477016.6 | G8: =Forecast!I119 -> 509052.03
A9: Revalorización de PI atribuible, neta de impuesto diferido | B9: =Forecast!D150 -> 259116.35 | C9: =Forecast!E150 -> 178038.57 | D9: =Forecast!F150 -> 174018.45 | E9: =Forecast!G150 -> 176308.3 | F9: =Forecast!H150 -> 179885.12 | G9: =Forecast!I150 -> 185999.38
A10: Total activos al cierre | B10: =Forecast!D153 -> 8230928.7 | C10: =Forecast!E153 -> 8767723.9 | D10: =Forecast!F153 -> 9209694 | E10: =Forecast!G153 -> 9502564.1 | F10: =Forecast!H153 -> 9802581.1 | G10: =Forecast!I153 -> 10113052
A11: Otros resultados integrales atribuibles (conversión, coberturas) | B11: 0 | C11: 0 | D11: 0 | E11: 0 | F11: 0 | G11: 0
A13: Regla de proyección de la revalorización [S, a decidir con valuation]: con tasas de descuento constantes, la PI crece por indexación + capex; la revalorización = PI inicial × inflación de largo plazo, neta de impuesto diferido. Cualquier compresión de tasas debe ser explícita y consistente con el escenario del DCF.
A14: Patrimonio proyectado: E1 lo calcula por roll-forward = patrimonio previo + utilidad reportada − payout × utilidad distribuible + ORI.

Sheet FCFF_DCF
A1: FCFF y DCF — interfaz forecast (supuestos de financial analysis) ↔ valuation (WACC, g, cap rate de salida)
A2: Fecha de valorización: 30-06-2026 (coincide con la última DFN y minoritarios reportados). Para llevar a la fecha de corte (D1), capitalizar el patrimonio al costo del patrimonio y restar dividendos pagados en el intermedio.
A3: Amarillo = inputs que entrega valuation. Flujos en CLP nominales → la WACC debe ser nominal en CLP. Celdas vacías dejan el bloque de resultado en blanco; la grilla de sensibilidad funciona sin inputs.
A5: A. Inputs de valuation
A6: WACC nominal CLP | J6: Valuation [S]. Debe ser nominal en CLP (BCP + ERP + riesgo país ponderado), consistente con flujos en CLP
A7: Crecimiento terminal nominal (g) | J7: Valuation [S]. Referencia: inflación LP Chile 3,0% + crecimiento real 0%–1% (Nota 11)
A8: Retorno sobre nueva inversión en perpetuidad (RONIC) | J8: [S] Si se deja vacío = WACC (el crecimiento terminal no crea valor; supuesto neutral)
A9: Cap rate de salida (sobre EBITDA 2032E) | J9: Valuation [S]. Referencias: Gran Plaza 9,4% (2026); WACC real Nota 11 Chile ~5,5%
A10: RONIC usado | C10: =IF(C8="",C6,C8) -> 0
A11: DFN 30-06-2026 (definición compañía) | C11: =Inputs!C64 -> 1285740 | J11: [R] Release 2T26 / Análisis Razonado 1S26
A12: Participaciones no controladoras (libro) 30-06-2026 | C12: 50841 | J12: [R] Release 2T26, estado de situación. Libro como proxy del valor de mercado [S]
A13: Acciones (MM) | C13: =Inputs!C125 -> 2190
A14: Precio de referencia (CLP) | C14: 3642 | J14: [R] Bloomberg DES, impresión 27-09-2026. Reemplazar por el precio de la fecha de corte (D1)
A15: EBITDA 1S26 real (para aislar el 2S26) | C15: 270573 | J15: [R] Release 2T26
A17: B. Flujo de caja libre de la firma (MM CLP) | C17: 2S26E | D17: 2027E | E17: 2028E | F17: 2029E | G17: 2030E | H17: 2031E | J17: Fuente / supuesto
A18: EBITDA | C18: =Forecast!D104-$C$15 -> 290742.41 | D18: =Forecast!E104 -> 611360.36 | E18: =Forecast!F104 -> 659160.32 | F18: =Forecast!G104 -> 704684.52 | G18: =Forecast!H104 -> 736419.6 | H18: =Forecast!I104 -> 765088.08 | J18: 2S26E = EBITDA 2026E (Forecast) − 1S26 real
A19: Impuesto operativo en caja (tasa del forecast × EBITDA) | C19: =-Forecast!D110*C18 -> -48844.724 | D19: =-Forecast!E110*D18 -> -116158.47 | E19: =-Forecast!F110*E18 -> -141719.47 | F19: =-Forecast!G110*F18 -> -169124.28 | G19: =-Forecast!H110*G18 -> -198833.29 | H19: =-Forecast!I110*H18 -> -206573.78 | J19: Misma tasa de impuesto en caja del forecast, aplicada sin escudo de intereses (flujo desapalancado) [S]
A20: Capex total | C20: =-(Forecast!D137+Forecast!D139) -> -149905.97 | D20: =-Forecast!E142 -> -290119.34 | E20: =-Forecast!F142 -> -200864.13 | F20: =-Forecast!G142 -> -48591.535 | G20: =-Forecast!H142 -> -50782.702 | H20: =-Forecast!I142 -> -52765.562 | J20: 2S26E = capex de proyectos + mantención del 2S26 (Forecast). Sin greenfield ni capex de crecimiento post-2028 (ver anexo)
A21: Variación de capital de trabajo | C21: 0 | D21: 0 | E21: 0 | F21: 0 | G21: 0 | H21: 0 | J21: Δ capital de trabajo = 0 [S], declarado en el anexo
A22: FCFF | C22: =SUM(C18:C21) -> 91991.708 | D22: =SUM(D18:D21) -> 205082.55 | E22: =SUM(E18:E21) -> 316576.72 | F22: =SUM(F18:F21) -> 486968.7 | G22: =SUM(G18:G21) -> 486803.6 | H22: =SUM(H18:H21) -> 505748.74
A23: Período de descuento (años, mitad de período) | C23: 0.25 | D23: 1 | E23: 2 | F23: 3 | G23: 4 | H23: 5 | J23: Mitad de período: 2S26 a 0,25 años; luego mitad de cada año desde el 30-06-2026
A24: Factor de descuento | C24: =IF($C$6="","",1/(1+$C$6)^C23) | D24: =IF($C$6="","",1/(1+$C$6)^D23) | E24: =IF($C$6="","",1/(1+$C$6)^E23) | F24: =IF($C$6="","",1/(1+$C$6)^F23) | G24: =IF($C$6="","",1/(1+$C$6)^G23) | H24: =IF($C$6="","",1/(1+$C$6)^H23)
A25: Valor presente del FCFF | C25: =IF($C$6="","",C22*C24) | D25: =IF($C$6="","",D22*D24) | E25: =IF($C$6="","",E22*E24) | F25: =IF($C$6="","",F22*F24) | G25: =IF($C$6="","",G22*G24) | H25: =IF($C$6="","",H22*H24)
A27: C. Valor terminal y valor por acción | C27: Gordon | D27: Cap rate salida
A28: NOPAT 2032E = EBITDA 2031E × (1+g) × (1 − tasa 2031E) | C28: =IF($C$7="","",H18*(1+$C$7)*(1-Forecast!I110)) | J28: EBITDA ≈ EBIT (D&A 2025: 3.610) → NOPAT ≈ EBITDA × (1 − t). Tasa terminal = 27%
A29: Tasa de reinversión terminal = (g − IPC LP Chile) / RONIC | C29: =IF(OR($C$6="",$C$7=""),"",MAX(0,$C$7-Forecast!$I$6)/$C$10) | J29: Value driver: VT = NOPAT × (1 − reinversión) / (WACC − g). Solo el crecimiento REAL exige reinversión: la parte de inflación llega por la indexación de los contratos (UF/IPC) sin capex. Corrige que el forecast no tenga reinversión post-2028
A30: Valor terminal al 31-12-2031 | C30: =IF(OR($C$6="",$C$7=""),"",C28*(1-C29)/($C$6-$C$7)) | D30: =IF(OR($C$7="",$C$9=""),"",H18*(1+$C$7)/$C$9) | J30: Gordon: perpetuidad con reinversión explícita. Cap rate: EBITDA 2032E / cap rate (EBITDA incluye gastos corporativos → conservador vs NOI)
A31: Valor presente del valor terminal (5,5 años) | C31: =IF(OR($C$6="",C30=""),"",C30/(1+$C$6)^5.5) | D31: =IF(OR($C$6="",D30=""),"",D30/(1+$C$6)^5.5)
A32: Valor presente FCFF explícito | C32: =IF($C$6="","",SUM($C$25:$H$25)) | D32: =IF($C$6="","",SUM($C$25:$H$25))
A33: Valor empresa | C33: =IF(C31="","",C31+C32) | D33: =IF(D31="","",D31+D32)
A34: − DFN | C34: =IF(C33="","",-$C$11) | D34: =IF(D33="","",-$C$11)
A35: − Minoritarios | C35: =IF(C33="","",-$C$12) | D35: =IF(D33="","",-$C$12)
A36: Valor del patrimonio | C36: =IF(C33="","",SUM(C33:C35)) | D36: =IF(D33="","",SUM(D33:D35))
A37: Valor por acción (CLP) | C37: =IF(C36="","",C36/$C$13) | D37: =IF(D36="","",D36/$C$13)
A38: Upside vs precio de referencia | C38: =IF(C37="","",C37/$C$14-1) | D38: =IF(D37="","",D37/$C$14-1)
A40: Chequeo: valor terminal / valor empresa | C40: =IF(C33="","",C31/C33) | D40: =IF(D33="","",D31/D33)
A41: Chequeo: EV / EBITDA 2027E implícito | C41: =IF(C33="","",C33/D18) | D41: =IF(D33="","",D33/D18)
A42: Chequeo: cap rate implícito del valor terminal (EBITDA 2032E / VT) | C42: =IF(C30="","",H18*(1+$C$7)/C30)
A43: Chequeo: WACC real implícita = (1+WACC)/(1+IPC LP Chile) − 1 | C43: =IF($C$6="","",(1+$C$6)/(1+Forecast!I6)-1) | J43: Debe estar cerca de la WACC real de la Nota 11 si valuation usa supuestos de mercado similares a la compañía; una diferencia grande debe explicarse
A44: Referencia: WACC real Nota 11 Chile jun-26 (punto medio) | C44: =E7_WACC!G24 -> 0.0555
...

Sheet DCF_Valuation
B1: DCF de FCFF — Mallplaza (Plaza S.A.) · CLP nominales · fecha de valorización 30-06-2026 (2T26)
B2: Leyenda: azul con fondo celeste = dato observado [R] · negro = calculado [C] · fondo amarillo = supuesto [S] · fondo verde = proyección [P] (viene de la hoja Forecast) · verde = vínculo a otra hoja
B3: Unidad: MM CLP salvo indicación. Fuentes: EEFF dic-23 (reformulado), releases 4T24 y 2T26, Inputs, Forecast; WACC del modelo de valuation (Mall_plaza_Valuacion.xlsm, hoja FFCF).
B5: Ítem | C5: Tipo | D5: 2022A | E5: 2023A | F5: 2024A | G5: 2025A | H5: LTM 2T26 | I5: 1S26A | J5: 2S26E | K5: 2027E | L5: 2028E | M5: 2029E | N5: 2030E | O5: 2031E | P5: Fuente / cálculo
B7: II–IV. Ingresos y construcción del EBITDA ajustado
A8: 1 | B8: Ingresos ordinarios | C8: R / P | D8: 370899 | E8: =Inputs!C4 -> 419904 | F8: =Inputs!C5 -> 494605 | G8: =Inputs!C6 -> 653911 | H8: =Inputs!C82 -> 677333 | I8: =Inputs!C8 -> 339530 | J8: =Forecast!D95-I8 -> 364468.94 | K8: =Forecast!E95 -> 767179.42 | L8: =Forecast!F95 -> 826661.82 | M8: =Forecast!G95 -> 883482.45 | N8: =Forecast!H95 -> 923321.86 | O8: =Forecast!I95 -> 959373.85 | P8: 2022 reformulado (EEFF dic-23, EERR). 2023–1S26: EEFF y releases (Inputs). 2S26E = 2026E (Forecast) − 1S26 real
A9: 2 | B9: Crecimiento de ingresos | C9: C | E9: =E8/D8-1 -> 0.13212492 | F9: =F8/E8-1 -> 0.17790019 | G9: =G8/F8-1 -> 0.32208732 | K9: =K8/(I8+J8)-1 -> 0.089745147 | L9: =L8/K8-1 -> 0.077533882 | M9: =M8/L8-1 -> 0.068735037 | N9: =N8/M8-1 -> 0.045093604 | O9: =O8/N8-1 -> 0.039045966 | P9: 2024: incluye 1 mes de Perú; 2025: 12 meses (perímetro). 2027E vs 2026E completo
A10: 3a | B10: Resultado operacional (Ganancias de actividades operacionales) | C10: R / C | D10: 363621 | E10: 513768 | F10: =F15-F11+F13-F14 -> 535873 | G10: =G15-G11+G13-G14 -> 1968050 | H10: =G10-720093+I10 -> 1730612 | I10: 482655 | P10: 2022–2023: EERR EEFF dic-23 (reformulado). 1S26 y 1S25 (720.093): release 2T26. 2024–2025 reconstruido desde EBITDA, D&A y otros ingresos/gastos [C]
A11: 3b | B11: (+) Depreciación y amortización | C11: R / C / S | D11: =Inputs!C77-(324954-44420) -> 2165 | E11: 2154 | F11: 2112 | G11: =Inputs!C17 -> 3610 | H11: =G11-1837+I11 -> 4766 | I11: 2993 | J11: =$H$18*J8 -> 2564.5568 | K11: =$H$18*K8 -> 5398.1972 | L11: =$H$18*L8 -> 5816.7404 | M11: =$H$18*M8 -> 6216.5543 | N11: =$H$18*N8 -> 6496.8811 | O11: =$H$18*O8 -> 6750.5581 | P11: 2022 implícita (EBITDA − ganancia bruta + GAV). 2023–2024: release 4T24. 1S26: release 2T26 (1.382 + 1.611). Proyección: D&A/ingresos LTM [S]
A12: 3 | B12: EBITDA contable (incluye revalorización de PI) | C12: C | D12: =D10+D11 -> 365786 | E12: =E10+E11 -> 515922 | F12: =F10+F11 -> 537985 | G12: =G10+G11 -> 1971660 | H12: =H10+H11 -> 1735378 | I12: =I10+I11 -> 485648 | J12: =J15+J13-J14 -> 433146.13 | K12: =K15+K13-K14 -> 858036.25 | L12: =L15+L13-L14 -> 900266.25 | M12: =M15+M13-M14 -> 948963.08 | N12: =N15+N13-N14 -> 985653.91 | O12: =O15+O13-O14 -> 1022793.8 | P12: Resultado operacional + D&A. Es el "EBITDA" que entregan algunas bases de datos (trampa 1 del WP: campo EBITDA de Bloomberg)
A13: 4a | B13: (−) Otros ingresos por función (revalorización de PI a valor razonable) | C13: R / P | D13: 85361 | E13: 195562 | F13: 162507 | G13: =Inputs!C15 -> 1448943 | H13: =G13-471020+I13 -> 1194529 | I13: 216606 | J13: =Forecast!D148-I13 -> 142404.73 | K13: =Forecast!E148 -> 246675.89 | L13: =Forecast!F148 -> 241105.93 | M13: =Forecast!G148 -> 244278.56 | N13: =Forecast!H148 -> 249234.32 | O13: =Forecast!I148 -> 257705.75 | P13: Valor razonable: 2022 79.489, 2025 1.447.136 (Inputs); el resto son ingresos menores no recurrentes. 1S25: 471.020 (release 2T26). Proyección: regla de Forecast
A14: 4b | B14: (+) Otros gastos por función (no recurrentes) | C14: R / S | D14: 2274 | E14: 1825 | F14: 5159 | G14: =Inputs!C16 -> 3511 | H14: =G14-957+I14 -> 4086 | I14: 1532 | J14: 0 | K14: 0 | L14: 0 | M14: 0 | N14: 0 | O14: 0 | P14: Release 4T24 / 2T26; proyección 0 [S]
A15: 5 | B15: EBITDA ajustado (= EBITDA definición compañía) | C15: C / P | D15: =D12-D13+D14 -> 282699 | E15: =E12-E13+E14 -> 322185 | F15: =Inputs!C9 -> 380637 | G15: =Inputs!C10 -> 526228 | H15: =H12-H13+H14 -> 544935 | I15: =I12-I13+I14 -> 270574 | J15: =Forecast!D104-I15 -> 290741.41 | K15: =Forecast!E104 -> 611360.36 | L15: =Forecast!F104 -> 659160.32 | M15: =Forecast!G104 -> 704684.52 | N15: =Forecast!H104 -> 736419.6 | O15: =Forecast!I104 -> 765088.08 | P15: EBITDA que entra al DCF: excluye la revalorización (no caja). 2S26E = 2026E − 1S26
A16: 5b | B16: Control: EBITDA ajustado − EBITDA reportado por la compañía | C16: C | D16: =D15-Inputs!C77 -> 0 | E16: =E15-Inputs!C78 -> 0 | F16: =F12-F13+F14-Inputs!C9 -> 0 | G16: =G12-G13+G14-Inputs!C10 -> 0 | H16: =H15-Inputs!C79 -> 0 | I16: =I15-270573 -> 1 | P16: Debe ser 0 (±1 por redondeo): el ajuste reproduce exactamente el EBITDA que publica la compañía
A17: 5c | B17: Margen EBITDA ajustado | C17: C | D17: =D15/D8 -> 0.76219941 | E17: =E15/E8 -> 0.76728252 | F17: =F15/F8 -> 0.76957774 | G17: =G15/G8 -> 0.80473948 | H17: =H15/H8 -> 0.80453042 | I17: =I15/I8 -> 0.79690749 | J17: =J15/J8 -> 0.79771244 | K17: =K15/K8 -> 0.79689358 | ... O17: =O15/O8 -> 0.7974869
A18: 6 | B18: D&A / ingresos | C18: C | H18: =H11/H8 -> 0.0070364208 | P18: Se usa para proyectar D&A [S]
A19: 7 | B19: EBIT (EBITDA ajustado − D&A) | C19: C | D19: =D15-D11 -> 280534 | E19: =E15-E11 -> 320031 | F19: =F15-F11 -> 378525 | G19: =G15-G11 -> 522618 | H19: =H15-H11 -> 540169 | I19: =I15-I11 -> 267581 | J19: =J15-J11 -> 288176.85 | K19: =K15-K11 -> 605962.16 | ... O19: =O15-O11 -> 758337.52
B21: V. Construcción del FCFF (2S26E–2031E)
A22: 8a | B22: Tasa de impuesto operacional | C22: S / P | J22: =Forecast!D110 -> 0.168 | K22: =Forecast!E110 -> 0.19 | L22: =Forecast!F110 -> 0.215 | M22: =Forecast!G110 -> 0.24 | N22: =Forecast!H110 -> 0.27 | O22: =Forecast!I110 -> 0.27 | P22: Trayectoria de impuesto en caja del forecast (16,8% → 27%) [S]. Alternativa: tasa legal ponderada 28,22% (FFCF!J37 del modelo de valuation)
A23: 8 | B23: (−) Impuestos operacionales sobre EBIT | C23: C | J23: =-J22*J19 -> -48413.711 | K23: =-K22*K19 -> -115132.81 | L23: =-L22*L19 -> -140468.87 | M23: =-M22*M19 -> -167632.31 | N23: =-N22*N19 -> -197079.13 | O23: =-O22*O19 -> -204751.13 | P23: Sobre EBIT, sin escudo de intereses (flujo desapalancado)
A24: 9 | B24: NOPAT | C24: C | J24: =J19+J23 -> 239763.14 | K24: =K19+K23 -> 490829.35 | L24: =L19+L23 -> 512874.71 | M24: =M19+M23 -> 530835.65 | N24: =N19+N23 -> 532843.58 | O24: =O19+O23 -> 553586.39
A25: 10 | B25: (+) D&A | C25: C | J25: =J11 -> 2564.5568 | K25: =K11 -> 5398.1972 | L25: =L11 -> 5816.7404 | M25: =M11 -> 6216.5543 | N25: =N11 -> 6496.8811 | O25: =O11 -> 6750.5581
A26: 11 | B26: (−) Capex | C26: P | J26: =-(Forecast!D137+Forecast!D139) -> -149905.97 | K26: =-Forecast!E142 -> -290119.34 | L26: =-Forecast!F142 -> -200864.13 | M26: =-Forecast!G142 -> -48591.535 | N26: =-Forecast!H142 -> -50782.702 | O26: =-Forecast!I142 -> -52765.562 | P26: Proyectos remanentes (release 2T26) + mantención/TI 5,5% de ingresos. 2S26E excluye el capex real del 1S26 (ya pagado antes de la fecha de valorización). Sin greenfield ni Gran Plaza
A27: 12 | B27: (−/+) Variación de capital de trabajo | C27: S | J27: 0 | K27: 0 | L27: 0 | M27: 0 | N27: 0 | O27: 0 | P27: ΔNWC = 0 [S], declarado en el anexo
A28: 13 | B28: FCFF | C28: C | J28: =J24+J25+J26-J27 -> 92421.722 | K28: =K24+K25+K26-K27 -> 206108.21 | L28: =L24+L25+L26-L27 -> 317827.32 | M28: =M24+M25+M26-M27 -> 488460.67 | N28: =N24+N25+N26-N27 -> 488557.76 | O28: =O24+O25+O26-O27 -> 507571.39 | P28: NOPAT + D&A − capex − ΔNWC
B30: VI–VIII. Descuento
A31: 14 | B31: WACC nominal CLP (modelo de valuation) | C31: S | J31: 0.1003 | P31: FFCF!B120 = 10,03% (Mall_plaza_Valuacion.xlsm). Se respeta; ver auditoría abajo antes de usarla como definitiva
A32: 15a | B32: Período de descuento (años desde 30-06-2026, mitad de período) | C32: S | J32: 0.25 | K32: 1 | L32: 2 | M32: 3 | N32: 4 | O32: 5 | P32: Convención de mitad de período
A33: 15 | B33: Factor de descuento | C33: C | J33: =1/(1+$J$31)^J32 -> 0.97638752 | K33: =1/(1+$J$31)^K32 -> 0.90884304 | L33: =1/(1+$J$31)^L32 -> 0.82599568 | M33: =1/(1+$J$31)^M32 -> 0.75070042 | N33: =1/(1+$J$31)^N32 -> 0.68226886 | O33: =1/(1+$J$31)^O32 -> 0.6200753 | P33: 1 / (1 + WACC)^t
A34: 16 | B34: Valor presente del FCFF | C34: C | J34: =J28*J33 -> 90239.416 | K34: =K28*K33 -> 187320.01 | L34: =L28*L33 -> 262523.99 | M34: =M28*M33 -> 366687.63 | N34: =N28*N33 -> 333327.75 | O34: =O28*O33 -> 314732.48
B36: VII. Valor terminal (Gordon)
A37: 17a | B37: Crecimiento perpetuo nominal (g) | C37: S | J37: 0.03 | P37: [S] = meta de inflación BCCh (3%): crecimiento real 0% a perpetuidad, coherente con un FCFF terminal sin capex de crecimiento. Rango Nota 11: 0,1%–1,1% real
A38: 17b | B38: FCFF 2032E = FCFF 2031E × (1 + g) | C38: C | J38: =O28*(1+J37) -> 522798.53
A39: 17 | B39: Valor terminal al 31-12-2031 = FCFF 2032E / (WACC − g) | C39: C | J39: =J38/(J31-J37) -> 7436679
A40: 18 | B40: Valor presente del VT = VT / (1 + WACC)^5,5 | C40: C | J40: =J39/(1+J31)^5.5 -> 4396103.5
B42: IX. Enterprise Value → Equity Value
A43: 19a | B43: Suma VP FCFF explícito | C43: C | J43: =SUM(J34:O34) -> 1554831.3
A44: 19 | B44: Enterprise Value | C44: C | J44: =J43+J40 -> 5950934.8
A45: 20a | B45: (−) Deuda financiera neta 30-06-2026 | C45: R | J45: =-Inputs!C64 -> -1285740 | P45: Release 2T26 / Análisis Razonado 1S26 (1.285.740)
A46: 20b | B46: (−) Participaciones no controladoras (libro) 30-06-2026 | C46: R | J46: -50841 | P46: Release 2T26, estado de situación. Libro como proxy [S]
...

Sheet Peers_inputs
A1: Peers — Bloomberg FA, datos declarados (ARD), MM CLP. Export 28-09-2026 (WP §85)
A2: Azul = dato [R] de Bloomberg (verificar contra EEFF CMF 2025); negro = cálculo [C]. Método de revalorización distinto por par (ver notas). Validación: ROE reportado = §56 en los 8 años.
A4: Parque Arauco (PARAUCO CI) | B4: 2021 | C4: 2022 | D4: 2023 | E4: 2024 | F4: 2025 | G4: Campo Bloomberg
A5: Ingresos | C5: 243119.54 | D5: 264312.61 | E5: 316775.71 | F5: 383792.58 | G5: ARD_REVENUES
A6: EBITDA (definición compañía) | C6: 170697 | D6: 188159 | E6: 227727 | F6: 272233 | G6: ARD_REF_EBITDA_IS
A7: Resultado operacional | C7: 271632.11 | D7: 228661.96 | E7: 271106.29 | F7: 328348.13 | G7: ARD_OPERATING_INCOME
A8: D&A | C8: 5128.377 | D8: 5280.937 | E8: 6518.906 | F8: 4739.59 | G8: ARDR_DEPRECIATION_AMORTIZATION
A9: Utilidad atribuible | C9: 101031.63 | D9: 112345.33 | E9: 120571.31 | F9: 149972.7 | G9: ARD_NET_INC
A10: Utilidad antes de minoritarios | C10: 137551.97 | D10: 129114.89 | E10: 149541.58 | F10: 213796.3 | G10: ARD_PROF_AFTER_TAX_BEF_MINORITY
A11: Propiedades de inversión | B11: 2183835.8 | C11: 2341871.5 | D11: 2750846.3 | E11: 3042457 | F11: 3606680.8 | G11: ARD_TOTAL_PROPERTY_INVESTMENTS (excluye negocios conjuntos)
A12: Patrimonio atribuible | B12: 1077424.5 | C12: 1144928.9 | D12: 1298911.3 | E12: 1464457.7 | F12: 1594521.9 | G12: ARD_TOT_SHARE_EQY_EXCL_MINORITY
A13: Préstamos corto plazo | C13: 116991.74 | D13: 167120.27 | E13: 187477.08 | F13: 153323.03 | G13: ARD_ST_BORROW
A14: Deuda largo plazo | C14: 1034638.3 | D14: 1183607.7 | E14: 1394283 | F14: 1547183.9 | G14: ARD_LT_DEBT
A15: Efectivo y equivalentes | C15: 243042.95 | D15: 319187 | E15: 387091.46 | F15: 153099.71 | G15: ARD_CASH_AND_EQUIVALENTS
A16: Activos totales | C16: 2938210.6 | D16: 3482971.1 | E16: 3930479.5 | F16: 4284682.6 | G16: ARD_TOT_ASSETS
A18: Cencosud Shopping (CENCOMAL CI) | B18: 2021 | C18: 2022 | D18: 2023 | E18: 2024 | F18: 2025 | G18: Campo Bloomberg
A19: Ingresos | C19: 286949.85 | D19: 314784.93 | E19: 353183.7 | F19: 377940.6 | G19: ARD_REVENUES
A20: Margen EBITDA ajustado | C20: 0.9 | D20: 0.9 | E20: 0.908 | F20: 0.901 | G20: ARDR_ADJUSTED_EBITDA_MARGIN (no hay ARD_REF_EBITDA_IS en el export)
A21: Otro (ingreso)/gasto operacional neto (negativo = ganancia) | C21: -29523.565 | D21: 10515.477 | E21: -66670.135 | F21: -96648.526 | G21: ARD_OTH_OPERATING_INC_EXP_NET
A22: Utilidad atribuible | C22: 181875.55 | D22: 187329.71 | E22: 266953.08 | F22: 303966.19 | G22: ARD_NET_INC
A23: Propiedades de inversión | B23: 3794629.2 | C23: 3871649.1 | D23: 3955476.3 | E23: 4122201.8 | F23: 4395015.5 | G23: ARD_TOTAL_PROPERTY_INVESTMENTS
A24: Patrimonio atribuible | B24: 2663057.7 | C24: 2679608.6 | D24: 2744754.9 | E24: 2828031.7 | F24: 2989170.6 | G24: ARD_TOT_SHARE_EQY_EXCL_MINORITY
A25: Préstamos corto plazo | C25: 3415.014 | D25: 3704.413 | E25: 2545.265 | F25: 2632.142 | G25: ARD_ST_BORROW
A26: Deuda largo plazo | C26: 671134.62 | D26: 702753.14 | E26: 734811.85 | F26: 759521.59 | G26: ARD_LT_DEBT
A27: Efectivo y equivalentes | C27: 46100.451 | D27: 52508.911 | E27: 115011.66 | F27: 44347.593 | G27: ARD_CASH_AND_EQUIVALENTS
A28: Activos totales | C28: 4059976.2 | D28: 4147695.6 | E28: 4291155.7 | F28: 4501457.1 | G28: ARD_TOT_ASSETS
A30: Tasa de impuesto para normalizar [S] (legal Chile) | B30: 0.27
A32: Cálculos [C] | C32: 2022 | D32: 2023 | E32: 2024 | F32: 2025
A33: PA — Margen EBITDA | C33: =C6/C5 -> 0.70211139 | D33: =D6/D5 -> 0.71188053 | E33: =E6/E5 -> 0.71889034 | F33: =F6/F5 -> 0.70932325
A34: PA — Revalorización (residuo: res. operacional − (EBITDA − D&A)) | C34: =C7-(C6-C8) -> 106063.49 | D34: =D7-(D6-D8) -> 45783.893 | E34: =E7-(E6-E8) -> 49898.193 | F34: =F7-(F6-F8) -> 60854.721
A35: PA — % atribuible a la controladora (utilidad) | C35: =C9/C10 -> 0.7344979 | D35: =D9/D10 -> 0.87011914 | E35: =E9/E10 -> 0.8062728 | F35: =F9/F10 -> 0.70147472
A36: PA — Utilidad atribuible normalizada | C36: =C9-C34*(1-$B$30)*C35 -> 44162.148 | D36: =D9-D34*(1-$B$30)*D35 -> 83264.002 | E36: =E9-E34*(1-$B$30)*E35 -> 91202.272 | F36: =F9-F34*(1-$B$30)*F35 -> 118810.43
A37: PA — Patrimonio atribuible promedio | C37: =(B12+C12)/2 -> 1111176.7 | D37: =(C12+D12)/2 -> 1221920.1 | E37: =(D12+E12)/2 -> 1381684.5 | F37: =(E12+F12)/2 -> 1529489.8
A38: PA — ROE reportado | C38: =C9/C37 -> 0.090923105 | D38: =D9/D37 -> 0.091941638 | E38: =E9/E37 -> 0.087263993 | F38: =F9/F37 -> 0.098054072
A39: PA — ROE normalizado | C39: =C36/C37 -> 0.039743587 | D39: =D36/D37 -> 0.068141937 | E39: =E36/E37 -> 0.066008029 | F39: =F36/F37 -> 0.077679777
A40: PA — Revalorización / PI de apertura | C40: =C34/B11 -> 0.048567519 | D40: =D34/C11 -> 0.01955013 | E40: =E34/D11 -> 0.018139215 | F40: =F34/E11 -> 0.020001834
A41: PA — EBITDA / PI de cierre | C41: =C6/C11 -> 0.072889139 | D41: =D6/D11 -> 0.068400406 | E41: =E6/E11 -> 0.074849702 | F41: =F6/F11 -> 0.075480203
A42: PA — LTV (deuda neta / PI) | C42: =(C13+C14-C15)/C11 -> 0.38797476 | D42: =(D13+D14-D15)/D11 -> 0.37499042 | E42: =(E13+E14-E15)/E11 -> 0.39266572 | F42: =(F13+F14-F15)/F11 -> 0.42903913
A43: PA — Deuda neta / EBITDA | C43: =(C13+C14-C15)/C6 -> 5.3228063 | D43: =(D13+D14-D15)/D6 -> 5.4822835 | E43: =(E13+E14-E15)/E6 -> 5.2460559 | F43: =(F13+F14-F15)/F6 -> 5.684128
A44: PA — Activos / patrimonio atribuible | C44: =C16/C12 -> 2.5662823 | D44: =D16/D12 -> 2.6814542 | E44: =E16/E12 -> 2.6839146 | F44: =F16/F12 -> 2.6871269
...

Sheet E1_DuPont
A1: Exhibit 1 — Operating record and DuPont: 2019A–2031E
A2: Bloque A (indiferente al régimen contable): 2019A–2025A + LTM. Bloque B (balance a valor razonable): 2022A en adelante; 2019–2021 no comparables (modelo del costo, WP §3). Proyecciones: hoja Forecast_link.
A4: A. Operating record (MM CLP) | B4: 2019A | C4: 2020A | D4: 2021A | E4: 2022A | F4: 2023A | G4: 2024A | H4: 2025A | I4: LTM 2T26 | J4: 2026E | K4: 2027E | L4: 2028E | M4: 2029E | N4: 2030E | O4: 2031E
A5: Ingresos | B5: =IF(Inputs!$C$90="","",Inputs!$C$90) | C5: =IF(Inputs!$C$91="","",Inputs!$C$91) | D5: =IF(Inputs!$C$80="","",Inputs!$C$80) -> 276695 | E5: =IF(Inputs!$C$81="","",Inputs!$C$81) -> 370899 | F5: =IF(Inputs!$C$4="","",Inputs!$C$4) -> 419904 | G5: =IF(Inputs!$C$5="","",Inputs!$C$5) -> 494605 | H5: =IF(Inputs!$C$6="","",Inputs!$C$6) -> 653911 | I5: =IF(Inputs!$C$82="","",Inputs!$C$82) -> 677333 | J5: =IF(Forecast_link!B5="","",Forecast_link!B5) -> 703998.94 | K5: =IF(Forecast_link!C5="","",Forecast_link!C5) -> 767179.42 | L5: =IF(Forecast_link!D5="","",Forecast_link!D5) -> 826661.82 | M5: =IF(Forecast_link!E5="","",Forecast_link!E5) -> 883482.45 | N5: =IF(Forecast_link!F5="","",Forecast_link!F5) -> 923321.86 | O5: =IF(Forecast_link!G5="","",Forecast_link!G5) -> 959373.85
A6: EBITDA | B6: =IF(Inputs!$C$92="","",Inputs!$C$92) | C6: =IF(Inputs!$C$75="","",Inputs!$C$75) -> 116114 | D6: =IF(Inputs!$C$76="","",Inputs!$C$76) -> 208621 | E6: =IF(Inputs!$C$77="","",Inputs!$C$77) -> 282699 | F6: =IF(Inputs!$C$78="","",Inputs!$C$78) -> 322185 | G6: =IF(Inputs!$C$9="","",Inputs!$C$9) -> 380637 | H6: =IF(Inputs!$C$10="","",Inputs!$C$10) -> 526228 | I6: =IF(Inputs!$C$79="","",Inputs!$C$79) -> 544935 | J6: =IF(Forecast_link!B6="","",Forecast_link!B6) -> 561315.41 | K6: =IF(Forecast_link!C6="","",Forecast_link!C6) -> 611360.36 | L6: =IF(Forecast_link!D6="","",Forecast_link!D6) -> 659160.32 | M6: =IF(Forecast_link!E6="","",Forecast_link!E6) -> 704684.52 | N6: =IF(Forecast_link!F6="","",Forecast_link!F6) -> 736419.6 | O6: =IF(Forecast_link!G6="","",Forecast_link!G6) -> 765088.08
A7: Crecimiento de ingresos | C7: =IF(OR(C5="",B5=""),"",C5/B5-1) | D7: =IF(OR(D5="",C5=""),"",D5/C5-1) | E7: =IF(OR(E5="",D5=""),"",E5/D5-1) -> 0.34046152 | F7: =IF(OR(F5="",E5=""),"",F5/E5-1) -> 0.13212492 | G7: =IF(OR(G5="",F5=""),"",G5/F5-1) -> 0.17790019 | H7: =IF(OR(H5="",G5=""),"",H5/G5-1) -> 0.32208732 | J7: =IF(OR(J5="",H5=""),"",J5/H5-1) -> 0.07659748 | K7: =IF(OR(K5="",J5=""),"",K5/J5-1) -> 0.089745147 | L7: =IF(OR(L5="",K5=""),"",L5/K5-1) -> 0.077533882 | M7: =IF(OR(M5="",L5=""),"",M5/L5-1) -> 0.068735037 | N7: =IF(OR(N5="",M5=""),"",N5/M5-1) -> 0.045093604 | O7: =IF(OR(O5="",N5=""),"",O5/N5-1) -> 0.039045966
A8: Margen EBITDA | B8: =IF(OR(B5="",B6=""),"",B6/B5) | C8: =IF(OR(C5="",C6=""),"",C6/C5) | D8: =IF(OR(D5="",D6=""),"",D6/D5) -> 0.75397459 | E8: =IF(OR(E5="",E6=""),"",E6/E5) -> 0.76219941 | F8: =IF(OR(F5="",F6=""),"",F6/F5) -> 0.76728252 | G8: =IF(OR(G5="",G6=""),"",G6/G5) -> 0.76957774 | H8: =IF(OR(H5="",H6=""),"",H6/H5) -> 0.80473948 | I8: =IF(OR(I5="",I6=""),"",I6/I5) -> 0.80453042 | ... O8: =IF(OR(O5="",O6=""),"",O6/O5) -> 0.7974869
A9: FFO atribuible | E9: =IF(Inputs!$C$83="","",Inputs!$C$83) -> 218931 | F9: =IF(Inputs!$C$84="","",Inputs!$C$84) -> 257227 | G9: =IF(Inputs!$C$85="","",Inputs!$C$85) -> 303195 | H9: =IF(Inputs!$C$20="","",Inputs!$C$20) -> 405300 | I9: =IF(Inputs!$C$86="","",Inputs!$C$86) -> 419907 | J9: =IF(Forecast_link!B7="","",Forecast_link!B7) -> 428521.01 | K9: =IF(Forecast_link!C7="","",Forecast_link!C7) -> 457343.87 | L9: =IF(Forecast_link!D7="","",Forecast_link!D7) -> 479815.31 | M9: =IF(Forecast_link!E7="","",Forecast_link!E7) -> 500558.62 | N9: =IF(Forecast_link!F7="","",Forecast_link!F7) -> 509123.66 | O9: =IF(Forecast_link!G7="","",Forecast_link!G7) -> 535305.59
A10: Margen FFO | E10: =IF(OR(E5="",E9=""),"",E9/E5) -> 0.59027121 | F10: =IF(OR(F5="",F9=""),"",F9/F5) -> 0.61258526 | G10: =IF(OR(G5="",G9=""),"",G9/G5) -> 0.61300432 | H10: =IF(OR(H5="",H9=""),"",H9/H5) -> 0.61980912 | I10: =IF(OR(I5="",I9=""),"",I9/I5) -> 0.61994174 | J10: =IF(OR(J5="",J9=""),"",J9/J5) -> 0.60869554 | K10: =IF(OR(K5="",K9=""),"",K9/K5) -> 0.59613678 | L10: =IF(OR(L5="",L9=""),"",L9/L5) -> 0.58042515 | ... O10: =IF(OR(O5="",O9=""),"",O9/O5) -> 0.55797391
A11: 2022: ingresos EEFF reformulados (370.899); el FFO de la compañía usa 383.864 (base costo) → margen 59,0% vs 57,0% reportado (WP §28).
A13: B. DuPont (fair-value balance sheet) | B13: 2019A | C13: 2020A | D13: 2021A | E13: 2022A | F13: 2023A | G13: 2024A | H13: 2025A | I13: LTM 2T26 | J13: 2026E | K13: 2027E | L13: 2028E | M13: 2029E | N13: 2030E | O13: 2031E
A14: Utilidad atribuible reportada | E14: =IF(Inputs!$C$87="","",Inputs!$C$87) -> 157667 | F14: =IF(Inputs!$C$88="","",Inputs!$C$88) -> 349759 | G14: =IF(Inputs!$C$12="","",Inputs!$C$12) -> 335934 | H14: =IF(Inputs!$C$13="","",Inputs!$C$13) -> 1431012 | J14: =IF(OR(J15="",Forecast_link!B9=""),"",J15+Forecast_link!B9) -> 639155.17 | K14: =IF(OR(K15="",Forecast_link!C9=""),"",K15+Forecast_link!C9) -> 593529.37 | L14: =IF(OR(L15="",Forecast_link!D9=""),"",L15+Forecast_link!D9) -> 614088.92 | M14: =IF(OR(M15="",Forecast_link!E9=""),"",M15+Forecast_link!E9) -> 638982.38 | N14: =IF(OR(N15="",Forecast_link!F9=""),"",N15+Forecast_link!F9) -> 656901.72 | O14: =IF(OR(O15="",Forecast_link!G9=""),"",O15+Forecast_link!G9) -> 695051.41
A15: Utilidad distribuible (normalizada) | E15: =IF(Inputs!$C$97="","",Inputs!$C$97) -> 95856 | F15: =IF(Inputs!$C$89="","",Inputs!$C$89) -> 197540 | G15: =IF(Inputs!$C$21="","",Inputs!$C$21) -> 238305 | H15: =IF(Inputs!$C$22="","",Inputs!$C$22) -> 369312 | J15: =IF(Forecast_link!B8="","",Forecast_link!B8) -> 380038.82 | K15: =IF(Forecast_link!C8="","",Forecast_link!C8) -> 415490.8 | L15: =IF(Forecast_link!D8="","",Forecast_link!D8) -> 440070.47 | M15: =IF(Forecast_link!E8="","",Forecast_link!E8) -> 462674.09 | N15: =IF(Forecast_link!F8="","",Forecast_link!F8) -> 477016.6 | O15: =IF(Forecast_link!G8="","",Forecast_link!G8) -> 509052.03
A16: Total activos al cierre | E16: =IF(Inputs!$C$94="","",Inputs!$C$94) -> 4513943 | F16: =IF(Inputs!$C$23="","",Inputs!$C$23) -> 4796336 | G16: =IF(Inputs!$C$24="","",Inputs!$C$24) -> 5915073 | H16: =IF(Inputs!$C$25="","",Inputs!$C$25) -> 7583643 | J16: =IF(Forecast_link!B10="","",Forecast_link!B10) -> 8230928.7 | K16: =IF(Forecast_link!C10="","",Forecast_link!C10) -> 8767723.9 | L16: =IF(Forecast_link!D10="","",Forecast_link!D10) -> 9209694 | M16: =IF(Forecast_link!E10="","",Forecast_link!E10) -> 9502564.1 | N16: =IF(Forecast_link!F10="","",Forecast_link!F10) -> 9802581.1 | O16: =IF(Forecast_link!G10="","",Forecast_link!G10) -> 10113052
A17: Patrimonio atribuible al cierre | E17: =IF(Inputs!$C$96="","",Inputs!$C$96) -> 2263298 | F17: =IF(Inputs!$C$26="","",Inputs!$C$26) -> 2601053 | G17: =IF(Inputs!$C$27="","",Inputs!$C$27) -> 3157863 | H17: =IF(Inputs!$C$28="","",Inputs!$C$28) -> 4482905 | J17: =IF(OR(H17="",J14=""),"",H17+J14-Inputs!$C$98*J15+N(Forecast_link!B11)) -> 4970044.6 | K17: =IF(OR(J17="",K14=""),"",J17+K14-Inputs!$C$98*K15+N(Forecast_link!C11)) -> 5397377.7 | L17: =IF(OR(K17="",L14=""),"",K17+L14-Inputs!$C$98*L15+N(Forecast_link!D11)) -> 5835438.4 | M17: =IF(OR(L17="",M14=""),"",L17+M14-Inputs!$C$98*M15+N(Forecast_link!E11)) -> 6289351.2 | N17: =IF(OR(M17="",N14=""),"",M17+N14-Inputs!$C$98*N15+N(Forecast_link!F11)) -> 6755446.3 | O17: =IF(OR(N17="",O14=""),"",N17+O14-Inputs!$C$98*O15+N(Forecast_link!G11)) -> 7246876.8
A18: Apertura 2022A (reformulada 01-01-2022) | E18: =IF(Inputs!$C$93="","",Inputs!$C$93) -> 4094996
A19: patrimonio apertura 2022A | E19: =IF(Inputs!$C$95="","",Inputs!$C$95) -> 2167172
A20: Activos promedio | E20: =IF(OR(E16="",E18=""),"",(E16+E18)/2) -> 4304469.5 | F20: =IF(OR(F16="",E16=""),"",(F16+E16)/2) -> 4655139.5 | G20: =IF(OR(G16="",F16=""),"",(G16+F16)/2) -> 5355704.5 | H20: =IF(OR(H16="",G16=""),"",(H16+G16)/2) -> 6749358 | J20: =IF(OR(J16="",H16=""),"",(J16+H16)/2) -> 7907285.9 | K20: =IF(OR(K16="",J16=""),"",(K16+J16)/2) -> 8499326.3 | L20: =IF(OR(L16="",K16=""),"",(L16+K16)/2) -> 8988709 | M20: =IF(OR(M16="",L16=""),"",(M16+L16)/2) -> 9356129 | N20: =IF(OR(N16="",M16=""),"",(N16+M16)/2) -> 9652572.6 | O20: =IF(OR(O16="",N16=""),"",(O16+N16)/2) -> 9957816.8
A21: Patrimonio atribuible promedio | E21: =IF(OR(E17="",E19=""),"",(E17+E19)/2) -> 2215235 | F21: =IF(OR(F17="",E17=""),"",(F17+E17)/2) -> 2432175.5 | G21: =IF(OR(G17="",F17=""),"",(G17+F17)/2) -> 2879458 | H21: =IF(OR(H17="",G17=""),"",(H17+G17)/2) -> 3820384 | J21: =IF(OR(J17="",H17=""),"",(J17+H17)/2) -> 4726474.8 | K21: =IF(OR(K17="",J17=""),"",(K17+J17)/2) -> 5183711.2 | L21: =IF(OR(L17="",K17=""),"",(L17+K17)/2) -> 5616408.1 | M21: =IF(OR(M17="",L17=""),"",(M17+L17)/2) -> 6062394.8 | N21: =IF(OR(N17="",M17=""),"",(N17+M17)/2) -> 6522398.7 | O21: =IF(OR(O17="",N17=""),"",(O17+N17)/2) -> 7001161.6
A23: Margen neto reportado | B23: n.c. | C23: n.c. | D23: n.c. | E23: =IF(OR(E14="",E5="",N(E5)=0),"",E14/E5) -> 0.42509416 | F23: =IF(OR(F14="",F5="",N(F5)=0),"",F14/F5) -> 0.83294991 | G23: =IF(OR(G14="",G5="",N(G5)=0),"",G14/G5) -> 0.67919653 | H23: =IF(OR(H14="",H5="",N(H5)=0),"",H14/H5) -> 2.1883896 | J23: =IF(OR(J14="",J5="",N(J5)=0),"",J14/J5) -> 0.90789224 | K23: =IF(OR(K14="",K5="",N(K5)=0),"",K14/K5) -> 0.77365132 | L23: =IF(OR(L14="",L5="",N(L5)=0),"",L14/L5) -> 0.74285385 | M23: =IF(OR(M14="",M5="",N(M5)=0),"",M14/M5) -> 0.72325419 | N23: =IF(OR(N14="",N5="",N(N5)=0),"",N14/N5) -> 0.71145475 | O23: =IF(OR(O14="",O5="",N(O5)=0),"",O14/O5) -> 0.72448442
A24: Margen neto normalizado | B24: n.c. | C24: n.c. | D24: n.c. | E24: =IF(OR(E15="",E5="",N(E5)=0),"",E15/E5) -> 0.25844233 | F24: =IF(OR(F15="",F5="",N(F5)=0),"",F15/F5) -> 0.47044086 | G24: =IF(OR(G15="",G5="",N(G5)=0),"",G15/G5) -> 0.48180872 | H24: =IF(OR(H15="",H5="",N(H5)=0),"",H15/H5) -> 0.56477411 | J24: =IF(OR(J15="",J5="",N(J5)=0),"",J15/J5) -> 0.53982868 | K24: =IF(OR(K15="",K5="",N(K5)=0),"",K15/K5) -> 0.54158231 | L24: =IF(OR(L15="",L5="",N(L5)=0),"",L15/L5) -> 0.53234643 | M24: =IF(OR(M15="",M5="",N(M5)=0),"",M15/M5) -> 0.52369358 | N24: =IF(OR(N15="",N5="",N(N5)=0),"",N15/N5) -> 0.5166309 | O24: =IF(OR(O15="",O5="",N(O5)=0),"",O15/O5) -> 0.53060861
A25: Rotación de activos | B25: n.c. | C25: n.c. | D25: n.c. | E25: =IF(OR(E5="",E20="",N(E20)=0),"",E5/E20) -> 0.086166019 | F25: =IF(OR(F5="",F20="",N(F20)=0),"",F5/F20) -> 0.090202238 | G25: =IF(OR(G5="",G20="",N(G20)=0),"",G5/G20) -> 0.092351062 | H25: =IF(OR(H5="",H20="",N(H20)=0),"",H5/H20) -> 0.096884919 | J25: =IF(OR(J5="",J20="",N(J20)=0),"",J5/J20) -> 0.089031679 | K25: =IF(OR(K5="",K20="",N(K20)=0),"",K5/K20) -> 0.090263557 | L25: =IF(OR(L5="",L20="",N(L20)=0),"",L5/L20) -> 0.091966691 | M25: =IF(OR(M5="",M20="",N(M20)=0),"",M5/M20) -> 0.094428203 | N25: =IF(OR(N5="",N20="",N(N20)=0),"",N5/N20) -> 0.095655521 | O25: =IF(OR(O5="",O20="",N(O20)=0),"",O5/O20) -> 0.096343795
A26: Apalancamiento (activos / patrimonio) | B26: n.c. | C26: n.c. | D26: n.c. | E26: =IF(OR(E20="",E21="",N(E21)=0),"",E20/E21) -> 1.9431209 | F26: =IF(OR(F20="",F21="",N(F21)=0),"",F20/F21) -> 1.9139817 | G26: =IF(OR(G20="",G21="",N(G21)=0),"",G20/G21) -> 1.8599697 | H26: =IF(OR(H20="",H21="",N(H21)=0),"",H20/H21) -> 1.7666701 | J26: =IF(OR(J20="",J21="",N(J21)=0),"",J20/J21) -> 1.6729775 | K26: =IF(OR(K20="",K21="",N(K21)=0),"",K20/K21) -> 1.6396219 | L26: =IF(OR(L20="",L21="",N(L21)=0),"",L20/L21) -> 1.6004373 | M26: =IF(OR(M20="",M21="",N(M21)=0),"",M20/M21) -> 1.5433058 | N26: =IF(OR(N20="",N21="",N(N21)=0),"",N20/N21) -> 1.4799115 | O26: =IF(OR(O20="",O21="",N(O21)=0),"",O20/O21) -> 1.4223092
A27: ROE reportado | B27: n.c. | C27: n.c. | D27: n.c. | E27: =IF(OR(E14="",E21="",N(E21)=0),"",E14/E21) -> 0.071173939 | F27: =IF(OR(F14="",F21="",N(F21)=0),"",F14/F21) -> 0.143805 | G27: =IF(OR(G14="",G21="",N(G21)=0),"",G14/G21) -> 0.11666571 | H27: =IF(OR(H14="",H21="",N(H21)=0),"",H14/H21) -> 0.37457282 | J27: =IF(OR(J14="",J21="",N(J21)=0),"",J14/J21) -> 0.13522873 | K27: =IF(OR(K14="",K21="",N(K21)=0),"",K14/K21) -> 0.11449893 | L27: =IF(OR(L14="",L21="",N(L21)=0),"",L14/L21) -> 0.10933837 | M27: =IF(OR(M14="",M21="",N(M21)=0),"",M14/M21) -> 0.10540098 | N27: =IF(OR(N14="",N21="",N(N21)=0),"",N14/N21) -> 0.10071474 | O27: =IF(OR(O14="",O21="",N(O21)=0),"",O14/O21) -> 0.099276585
A28: ROE normalizado | B28: n.c. | C28: n.c. | D28: n.c. | E28: =IF(OR(E15="",E21="",N(E21)=0),"",E15/E21) -> 0.043271256 | F28: =IF(OR(F15="",F21="",N(F21)=0),"",F15/F21) -> 0.081219468 | G28: =IF(OR(G15="",G21="",N(G21)=0),"",G15/G21) -> 0.082760367 | H28: =IF(OR(H15="",H21="",N(H21)=0),"",H15/H21) -> 0.096668817 | J28: =IF(OR(J15="",J21="",N(J21)=0),"",J15/J21) -> 0.080406398 | K28: =IF(OR(K15="",K21="",N(K21)=0),"",K15/K21) -> 0.080153154 | L28: =IF(OR(L15="",L21="",N(L21)=0),"",L15/L21) -> 0.078354434 | M28: =IF(OR(M15="",M21="",N(M21)=0),"",M15/M21) -> 0.076318699 | N28: =IF(OR(N15="",N21="",N(N21)=0),"",N15/N21) -> 0.073135149 | O28: =IF(OR(O15="",O21="",N(O21)=0),"",O15/O21) -> 0.072709653
A29: ROA reportado | B29: n.c. | C29: n.c. | D29: n.c. | E29: =IF(OR(E14="",E20="",N(E20)=0),"",E14/E20) -> 0.036628672 | F29: =IF(OR(F14="",F20="",N(F20)=0),"",F14/F20) -> 0.075133946 | G29: =IF(OR(G14="",G20="",N(G20)=0),"",G14/G20) -> 0.062724521 | H29: =IF(OR(H14="",H20="",N(H20)=0),"",H14/H20) -> 0.21202194 | J29: =IF(OR(J14="",J20="",N(J20)=0),"",J14/J20) -> 0.08083117 | K29: =IF(OR(K14="",K20="",N(K20)=0),"",K14/K20) -> 0.069832519 | L29: =IF(OR(L14="",L20="",N(L20)=0),"",L14/L20) -> 0.068317811 | M29: =IF(OR(M14="",M20="",N(M20)=0),"",M14/M20) -> 0.068295593 | N29: =IF(OR(N14="",N20="",N(N20)=0),"",N14/N20) -> 0.068054574 | O29: =IF(OR(O14="",O20="",N(O20)=0),"",O14/O20) -> 0.069799578
A30: ROA normalizado | B30: n.c. | C30: n.c. | D30: n.c. | E30: =IF(OR(E15="",E20="",N(E20)=0),"",E15/E20) -> 0.022268946 | F30: =IF(OR(F15="",F20="",N(F20)=0),"",F15/F20) -> 0.042434819 | G30: =IF(OR(G15="",G20="",N(G20)=0),"",G15/G20) -> 0.044495547 | H30: =IF(OR(H15="",H20="",N(H20)=0),"",H15/H20) -> 0.054718093 | J30: =IF(OR(J15="",J20="",N(J20)=0),"",J15/J20) -> 0.048061854 | K30: =IF(OR(K15="",K20="",N(K20)=0),"",K15/K20) -> 0.048885145 | L30: =IF(OR(L15="",L20="",N(L20)=0),"",L15/L20) -> 0.04895814 | M30: =IF(OR(M15="",M20="",N(M20)=0),"",M15/M20) -> 0.049451443 | N30: =IF(OR(N15="",N20="",N(N20)=0),"",N15/N20) -> 0.049418598 | O30: =IF(OR(O15="",O20="",N(O20)=0),"",O15/O20) -> 0.051120847
A32: Controles: ROE reportado 2024A = 11,67% y 2025A = 37,46% (Bloomberg). Identidad DuPont: margen × rotación × apalancamiento = ROE.
A33: n.c. = no comparable (modelo del costo hasta 2021; NIC 8 reformula solo desde 01-01-2022).
A34: 2022A–2023A con EEFF dic-23 reformulado: utilidad 2022 = 157.667 (no 66.445 base costo); distribuible 2023 = 197.540 [R, Nota 21e]; distribuible 2022 = 95.856 [C, proxy]. Payout 2023 sobre distribuible = 40,0%, en línea con la política.
A35: LTM 2T26 no se calcula en el bloque B: exige balance de jun-25 (EEFF jun-25, pendiente). La compañía reporta ROE LTM 28,6% con otra definición (patrimonio total, promedio de 4 trimestres).
A37: C. Peers — same normalization (WP §85) | E37: 2022A | F37: 2023A | G37: 2024A | H37: 2025A
A38: ROE normalizado — Mallplaza | E38: =E28 -> 0.043271256 | F38: =F28 -> 0.081219468 | G38: =G28 -> 0.082760367 | H38: =H28 -> 0.096668817
A39: ROE normalizado — Parque Arauco | E39: =Peers_inputs!$C$39 -> 0.039743587 | F39: =Peers_inputs!$D$39 -> 0.068141937 | G39: =Peers_inputs!$E$39 -> 0.066008029 | H39: =Peers_inputs!$F$39 -> 0.077679777
A40: ROE normalizado — Cencosud Shopping | E40: =Peers_inputs!$C$51 -> 0.060016229 | F40: =Peers_inputs!$D$51 -> 0.071900052 | G40: =Peers_inputs!$E$51 -> 0.078339223 | H40: =Peers_inputs!$F$51 -> 0.080249149
A41: ROE reportado — Mallplaza | E41: =E27 -> 0.071173939 | F41: =F27 -> 0.143805 | G41: =G27 -> 0.11666571 | H41: =H27 -> 0.37457282
A42: ROE reportado — Parque Arauco | E42: =Peers_inputs!$C$38 -> 0.090923105 | F42: =Peers_inputs!$D$38 -> 0.091941638 | G42: =Peers_inputs!$E$38 -> 0.087263993 | H42: =Peers_inputs!$F$38 -> 0.098054072
A43: ROE reportado — Cencosud Shopping | E43: =Peers_inputs!$C$50 -> 0.068084187 | F43: =Peers_inputs!$D$50 -> 0.069069748 | G43: =Peers_inputs!$E$50 -> 0.09580596 | H43: =Peers_inputs!$F$50 -> 0.10450597
A44: Revalorización / PI de apertura — Mallplaza | E44: n/d | F44: n/d | G44: =Inputs!$C$116/Inputs!$C$117 -> 0.037403105 | H44: =Inputs!$C$68/Inputs!$C$65 -> 0.27016246
A45: Revalorización / PI de apertura — Parque Arauco | E45: =Peers_inputs!$C$40 -> 0.048567519 | F45: =Peers_inputs!$D$40 -> 0.01955013 | G45: =Peers_inputs!$E$40 -> 0.018139215 | H45: =Peers_inputs!$F$40 -> 0.020001834
...

Sheet E2_FFO_bridge
A1: Exhibit 2 — From reported profit to FFO, FY2025 (MM CLP)
A2: Reconstrucción propia; reproduce el FFO de la compañía con Δ −0,02%. Participación no controladora prorrateada por utilidad [S].
A4: Paso | B4: Monto | C4: Base (gráfico) | D4: Barra (gráfico)
A5: Ganancia consolidada | B5: =Inputs!$C$11 -> 1440978 | C5: 0 | D5: =B5 -> 1440978
A6: (−) Otros ingresos por función (revalorización) | B6: =-Inputs!$C$15 -> -1448943 | C6: =B5+B6 -> -7965 | D6: =-B6 -> 1448943
A7: (+) Otros gastos por función | B7: =Inputs!$C$16 -> 3511 | C7: =C6+IF(B6<0,0,D6) -> -7965 | D7: =B7 -> 3511
A8: (+) D&A | B8: =Inputs!$C$17 -> 3610 | C8: =C7+D7 -> -4454 | D8: =B8 -> 3610
A9: (+) Reajuste UF de la deuda | B9: =Inputs!$C$18 -> 43825 | C9: =C8+D8 -> -844 | D9: =B9 -> 43825
A10: (+) Impuesto diferido | B10: =Inputs!$C$19 -> 365071 | C10: =C9+D9 -> 42981 | D10: =B10 -> 365071
A11: FFO consolidado | B11: =SUM(B5:B10) -> 408052 | C11: 0 | D11: =B11 -> 408052
A12: (−) Participación no controladora (% de la utilidad) | B12: =-B11*Inputs!$C$14/Inputs!$C$11 -> -2822.4264
A13: FFO atribuible reconstruido | B13: =B11+B12 -> 405229.57
A14: FFO atribuible reportado (compañía) | B14: =Inputs!$C$20 -> 405300
A15: Diferencia | B15: =B13/B14-1 -> -0.00017376352
A16: Reajuste UF / FFO atribuible | B16: =B9/B13 -> 0.10814857
A18: Nota: columnas C–D solo alimentan el gráfico de cascada (base invisible).

Sheet E3_Growth
A1: Exhibit 3 — Growth: perimeter, indexation, real
A2: Deflactor Chile = UF promedio del período [C]. Colombia y Perú: tipo de cambio promedio (WP §82) e inflación local (WP §83). Bloque B = Exhibit 3 v1 (WP §84).
B4: FY2024 | C4: FY2025 | D4: 1S25 | E4: 1S26 | K4: 1S26 | L4: Reported (CLP) | M4: Real
A5: Ingresos consolidados | B5: =Inputs!$C$5 -> 494605 | C5: =Inputs!$C$6 -> 653911 | D5: =Inputs!$C$7 -> 316108 | E5: =Inputs!$C$8 -> 339530 | K5: Chile | L5: =B27 -> 0.060539575 | M5: =F27 -> 0.028266989
A6: Chile | B6: =Inputs!$C$35 -> 428322 | C6: =Inputs!$C$36 -> 469964 | D6: =Inputs!$C$29 -> 230626 | E6: =Inputs!$C$30 -> 244588 | K6: Peru | L6: =B28 -> 0.089139054 | M6: =F28 -> 0.044921018
A7: Colombia | B7: =Inputs!$C$37 -> 52671 | C7: =Inputs!$C$38 -> 62627 | D7: =Inputs!$C$31 -> 29393 | E7: =Inputs!$C$32 -> 33899 | K7: Colombia | L7: =B31 -> 0.15330181 | M7: =F31 -> 0.011081497
A8: Perú | B8: =Inputs!$C$39 -> 13612 | C8: =Inputs!$C$40 -> 121320 | D8: =Inputs!$C$33 -> 56496 | E8: =Inputs!$C$34 -> 61532 | K8: Consolidated | L8: =B32 -> 0.07409493 | M8: =F32 -> 0.029710902
A9: Rentas variables | B9: =Inputs!$C$42 -> 24833 | C9: =Inputs!$C$43 -> 38936 | D9: =Inputs!$C$44 -> 17521 | E9: =Inputs!$C$45 -> 17332 | K9: Rango auxiliar del gráfico "Reported vs real".
A10: UF promedio | B10: =Inputs!$C$46 -> 37569.64 | C10: =Inputs!$C$47 -> 39206.28 | D10: =Inputs!$C$48 -> 38841.29 | E10: =Inputs!$C$49 -> 40060.34
A12: Crecimiento | C12: FY2025 | E12: 1S26
A13: Consolidado nominal | C13: =C5/B5-1 -> 0.32208732 | E13: =E5/D5-1 -> 0.07409493 | G13: Serie | H13: FY2025 | I13: 1S26
A14: de lo cual: perímetro Perú (pp) | C14: =(C8-B8)/B5 -> 0.21776569 | G14: Nominal | H14: =C16 -> 0.097221249 | I14: =E16 -> 0.060539575
A15: Ex-Perú nominal (Chile + Colombia) | C15: =(C6+C7)/(B6+B7)-1 -> 0.10727391 | E15: =(E6+E7)/(D6+D7)-1 -> 0.071025579 | G15: UF | H15: =C17 -> 0.043562834 | I15: =E17 -> 0.031385415
A16: Chile nominal | C16: =C6/B6-1 -> 0.097221249 | E16: =E6/D6-1 -> 0.060539575 | G16: Real | H16: =C18 -> 0.05141848 | I16: =E18 -> 0.028266989
A17: Indexación UF (UF promedio) | C17: =C10/B10-1 -> 0.043562834 | E17: =E10/D10-1 -> 0.031385415
A18: Chile real | C18: =(1+C16)/(1+C17)-1 -> 0.05141848 | E18: =(1+E16)/(1+E17)-1 -> 0.028266989
A19: Colombia nominal en CLP (incluye FX) | C19: =C7/B7-1 -> 0.18902242 | E19: =E7/D7-1 -> 0.15330181
A20: Perú nominal en CLP (incluye FX) | C20: n.m. | E20: =E8/D8-1 -> 0.089139054
A21: Rentas variables / ingresos | B21: =B9/B5 -> 0.050207742 | C21: =C9/C5 -> 0.059543271 | D21: =D9/D5 -> 0.055427259 | E21: =E9/E5 -> 0.051047036
A22: Crecimiento rentas variables | C22: =C9/B9-1 -> 0.56791366 | E22: =E9/D9-1 -> -0.010787056
A23: Crecimiento ingresos no variables | C23: =(C5-C9)/(B5-B9)-1 -> 0.3090925 | E23: =(E5-E9)/(D5-D9)-1 -> 0.07907578
A25: B. By country: CLP → local currency → real | B25: Nominal CLP | C25: Efecto FX | D25: Moneda local | E25: Inflación / UF | F25: Real
A26: Chile FY2025 | B26: =C16 -> 0.097221249 | C26: 0 | D26: =(1+B26)/(1+C26)-1 -> 0.097221249 | E26: =C17 -> 0.043562834 | F26: =(1+D26)/(1+E26)-1 -> 0.05141848
A27: Chile 1S26 | B27: =E16 -> 0.060539575 | C27: 0 | D27: =(1+B27)/(1+C27)-1 -> 0.060539575 | E27: =E17 -> 0.031385415 | F27: =(1+D27)/(1+E27)-1 -> 0.028266989
A28: Perú 1S26 | B28: =E20 -> 0.089139054 | C28: =Inputs!$C$109/Inputs!$C$108-1 -> 0.0092168157 | D28: =(1+B28)/(1+C28)-1 -> 0.079192337 | E28: =Inputs!$C$112 -> 0.032798 | F28: =(1+D28)/(1+E28)-1 -> 0.044921018
A29: Colombia FY2024 | B29: =Inputs!$C$37/Inputs!$C$100-1 -> 0.44859736 | C29: =Inputs!$C$102/Inputs!$C$101-1 -> 0.17218697 | D29: =(1+B29)/(1+C29)-1 -> 0.23580742 | E29: =Inputs!$C$113 -> 0.052 | F29: =(1+D29)/(1+E29)-1 -> 0.17472189
A30: Colombia FY2025 | B30: =C19 -> 0.18902242 | C30: =Inputs!$C$103/Inputs!$C$102-1 -> 0.013395512 | D30: =(1+B30)/(1+C30)-1 -> 0.1733054 | E30: =Inputs!$C$114 -> 0.051 | F30: =(1+D30)/(1+E30)-1 -> 0.1163705
A31: Colombia 1S26 | B31: =E19 -> 0.15330181 | C31: =Inputs!$C$105/Inputs!$C$104-1 -> 0.074676436 | D31: =(1+B31)/(1+C31)-1 -> 0.073161901 | E31: =Inputs!$C$115 -> 0.0614 | F31: =(1+D31)/(1+E31)-1 -> 0.011081497
